Workbook
Name Scenario: '01_CONTROL'!$D$12
Name Hold_Y: '01_CONTROL'!$D$14
Name Hold_Col: '01_CONTROL'!$G$14
Name Entry_Multiple: '01_CONTROL'!$D$16
Name Exit_Method: '01_CONTROL'!$D$17
Name Exit_Multiple: '01_CONTROL'!$D$18
Name Exit_Equity_Target: '01_CONTROL'!$D$19
Name Debt_Structure: '01_CONTROL'!$D$20
Name IR_Mode: '01_CONTROL'!$D$21
Name Bench_Rate: '01_CONTROL'!$D$22
Name Tax_Rate: '01_CONTROL'!$D$26
Name Exit_Fee_Pct: '01_CONTROL'!$D$35
Name Coven_NetLev_Max: '01_CONTROL'!$D$71
Name Coven_IntCov_Min: '01_CONTROL'!$D$72
Name Min_Liq_Target: '01_CONTROL'!$D$73
Name Purchase_Price: '01_CONTROL'!$D$15
Name FX_Mode: '01_CONTROL'!$D$23
Name FX_Rate: '01_CONTROL'!$D$24
Name Lev_Target: '01_CONTROL'!$D$48
Name Revolver_Limit: '01_CONTROL'!$G$49
Name Cash_Sweep: '01_CONTROL'!$G$54
Name Mgmt_Rollover_Pct: '01_CONTROL'!$G$55
Name WC_Adjust: '01_CONTROL'!$G$56
Name TRAINING_MODE: 01_CONTROL!$G$12

Sheet 00_DASHBOARD
B2: CHECKS: | C2: =HYPERLINK("#'90_CHECKS'!B6",'90_CHECKS'!$C$22)
B3: LBO Dashboard (Sponsor IC)
B4: CatalystOne (Sweden) | HR platform | Training case | Reporting currency: DKK
B5: Key outputs update automatically from 01_CONTROL toggles.
B7: Key deal outputs
B9: Entry EV (DKKm) | C9: ='05_SOURCES_AND_USES'!$D$33 | E9: Entry multiple (x) | F9: =Entry_Multiple | H9: Leverage (Net debt / EBITDA, x) | I9: ='10_COVENANTS_AND_CREDIT_METRICS'!$D$34
H10: Learning cues (click)
B11: ENTRY EV (DKKm) | C11: ='05_SOURCES_AND_USES'!$D$16 | E11: EXIT MULTIPLE (x) | F11: =Exit_Multiple | H11: ENTRY EV | I11: Valuation starting point, drives equity check. | J11: =HYPERLINK("#'82_LBO_LEARN_INTERPRETATION'!B11","Learn")
B12: ENTRY MULTIPLE (x) | C12: =Entry_Multiple | E12: SPONSOR IRR | F12: ='09_RETURNS'!$D$20 | H12: ENTRY MULTIPLE | I12: Paying up needs a clear thesis or leverage/FCF. | J12: =HYPERLINK("#'82_LBO_LEARN_INTERPRETATION'!B12","Learn")
B13: TOTAL DEBT (DKKm) | C13: ='05_SOURCES_AND_USES'!$D$37 | E13: SPONSOR MOIC | F13: ='09_RETURNS'!$D$21 | H13: TOTAL DEBT | I13: Leverage boosts IRR but tightens covenants. | J13: =HYPERLINK("#'82_LBO_LEARN_INTERPRETATION'!B13","Learn")
B14: TOTAL EQUITY (DKKm) | C14: ='05_SOURCES_AND_USES'!$D$40 | E14: PEAK NET LEVERAGE (x) | F14: ='10_COVENANTS_AND_CREDIT_METRICS'!$D$34 | H14: TOTAL EQUITY | I14: Equity check is denominator for returns. | J14: =HYPERLINK("#'82_LBO_LEARN_INTERPRETATION'!B14","Learn")
B15: ENTRY LEVERAGE (x) | C15: ='05_SOURCES_AND_USES'!$D$37/'05_SOURCES_AND_USES'!$D$14 | E15: MIN LIQUIDITY (DKKm) | F15: ='10_COVENANTS_AND_CREDIT_METRICS'!$D$35 | H15: ENTRY LEVERAGE | I15: Risk-return; watch peak leverage and liquidity. | J15: =HYPERLINK("#'82_LBO_LEARN_INTERPRETATION'!B15","Learn")
E16: MIN COVENANT HEADROOM (x) | F16: ='10_COVENANTS_AND_CREDIT_METRICS'!$D$36 | H16: EXIT MULTIPLE | I16: Largest driver, defend range and stress downside. | J16: =HYPERLINK("#'82_LBO_LEARN_INTERPRETATION'!B16","Learn")
E17: CHECKS STATUS | F17: ='90_CHECKS'!$C$2 | H17: SPONSOR IRR | I17: Timing-sensitive headline, reconcile to MOIC. | J17: =HYPERLINK("#'82_LBO_LEARN_INTERPRETATION'!B17","Learn")
B18: Min covenant headroom (x) | C18: ='10_COVENANTS_AND_CREDIT_METRICS'!$D$36 | H18: SPONSOR MOIC | I18: Value creation multiple, pair with hold period. | J18: =HYPERLINK("#'82_LBO_LEARN_INTERPRETATION'!B18","Learn")
H19: PEAK NET LEVERAGE | I19: Stress point for credit risk and flexibility. | J19: =HYPERLINK("#'82_LBO_LEARN_INTERPRETATION'!B19","Learn")
H20: MIN LIQUIDITY | I20: First line of defense, watch revolver usage. | J20: =HYPERLINK("#'82_LBO_LEARN_INTERPRETATION'!B20","Learn")
H21: MIN COV HEADROOM | I21: Breach risk, identify what breaks first. | J21: =HYPERLINK("#'82_LBO_LEARN_INTERPRETATION'!B21","Learn")
B22: Checks status | H22: CHECKS STATUS | I22: Must be PASS before interpreting outputs. | J22: =HYPERLINK("#'82_LBO_LEARN_INTERPRETATION'!B22","Learn")
B24: Overall | C24: ='90_CHECKS'!$C$22 | D24: See 90_Checks for details
B26: Charts
B28: Year | C28: Total debt | D28: Net leverage
B29: 1 | C29: =INDEX('06_DEBT_SCHEDULES'!$F$67:$L$67,1,1) | D29: =INDEX('10_COVENANTS_AND_CREDIT_METRICS'!$F$19:$L$19,1,1)
B30: 2 | C30: =INDEX('06_DEBT_SCHEDULES'!$F$67:$L$67,1,2) | D30: =INDEX('10_COVENANTS_AND_CREDIT_METRICS'!$F$19:$L$19,1,2)
B31: 3 | C31: =INDEX('06_DEBT_SCHEDULES'!$F$67:$L$67,1,3) | D31: =INDEX('10_COVENANTS_AND_CREDIT_METRICS'!$F$19:$L$19,1,3)
B32: 4 | C32: =INDEX('06_DEBT_SCHEDULES'!$F$67:$L$67,1,4) | D32: =INDEX('10_COVENANTS_AND_CREDIT_METRICS'!$F$19:$L$19,1,4)
B33: 5 | C33: =INDEX('06_DEBT_SCHEDULES'!$F$67:$L$67,1,5) | D33: =INDEX('10_COVENANTS_AND_CREDIT_METRICS'!$F$19:$L$19,1,5)
B34: 6 | C34: =INDEX('06_DEBT_SCHEDULES'!$F$67:$L$67,1,6) | D34: =INDEX('10_COVENANTS_AND_CREDIT_METRICS'!$F$19:$L$19,1,6)
B35: 7 | C35: =INDEX('06_DEBT_SCHEDULES'!$F$67:$L$67,1,7) | D35: =INDEX('10_COVENANTS_AND_CREDIT_METRICS'!$F$19:$L$19,1,7)
B37: IRR heatmap (Exit multiple vs Entry multiple)
B39: (Links to 11_SENSITIVITIES)
C41: ='11_SENSITIVITIES'!D23 | D41: ='11_SENSITIVITIES'!E23 | E41: ='11_SENSITIVITIES'!F23 | F41: ='11_SENSITIVITIES'!G23 | G41: ='11_SENSITIVITIES'!H23 | H41: ='11_SENSITIVITIES'!I23
B42: ='11_SENSITIVITIES'!C24 | C42: ='11_SENSITIVITIES'!D24 | D42: ='11_SENSITIVITIES'!E24 | E42: ='11_SENSITIVITIES'!F24 | F42: ='11_SENSITIVITIES'!G24 | G42: ='11_SENSITIVITIES'!H24 | H42: ='11_SENSITIVITIES'!I24
B43: ='11_SENSITIVITIES'!C25 | C43: ='11_SENSITIVITIES'!D25 | D43: ='11_SENSITIVITIES'!E25 | E43: ='11_SENSITIVITIES'!F25 | F43: ='11_SENSITIVITIES'!G25 | G43: ='11_SENSITIVITIES'!H25 | H43: ='11_SENSITIVITIES'!I25
B44: ='11_SENSITIVITIES'!C26 | C44: ='11_SENSITIVITIES'!D26 | D44: ='11_SENSITIVITIES'!E26 | E44: ='11_SENSITIVITIES'!F26 | F44: ='11_SENSITIVITIES'!G26 | G44: ='11_SENSITIVITIES'!H26 | H44: ='11_SENSITIVITIES'!I26
B45: ='11_SENSITIVITIES'!C27 | C45: ='11_SENSITIVITIES'!D27 | D45: ='11_SENSITIVITIES'!E27 | E45: ='11_SENSITIVITIES'!F27 | F45: ='11_SENSITIVITIES'!G27 | G45: ='11_SENSITIVITIES'!H27 | H45: ='11_SENSITIVITIES'!I27
B46: ='11_SENSITIVITIES'!C28 | C46: ='11_SENSITIVITIES'!D28 | D46: ='11_SENSITIVITIES'!E28 | E46: ='11_SENSITIVITIES'!F28 | F46: ='11_SENSITIVITIES'!G28 | G46: ='11_SENSITIVITIES'!H28 | H46: ='11_SENSITIVITIES'!I28
B47: ='11_SENSITIVITIES'!C29 | C47: ='11_SENSITIVITIES'!D29 | D47: ='11_SENSITIVITIES'!E29 | E47: ='11_SENSITIVITIES'!F29 | F47: ='11_SENSITIVITIES'!G29 | G47: ='11_SENSITIVITIES'!H29 | H47: ='11_SENSITIVITIES'!I29
B49: What this means (interpretation)
B51: • IRR and MOIC are sensitive to exit multiple and growth. Review 11_SENSITIVITIES heatmaps.
...

Sheet 01_CONTROL
B1: LBO Model Builder (Training Simulation)
B2: CHECKS: | C2: =HYPERLINK("#'90_CHECKS'!B6",'90_CHECKS'!$C$22)
B3: Checks: | C3: =HYPERLINK("#'90_CHECKS'!B2","Go to 90_CHECKS")
B4: Units: | C4: DKKm
B5: Version: | C5: v0.1
B6: Date: | C6: 46069
B10: MODEL CONTROLS AND GLOBAL ASSUMPTIONS
B12: Scenario | D12: Base | F12: TRAINING_MODE (ON/OFF) | G12: OFF
B13: Scenario index (1=Base,2=Upside,3=Downside) | D13: =MATCH(D12,{"Base","Upside","Downside"},0)
B14: Hold period (years) | D14: 5 | G14: =Hold_Y+1
B15: Hold col index (LTM=1, Year1=2...) | D15: =1+D14
B16: Entry EV multiple (x LTM EBITDA) - primary driver | D16: 12
B17: Exit method | D17: Exit Multiple
B18: Exit EV multiple (x EBITDA) | D18: 13
B19: Exit equity value target (DKKm, used if Exit method = Equity Value) | D19: 0
B20: Debt structure | D20: Standard
B21: Interest rate mode | D21: Floating
B22: Benchmark rate (e.g., CIBOR 3M) | D22: 0.03
B23: FX enabled? | D23: Off
B24: Target currency | D24: SEK
B25: FX rate (DKK per target currency unit) | D25: 0.65
B26: Corporate tax rate | D26: 0.22
B27: Margin ramp (years) | D27: 2
B28: TARGET LTM INPUTS (SINGLE-ENTRY)
B30: LTM Revenue (DKKm) | D30: 450
B31: LTM EBITDA margin | D31: 0.28
B32: LTM EBITDA (DKKm) | D32: =D30*D31
B33: Opening cash at close (DKKm) | D33: 0
B34: Existing net debt refinanced (DKKm, + means debt) | D34: 0
B35: Exit fees (% EV) | D35: 0.01
B36: SCENARIO ASSUMPTIONS (EDIT BLUE, ACTIVE DRIVES MODEL)
B38: Assumption | C38: Unit | D38: Base | E38: Upside | F38: Downside | G38: Active
B39: Revenue growth (annual) | C39: % | D39: 0.1 | E39: 0.12 | F39: 0.06 | G39: =CHOOSE($D$13, D39, E39, F39)
B40: EBITDA margin (steady state) | C40: % | D40: 0.29 | E40: 0.31 | F40: 0.26 | G40: =CHOOSE($D$13, D40, E40, F40)
B41: Capex (% revenue) | C41: % | D41: 0.03 | E41: 0.035 | F41: 0.025 | G41: =CHOOSE($D$13, D41, E41, F41)
B42: D&A (% revenue) | C42: % | D42: 0.02 | E42: 0.02 | F42: 0.02 | G42: =CHOOSE($D$13, D42, E42, F42)
B43: NWC method | C43: text | D43: PctRev | E43: DSO | F43: PctRev | G43: =CHOOSE($D$13, D43, E43, F43)
B44: NWC (% revenue) | C44: % | D44: 0.05 | E44: 0.04 | F44: 0.06 | G44: =CHOOSE($D$13, D44, E44, F44)
B45: DSO (days) | C45: days | D45: 60 | E45: 55 | F45: 70 | G45: =CHOOSE($D$13, D45, E45, F45)
B46: DPO (days) | C46: days | D46: 45 | E46: 50 | F46: 40 | G46: =CHOOSE($D$13, D46, E46, F46)
...

Sheet 02_INPUTS_TARGET_HISTORICALS
B1: LBO Model Builder (Training Simulation)
B2: CHECKS: | C2: =HYPERLINK("#'90_CHECKS'!B6",'90_CHECKS'!$C$22)
B3: Checks: | C3: =HYPERLINK("#'90_CHECKS'!B2","Go to 90_CHECKS")
B4: Units: | C4: DKKm
B5: Version: | C5: v0.1
B6: Date: | C6: 46069
B7: Period end | E7: 46022 | F7: 46387 | G7: 46752 | H7: 47118 | I7: 47483 | J7: 47848 | K7: 48213 | L7: 48579
B8: Period | E8: LTM | F8: 2026E | G8: 2027E | H8: 2028E | I8: 2029E | J8: 2030E | K8: 2031E | L8: 2032E
B9: Year # | E9: 0 | F9: 1 | G9: 2 | H9: 3 | I9: 4 | J9: 5 | K9: 6 | L9: 7

Sheet 03_DRIVERS_AND_FORECAST
B1: LBO Model Builder (Training Simulation)
B2: CHECKS: | C2: =HYPERLINK("#'90_CHECKS'!B6",'90_CHECKS'!$C$22)
B3: Checks: | C3: =HYPERLINK("#'90_CHECKS'!B2","Go to 90_CHECKS")
B4: Units: | C4: DKKm
B5: Version: | C5: v0.1
B6: Date: | C6: 46069
B7: Period end | E7: 46022 | F7: 46387 | G7: 46752 | H7: 47118 | I7: 47483 | J7: 47848 | K7: 48213 | L7: 48579
B8: Period | E8: LTM | F8: 2026E | G8: 2027E | H8: 2028E | I8: 2029E | J8: 2030E | K8: 2031E | L8: 2032E
B9: Year # | E9: 0 | F9: 1 | G9: 2 | H9: 3 | I9: 4 | J9: 5 | K9: 6 | L9: 7
B10: OPERATING DRIVERS (SCENARIO-DRIVEN)
B12: Revenue (DKKm) | C12: DKKm | E12: ='01_CONTROL'!$D$30 | F12: =E12*(1+F13) | G12: =F12*(1+G13) | H12: =G12*(1+H13) | I12: =H12*(1+I13) | J12: =I12*(1+J13) | K12: =J12*(1+K13) | L12: =K12*(1+L13)
B13: Revenue growth (active) | C13: % | F13: ='01_CONTROL'!$G$39 | G13: ='01_CONTROL'!$G$39 | H13: ='01_CONTROL'!$G$39 | I13: ='01_CONTROL'!$G$39 | J13: ='01_CONTROL'!$G$39 | K13: ='01_CONTROL'!$G$39 | L13: ='01_CONTROL'!$G$39
B15: EBITDA margin (active ramp) | C15: % | E15: ='01_CONTROL'!$D$31 | F15: ='01_CONTROL'!$D$31 + MIN(1,F9/'01_CONTROL'!$D$27)*('01_CONTROL'!$G$40-'01_CONTROL'!$D$31) | G15: ='01_CONTROL'!$D$31 + MIN(1,G9/'01_CONTROL'!$D$27)*('01_CONTROL'!$G$40-'01_CONTROL'!$D$31) | H15: ='01_CONTROL'!$D$31 + MIN(1,H9/'01_CONTROL'!$D$27)*('01_CONTROL'!$G$40-'01_CONTROL'!$D$31) | I15: ='01_CONTROL'!$D$31 + MIN(1,I9/'01_CONTROL'!$D$27)*('01_CONTROL'!$G$40-'01_CONTROL'!$D$31) | J15: ='01_CONTROL'!$D$31 + MIN(1,J9/'01_CONTROL'!$D$27)*('01_CONTROL'!$G$40-'01_CONTROL'!$D$31) | K15: ='01_CONTROL'!$D$31 + MIN(1,K9/'01_CONTROL'!$D$27)*('01_CONTROL'!$G$40-'01_CONTROL'!$D$31) | L15: ='01_CONTROL'!$D$31 + MIN(1,L9/'01_CONTROL'!$D$27)*('01_CONTROL'!$G$40-'01_CONTROL'!$D$31)
B16: EBITDA (DKKm) | C16: DKKm | E16: =E12*E15 | F16: =F12*F15 | G16: =G12*G15 | H16: =H12*H15 | I16: =I12*I15 | J16: =J12*J15 | K16: =K12*K15 | L16: =L12*L15
B18: Capex (% revenue) | C18: % | F18: ='01_CONTROL'!$G$41 | G18: ='01_CONTROL'!$G$41 | H18: ='01_CONTROL'!$G$41 | I18: ='01_CONTROL'!$G$41 | J18: ='01_CONTROL'!$G$41 | K18: ='01_CONTROL'!$G$41 | L18: ='01_CONTROL'!$G$41
B19: D&A (% revenue) | C19: % | F19: ='01_CONTROL'!$G$42 | G19: ='01_CONTROL'!$G$42 | H19: ='01_CONTROL'!$G$42 | I19: ='01_CONTROL'!$G$42 | J19: ='01_CONTROL'!$G$42 | K19: ='01_CONTROL'!$G$42 | L19: ='01_CONTROL'!$G$42
B21: NWC method (active) | C21: text | E21: ='01_CONTROL'!$G$43
B22: NWC (% revenue) if PctRev | C22: % | F22: ='01_CONTROL'!$G$44
B23: DSO / DPO / DIO (days) if DSO | C23: days | F23: ='01_CONTROL'!$G$45 | G23: ='01_CONTROL'!$G$46 | H23: ='01_CONTROL'!$G$47

Sheet 04_OPERATING_MODEL
B1: LBO Model Builder (Training Simulation)
B2: CHECKS: | C2: =HYPERLINK("#'90_CHECKS'!B6",'90_CHECKS'!$C$22)
B3: Checks: | C3: =HYPERLINK("#'90_CHECKS'!B2","Go to 90_CHECKS")
B4: Units: | C4: DKKm
B5: Version: | C5: v0.1
B6: Date: | C6: 46069
B7: Period end | E7: 46022 | F7: 46387 | G7: 46752 | H7: 47118 | I7: 47483 | J7: 47848 | K7: 48213 | L7: 48579
B8: Period | E8: LTM | F8: 2026E | G8: 2027E | H8: 2028E | I8: 2029E | J8: 2030E | K8: 2031E | L8: 2032E
B9: Year # | E9: 0 | F9: 1 | G9: 2 | H9: 3 | I9: 4 | J9: 5 | K9: 6 | L9: 7
B10: OPERATING MODEL (3-STATEMENT-LITE)
B12: INCOME STATEMENT (DKKM)
B14: Revenue | C14: DKKm | E14: ='03_DRIVERS_AND_FORECAST'!E12 | F14: ='03_DRIVERS_AND_FORECAST'!F12 | G14: ='03_DRIVERS_AND_FORECAST'!G12 | H14: ='03_DRIVERS_AND_FORECAST'!H12 | I14: ='03_DRIVERS_AND_FORECAST'!I12 | J14: ='03_DRIVERS_AND_FORECAST'!J12 | K14: ='03_DRIVERS_AND_FORECAST'!K12 | L14: ='03_DRIVERS_AND_FORECAST'!L12
B15: EBITDA | C15: DKKm | E15: ='03_DRIVERS_AND_FORECAST'!E16 | F15: ='03_DRIVERS_AND_FORECAST'!F16 | G15: ='03_DRIVERS_AND_FORECAST'!G16 | H15: ='03_DRIVERS_AND_FORECAST'!H16 | I15: ='03_DRIVERS_AND_FORECAST'!I16 | J15: ='03_DRIVERS_AND_FORECAST'!J16 | K15: ='03_DRIVERS_AND_FORECAST'!K16 | L15: ='03_DRIVERS_AND_FORECAST'!L16
B16: EBITDA margin | C16: % | E16: =IF(E14=0,0,E15/E14) | F16: =IF(F14=0,0,F15/F14) | G16: =IF(G14=0,0,G15/G14) | H16: =IF(H14=0,0,H15/H14) | I16: =IF(I14=0,0,I15/I14) | J16: =IF(J14=0,0,J15/J14) | K16: =IF(K14=0,0,K15/K14) | L16: =IF(L14=0,0,L15/L14)
B17: D&A | C17: DKKm | E17: =E14*'03_DRIVERS_AND_FORECAST'!E19 | F17: =F14*'03_DRIVERS_AND_FORECAST'!F19 | G17: =G14*'03_DRIVERS_AND_FORECAST'!G19 | H17: =H14*'03_DRIVERS_AND_FORECAST'!H19 | I17: =I14*'03_DRIVERS_AND_FORECAST'!I19 | J17: =J14*'03_DRIVERS_AND_FORECAST'!J19 | K17: =K14*'03_DRIVERS_AND_FORECAST'!K19 | L17: =L14*'03_DRIVERS_AND_FORECAST'!L19
B18: EBIT | C18: DKKm | E18: =E15-E17 | F18: =F15-F17 | G18: =G15-G17 | H18: =H15-H17 | I18: =I15-I17 | J18: =J15-J17 | K18: =K15-K17 | L18: =L15-L17
B19: Unlevered cash taxes | C19: DKKm | E19: =MAX(0,E18)*'01_CONTROL'!$D$26 | F19: =MAX(0,F18)*'01_CONTROL'!$D$26 | G19: =MAX(0,G18)*'01_CONTROL'!$D$26 | H19: =MAX(0,H18)*'01_CONTROL'!$D$26 | I19: =MAX(0,I18)*'01_CONTROL'!$D$26 | J19: =MAX(0,J18)*'01_CONTROL'!$D$26 | K19: =MAX(0,K18)*'01_CONTROL'!$D$26 | L19: =MAX(0,L18)*'01_CONTROL'!$D$26
B20: NOPAT | C20: DKKm | E20: =E18-E19 | F20: =F18-F19 | G20: =G18-G19 | H20: =H18-H19 | I20: =I18-I19 | J20: =J18-J19 | K20: =K18-K19 | L20: =L18-L19
B22: WORKING CAPITAL (DKKM)
B24: NWC method flag (1=PctRev,0=DSO) | C24: flag | E24: =IF('03_DRIVERS_AND_FORECAST'!$E$21="PctRev",1,0) | F24: =IF('03_DRIVERS_AND_FORECAST'!$E$21="PctRev",1,0) | G24: =IF('03_DRIVERS_AND_FORECAST'!$E$21="PctRev",1,0) | H24: =IF('03_DRIVERS_AND_FORECAST'!$E$21="PctRev",1,0) | I24: =IF('03_DRIVERS_AND_FORECAST'!$E$21="PctRev",1,0) | J24: =IF('03_DRIVERS_AND_FORECAST'!$E$21="PctRev",1,0) | K24: =IF('03_DRIVERS_AND_FORECAST'!$E$21="PctRev",1,0) | L24: =IF('03_DRIVERS_AND_FORECAST'!$E$21="PctRev",1,0)
B25: NWC (PctRev method) | C25: DKKm | E25: =E14*'03_DRIVERS_AND_FORECAST'!$F$22 | F25: =F14*'03_DRIVERS_AND_FORECAST'!$F$22 | G25: =G14*'03_DRIVERS_AND_FORECAST'!$F$22 | H25: =H14*'03_DRIVERS_AND_FORECAST'!$F$22 | I25: =I14*'03_DRIVERS_AND_FORECAST'!$F$22 | J25: =J14*'03_DRIVERS_AND_FORECAST'!$F$22 | K25: =K14*'03_DRIVERS_AND_FORECAST'!$F$22 | L25: =L14*'03_DRIVERS_AND_FORECAST'!$F$22
B27: Accounts receivable (DSO method) | C27: DKKm | E27: =E14/365*'03_DRIVERS_AND_FORECAST'!$F$23 | F27: =F14/365*'03_DRIVERS_AND_FORECAST'!$F$23 | G27: =G14/365*'03_DRIVERS_AND_FORECAST'!$F$23 | H27: =H14/365*'03_DRIVERS_AND_FORECAST'!$F$23 | I27: =I14/365*'03_DRIVERS_AND_FORECAST'!$F$23 | J27: =J14/365*'03_DRIVERS_AND_FORECAST'!$F$23 | K27: =K14/365*'03_DRIVERS_AND_FORECAST'!$F$23 | L27: =L14/365*'03_DRIVERS_AND_FORECAST'!$F$23
B28: Accounts payable (DPO method) | C28: DKKm | E28: =(E14-E15)/365*'03_DRIVERS_AND_FORECAST'!$G$23 | F28: =(F14-F15)/365*'03_DRIVERS_AND_FORECAST'!$G$23 | G28: =(G14-G15)/365*'03_DRIVERS_AND_FORECAST'!$G$23 | H28: =(H14-H15)/365*'03_DRIVERS_AND_FORECAST'!$G$23 | I28: =(I14-I15)/365*'03_DRIVERS_AND_FORECAST'!$G$23 | J28: =(J14-J15)/365*'03_DRIVERS_AND_FORECAST'!$G$23 | K28: =(K14-K15)/365*'03_DRIVERS_AND_FORECAST'!$G$23 | L28: =(L14-L15)/365*'03_DRIVERS_AND_FORECAST'!$G$23
B29: Net working capital (DSO method) | C29: DKKm | E29: =E27-E28 | F29: =F27-F28 | G29: =G27-G28 | H29: =H27-H28 | I29: =I27-I28 | J29: =J27-J28 | K29: =K27-K28 | L29: =L27-L28
B31: Selected NWC | C31: DKKm | E31: =IF(E24=1,E25,E29) | F31: =IF(F24=1,F25,F29) | G31: =IF(G24=1,G25,G29) | H31: =IF(H24=1,H25,H29) | I31: =IF(I24=1,I25,I29) | J31: =IF(J24=1,J25,J29) | K31: =IF(K24=1,K25,K29) | L31: =IF(L24=1,L25,L29)
B32: Change in NWC | C32: DKKm | E32: 0 | F32: =F31-E31 | G32: =G31-F31 | H32: =H31-G31 | I32: =I31-H31 | J32: =J31-I31 | K32: =K31-J31 | L32: =L31-K31
B34: UNLEVERED FREE CASH FLOW (DKKM)
B36: Capex | C36: DKKm | E36: 0 | F36: =-F14*'03_DRIVERS_AND_FORECAST'!F18 | G36: =-G14*'03_DRIVERS_AND_FORECAST'!G18 | H36: =-H14*'03_DRIVERS_AND_FORECAST'!H18 | I36: =-I14*'03_DRIVERS_AND_FORECAST'!I18 | J36: =-J14*'03_DRIVERS_AND_FORECAST'!J18 | K36: =-K14*'03_DRIVERS_AND_FORECAST'!K18 | L36: =-L14*'03_DRIVERS_AND_FORECAST'!L18
B37: Unlevered FCF | C37: DKKm | E37: 0 | F37: =F20+F17+F36-F32 | G37: =G20+G17+G36-G32 | H37: =H20+H17+H36-H32 | I37: =I20+I17+I36-I32 | J37: =J20+J17+J36-J32 | K37: =K20+K17+K36-K32 | L37: =L20+L17+L36-L32

Sheet 05_SOURCES_AND_USES
B1: LBO Model Builder (Training Simulation)
B2: CHECKS: | C2: =HYPERLINK("#'90_CHECKS'!B6",'90_CHECKS'!$C$22)
B3: Checks: | C3: =HYPERLINK("#'90_CHECKS'!B2","Go to 90_CHECKS")
B4: Units: | C4: DKKm
B5: Version: | C5: v0.1
B6: Date: | C6: 46069
B10: SOURCES & USES (ENTRY)
B12: ENTRY VALUATION
B14: LTM EBITDA (DKKm) | D14: ='01_CONTROL'!$D$32
B15: Entry EV multiple (x) | D15: ='01_CONTROL'!$D$16
B16: Entry Enterprise Value (EV) (DKKm) | D16: =D14*D15
B17: Existing net debt refinanced (DKKm) | D17: ='01_CONTROL'!$D$34
B18: Equity purchase price (to seller) (DKKm) | D18: =D16-D17
B20: USES
B22: Equity purchase price | D22: =D18
B23: Refinance existing net debt | D23: =D17
B24: Advisory fees | D24: =D16*'01_CONTROL'!$G$56
B25: Financing fees | D25: =D37*'01_CONTROL'!$G$57
B26: Working capital adjustment | D26: 0
B28: Total uses | D28: =SUM(D22:D26)
B30: SOURCES
B32: Debt structure flag (1=Standard,0=Simple) | D32: =IF('01_CONTROL'!$D$20="Standard",1,0)
B33: Term Loan A | D33: =D32*'01_CONTROL'!$G$50*D14
B34: Term Loan B | D34: =IF(D32=1,'01_CONTROL'!$G$51*D14, '01_CONTROL'!$G$48*D14)
B35: Senior Secured Notes | D35: =D32*'01_CONTROL'!$G$52*D14
B36: Mezz / PIK | D36: =D32*'01_CONTROL'!$G$53*D14
B37: Total new term debt (ex revolver) | D37: =SUM(D33:D36)
B38: Sponsor equity (plug) | D38: =D40-D39
B39: Mgmt rollover equity | D39: =D40*'01_CONTROL'!$G$55
B40: Total equity | D40: =D28-D37
B41: Total sources | D41: =D37+D40
B43: CHECKS
B44: Sources - Uses check | C44: DKKm | D44: =D37+D40-D28
B45: Sources - Uses (must be 0) | D45: =D41-D28

Sheet 06_DEBT_SCHEDULES
B1: LBO Model Builder (Training Simulation)
B2: CHECKS: | C2: =HYPERLINK("#'90_CHECKS'!B6",'90_CHECKS'!$C$22)
B3: Checks: | C3: =HYPERLINK("#'90_CHECKS'!B2","Go to 90_CHECKS")
B4: Units: | C4: DKKm
B5: Version: | C5: v0.1
B6: Date: | C6: 46069
B7: Period end | E7: 46022 | F7: 46387 | G7: 46752 | H7: 47118 | I7: 47483 | J7: 47848 | K7: 48213 | L7: 48579
B8: Period | E8: LTM | F8: 2026E | G8: 2027E | H8: 2028E | I8: 2029E | J8: 2030E | K8: 2031E | L8: 2032E
B9: Year # | E9: 0 | F9: 1 | G9: 2 | H9: 3 | I9: 4 | J9: 5 | K9: 6 | L9: 7
B10: DEBT SCHEDULES (ALL TRANCHES)
B12: INPUTS
B14: Revolver limit (DKKm) | C14: DKKm | E14: ='01_CONTROL'!$G$49
B15: TLA opening balance at close (DKKm) | C15: DKKm | E15: ='05_SOURCES_AND_USES'!$D$33
B16: TLB opening balance at close (DKKm) | C16: DKKm | E16: ='05_SOURCES_AND_USES'!$D$34
B17: SSN opening balance at close (DKKm) | C17: DKKm | E17: ='05_SOURCES_AND_USES'!$D$35
B18: Mezz/PIK opening balance at close (DKKm) | C18: DKKm | E18: ='05_SOURCES_AND_USES'!$D$36
B20: REVOLVER (DRAW/REPAY)
B22: Opening balance | C22: DKKm | E22: 0 | F22: =E25 | G22: =F25 | H22: =G25 | I22: =H25 | J22: =I25 | K22: =J25 | L22: =K25
B23: Draws | C23: DKKm | E23: 0 | F23: ='07_CASH_FLOW_WATERFALL'!F30 | G23: ='07_CASH_FLOW_WATERFALL'!G30 | H23: ='07_CASH_FLOW_WATERFALL'!H30 | I23: ='07_CASH_FLOW_WATERFALL'!I30 | J23: ='07_CASH_FLOW_WATERFALL'!J30 | K23: ='07_CASH_FLOW_WATERFALL'!K30 | L23: ='07_CASH_FLOW_WATERFALL'!L30
B24: Repayments | C24: DKKm | E24: 0 | F24: ='07_CASH_FLOW_WATERFALL'!F31 | G24: ='07_CASH_FLOW_WATERFALL'!G31 | H24: ='07_CASH_FLOW_WATERFALL'!H31 | I24: ='07_CASH_FLOW_WATERFALL'!I31 | J24: ='07_CASH_FLOW_WATERFALL'!J31 | K24: ='07_CASH_FLOW_WATERFALL'!K31 | L24: ='07_CASH_FLOW_WATERFALL'!L31
B25: Ending balance | C25: DKKm | E25: =E22+E23-E24 | F25: =F22+F23-F24 | G25: =G22+G23-G24 | H25: =H22+H23-H24 | I25: =I22+I23-I24 | J25: =J22+J23-J24 | K25: =K22+K23-K24 | L25: =L22+L23-L24
B26: All-in rate | C26: % | F26: =IF(IR_Mode="Fixed",'01_CONTROL'!$F$63,MAX(Bench_Rate+'01_CONTROL'!$D$63,'01_CONTROL'!$E$63)) | G26: =IF(IR_Mode="Fixed",'01_CONTROL'!$F$63,MAX(Bench_Rate+'01_CONTROL'!$D$63,'01_CONTROL'!$E$63)) | H26: =IF(IR_Mode="Fixed",'01_CONTROL'!$F$63,MAX(Bench_Rate+'01_CONTROL'!$D$63,'01_CONTROL'!$E$63)) | I26: =IF(IR_Mode="Fixed",'01_CONTROL'!$F$63,MAX(Bench_Rate+'01_CONTROL'!$D$63,'01_CONTROL'!$E$63)) | J26: =IF(IR_Mode="Fixed",'01_CONTROL'!$F$63,MAX(Bench_Rate+'01_CONTROL'!$D$63,'01_CONTROL'!$E$63)) | K26: =IF(IR_Mode="Fixed",'01_CONTROL'!$F$63,MAX(Bench_Rate+'01_CONTROL'!$D$63,'01_CONTROL'!$E$63)) | L26: =IF(IR_Mode="Fixed",'01_CONTROL'!$F$63,MAX(Bench_Rate+'01_CONTROL'!$D$63,'01_CONTROL'!$E$63))
B27: Cash interest | C27: DKKm | E27: 0 | F27: =F22*F26 | G27: =G22*G26 | H27: =H22*H26 | I27: =I22*I26 | J27: =J22*J26 | K27: =K22*K26 | L27: =L22*L26
B29: TERM LOAN A
B31: Opening balance | C31: DKKm | E31: ='06_DEBT_SCHEDULES'!$E$15 | F31: =E34 | G31: =F34 | H31: =G34 | I31: =H34 | J31: =I34 | K31: =J34 | L31: =K34
B32: Mandatory amortization | C32: DKKm | E32: 0 | F32: =MIN(F31,'01_CONTROL'!$C$64*F31) | G32: =MIN(G31,'01_CONTROL'!$C$64*G31) | H32: =MIN(H31,'01_CONTROL'!$C$64*H31) | I32: =MIN(I31,'01_CONTROL'!$C$64*I31) | J32: =MIN(J31,'01_CONTROL'!$C$64*J31) | K32: =MIN(K31,'01_CONTROL'!$C$64*K31) | L32: =MIN(L31,'01_CONTROL'!$C$64*L31)
B33: Optional sweep | C33: DKKm | E33: 0 | F33: ='07_CASH_FLOW_WATERFALL'!F33 | G33: ='07_CASH_FLOW_WATERFALL'!G33 | H33: ='07_CASH_FLOW_WATERFALL'!H33 | I33: ='07_CASH_FLOW_WATERFALL'!I33 | J33: ='07_CASH_FLOW_WATERFALL'!J33 | K33: ='07_CASH_FLOW_WATERFALL'!K33 | L33: ='07_CASH_FLOW_WATERFALL'!L33
B34: Ending balance | C34: DKKm | E34: =E31-E32-E33 | F34: =F31-F32-F33 | G34: =G31-G32-G33 | H34: =H31-H32-H33 | I34: =I31-I32-I33 | J34: =J31-J32-J33 | K34: =K31-K32-K33 | L34: =L31-L32-L33
B35: All-in rate | C35: % | F35: =IF(IR_Mode="Fixed",'01_CONTROL'!$F$64,MAX(Bench_Rate+'01_CONTROL'!$D$64,'01_CONTROL'!$E$64)) | G35: =IF(IR_Mode="Fixed",'01_CONTROL'!$F$64,MAX(Bench_Rate+'01_CONTROL'!$D$64,'01_CONTROL'!$E$64)) | H35: =IF(IR_Mode="Fixed",'01_CONTROL'!$F$64,MAX(Bench_Rate+'01_CONTROL'!$D$64,'01_CONTROL'!$E$64)) | I35: =IF(IR_Mode="Fixed",'01_CONTROL'!$F$64,MAX(Bench_Rate+'01_CONTROL'!$D$64,'01_CONTROL'!$E$64)) | J35: =IF(IR_Mode="Fixed",'01_CONTROL'!$F$64,MAX(Bench_Rate+'01_CONTROL'!$D$64,'01_CONTROL'!$E$64)) | K35: =IF(IR_Mode="Fixed",'01_CONTROL'!$F$64,MAX(Bench_Rate+'01_CONTROL'!$D$64,'01_CONTROL'!$E$64)) | L35: =IF(IR_Mode="Fixed",'01_CONTROL'!$F$64,MAX(Bench_Rate+'01_CONTROL'!$D$64,'01_CONTROL'!$E$64))
B36: Cash interest | C36: DKKm | E36: 0 | F36: =F31*F35 | G36: =G31*G35 | H36: =H31*H35 | I36: =I31*I35 | J36: =J31*J35 | K36: =K31*K35 | L36: =L31*L35
B38: TERM LOAN B
B40: Opening balance | C40: DKKm | E40: ='06_DEBT_SCHEDULES'!$E$16 | F40: =E43 | G40: =F43 | H40: =G43 | I40: =H43 | J40: =I43 | K40: =J43 | L40: =K43
B41: Mandatory amortization | C41: DKKm | E41: 0 | F41: =MIN(F40,'01_CONTROL'!$C$65*F40) | G41: =MIN(G40,'01_CONTROL'!$C$65*G40) | H41: =MIN(H40,'01_CONTROL'!$C$65*H40) | I41: =MIN(I40,'01_CONTROL'!$C$65*I40) | J41: =MIN(J40,'01_CONTROL'!$C$65*J40) | K41: =MIN(K40,'01_CONTROL'!$C$65*K40) | L41: =MIN(L40,'01_CONTROL'!$C$65*L40)
B42: Optional sweep | C42: DKKm | E42: 0 | F42: ='07_CASH_FLOW_WATERFALL'!F34 | G42: ='07_CASH_FLOW_WATERFALL'!G34 | H42: ='07_CASH_FLOW_WATERFALL'!H34 | I42: ='07_CASH_FLOW_WATERFALL'!I34 | J42: ='07_CASH_FLOW_WATERFALL'!J34 | K42: ='07_CASH_FLOW_WATERFALL'!K34 | L42: ='07_CASH_FLOW_WATERFALL'!L34
B43: Ending balance | C43: DKKm | E43: =E40-E41-E42 | F43: =F40-F41-F42 | G43: =G40-G41-G42 | H43: =H40-H41-H42 | I43: =I40-I41-I42 | J43: =J40-J41-J42 | K43: =K40-K41-K42 | L43: =L40-L41-L42
B44: All-in rate | C44: % | F44: =IF(IR_Mode="Fixed",'01_CONTROL'!$F$65,MAX(Bench_Rate+'01_CONTROL'!$D$65,'01_CONTROL'!$E$65)) | G44: =IF(IR_Mode="Fixed",'01_CONTROL'!$F$65,MAX(Bench_Rate+'01_CONTROL'!$D$65,'01_CONTROL'!$E$65)) | H44: =IF(IR_Mode="Fixed",'01_CONTROL'!$F$65,MAX(Bench_Rate+'01_CONTROL'!$D$65,'01_CONTROL'!$E$65)) | I44: =IF(IR_Mode="Fixed",'01_CONTROL'!$F$65,MAX(Bench_Rate+'01_CONTROL'!$D$65,'01_CONTROL'!$E$65)) | J44: =IF(IR_Mode="Fixed",'01_CONTROL'!$F$65,MAX(Bench_Rate+'01_CONTROL'!$D$65,'01_CONTROL'!$E$65)) | K44: =IF(IR_Mode="Fixed",'01_CONTROL'!$F$65,MAX(Bench_Rate+'01_CONTROL'!$D$65,'01_CONTROL'!$E$65)) | L44: =IF(IR_Mode="Fixed",'01_CONTROL'!$F$65,MAX(Bench_Rate+'01_CONTROL'!$D$65,'01_CONTROL'!$E$65))
B45: Cash interest | C45: DKKm | E45: 0 | F45: =F40*F44 | G45: =G40*G44 | H45: =H40*H44 | I45: =I40*I44 | J45: =J40*J44 | K45: =K40*K44 | L45: =L40*L44
B47: SENIOR SECURED NOTES
B49: Opening balance | C49: DKKm | E49: ='06_DEBT_SCHEDULES'!$E$17 | F49: =E52 | G49: =F52 | H49: =G52 | I49: =H52 | J49: =I52 | K49: =J52 | L49: =K52
B50: Mandatory amortization | C50: DKKm | E50: 0 | F50: =MIN(F49,'01_CONTROL'!$C$66*F49) | G50: =MIN(G49,'01_CONTROL'!$C$66*G49) | H50: =MIN(H49,'01_CONTROL'!$C$66*H49) | I50: =MIN(I49,'01_CONTROL'!$C$66*I49) | J50: =MIN(J49,'01_CONTROL'!$C$66*J49) | K50: =MIN(K49,'01_CONTROL'!$C$66*K49) | L50: =MIN(L49,'01_CONTROL'!$C$66*L49)
...

Sheet 07_CASH_FLOW_WATERFALL
B1: LBO Model Builder (Training Simulation)
B2: CHECKS: | C2: =HYPERLINK("#'90_CHECKS'!B6",'90_CHECKS'!$C$22)
B3: Checks: | C3: =HYPERLINK("#'90_CHECKS'!B2","Go to 90_CHECKS")
B4: Units: | C4: DKKm
B5: Version: | C5: v0.1
B6: Date: | C6: 46069
B7: Period end | E7: 46022 | F7: 46387 | G7: 46752 | H7: 47118 | I7: 47483 | J7: 47848 | K7: 48213 | L7: 48579
B8: Period | E8: LTM | F8: 2026E | G8: 2027E | H8: 2028E | I8: 2029E | J8: 2030E | K8: 2031E | L8: 2032E
B9: Year # | E9: 0 | F9: 1 | G9: 2 | H9: 3 | I9: 4 | J9: 5 | K9: 6 | L9: 7
B10: CASH FLOW WATERFALL (NON-CIRCULAR)
B12: CASH AVAILABLE FOR DEBT SERVICE (DKKM)
B14: EBITDA | C14: DKKm | E14: ='04_OPERATING_MODEL'!E15 | F14: ='04_OPERATING_MODEL'!F15 | G14: ='04_OPERATING_MODEL'!G15 | H14: ='04_OPERATING_MODEL'!H15 | I14: ='04_OPERATING_MODEL'!I15 | J14: ='04_OPERATING_MODEL'!J15 | K14: ='04_OPERATING_MODEL'!K15 | L14: ='04_OPERATING_MODEL'!L15
B15: Cash taxes (levered) | C15: DKKm | E15: =-MAX(0,'04_OPERATING_MODEL'!E18-E28)*'01_CONTROL'!$D$26 | F15: =-MAX(0,'04_OPERATING_MODEL'!F18-F28)*'01_CONTROL'!$D$26 | G15: =-MAX(0,'04_OPERATING_MODEL'!G18-G28)*'01_CONTROL'!$D$26 | H15: =-MAX(0,'04_OPERATING_MODEL'!H18-H28)*'01_CONTROL'!$D$26 | I15: =-MAX(0,'04_OPERATING_MODEL'!I18-I28)*'01_CONTROL'!$D$26 | J15: =-MAX(0,'04_OPERATING_MODEL'!J18-J28)*'01_CONTROL'!$D$26 | K15: =-MAX(0,'04_OPERATING_MODEL'!K18-K28)*'01_CONTROL'!$D$26 | L15: =-MAX(0,'04_OPERATING_MODEL'!L18-L28)*'01_CONTROL'!$D$26
B16: Change in NWC (cash effect) | C16: DKKm | E16: =-'04_OPERATING_MODEL'!E32 | F16: =-'04_OPERATING_MODEL'!F32 | G16: =-'04_OPERATING_MODEL'!G32 | H16: =-'04_OPERATING_MODEL'!H32 | I16: =-'04_OPERATING_MODEL'!I32 | J16: =-'04_OPERATING_MODEL'!J32 | K16: =-'04_OPERATING_MODEL'!K32 | L16: =-'04_OPERATING_MODEL'!L32
B17: Capex (cash effect) | C17: DKKm | E17: ='04_OPERATING_MODEL'!E36 | F17: ='04_OPERATING_MODEL'!F36 | G17: ='04_OPERATING_MODEL'!G36 | H17: ='04_OPERATING_MODEL'!H36 | I17: ='04_OPERATING_MODEL'!I36 | J17: ='04_OPERATING_MODEL'!J36 | K17: ='04_OPERATING_MODEL'!K36 | L17: ='04_OPERATING_MODEL'!L36
B18: Other (cash) | C18: DKKm | E18: 0 | F18: 0 | G18: 0 | H18: 0 | I18: 0 | J18: 0 | K18: 0 | L18: 0
B19: Cash before debt service | C19: DKKm | E19: =SUM(E14:E18) | F19: =SUM(F14:F18) | G19: =SUM(G14:G18) | H19: =SUM(H14:H18) | I19: =SUM(I14:I18) | J19: =SUM(J14:J18) | K19: =SUM(K14:K18) | L19: =SUM(L14:L18)
B20: Cash interest (total) | C20: DKKm | E20: =-('06_DEBT_SCHEDULES'!E27+'06_DEBT_SCHEDULES'!E36+'06_DEBT_SCHEDULES'!E45+'06_DEBT_SCHEDULES'!E54+'06_DEBT_SCHEDULES'!E63) | F20: =-('06_DEBT_SCHEDULES'!F27+'06_DEBT_SCHEDULES'!F36+'06_DEBT_SCHEDULES'!F45+'06_DEBT_SCHEDULES'!F54+'06_DEBT_SCHEDULES'!F63) | G20: =-('06_DEBT_SCHEDULES'!G27+'06_DEBT_SCHEDULES'!G36+'06_DEBT_SCHEDULES'!G45+'06_DEBT_SCHEDULES'!G54+'06_DEBT_SCHEDULES'!G63) | H20: =-('06_DEBT_SCHEDULES'!H27+'06_DEBT_SCHEDULES'!H36+'06_DEBT_SCHEDULES'!H45+'06_DEBT_SCHEDULES'!H54+'06_DEBT_SCHEDULES'!H63) | I20: =-('06_DEBT_SCHEDULES'!I27+'06_DEBT_SCHEDULES'!I36+'06_DEBT_SCHEDULES'!I45+'06_DEBT_SCHEDULES'!I54+'06_DEBT_SCHEDULES'!I63) | J20: =-('06_DEBT_SCHEDULES'!J27+'06_DEBT_SCHEDULES'!J36+'06_DEBT_SCHEDULES'!J45+'06_DEBT_SCHEDULES'!J54+'06_DEBT_SCHEDULES'!J63) | K20: =-('06_DEBT_SCHEDULES'!K27+'06_DEBT_SCHEDULES'!K36+'06_DEBT_SCHEDULES'!K45+'06_DEBT_SCHEDULES'!K54+'06_DEBT_SCHEDULES'!K63) | L20: =-('06_DEBT_SCHEDULES'!L27+'06_DEBT_SCHEDULES'!L36+'06_DEBT_SCHEDULES'!L45+'06_DEBT_SCHEDULES'!L54+'06_DEBT_SCHEDULES'!L63)
B21: Cash after interest | C21: DKKm | E21: =E19+E20 | F21: =F19+F20 | G21: =G19+G20 | H21: =H19+H20 | I21: =I19+I20 | J21: =J19+J20 | K21: =K19+K20 | L21: =L19+L20
B22: Mandatory amort (total) | C22: DKKm | E22: =-('06_DEBT_SCHEDULES'!E32+'06_DEBT_SCHEDULES'!E41+'06_DEBT_SCHEDULES'!E50+'06_DEBT_SCHEDULES'!E59) | F22: =-('06_DEBT_SCHEDULES'!F32+'06_DEBT_SCHEDULES'!F41+'06_DEBT_SCHEDULES'!F50+'06_DEBT_SCHEDULES'!F59) | G22: =-('06_DEBT_SCHEDULES'!G32+'06_DEBT_SCHEDULES'!G41+'06_DEBT_SCHEDULES'!G50+'06_DEBT_SCHEDULES'!G59) | H22: =-('06_DEBT_SCHEDULES'!H32+'06_DEBT_SCHEDULES'!H41+'06_DEBT_SCHEDULES'!H50+'06_DEBT_SCHEDULES'!H59) | I22: =-('06_DEBT_SCHEDULES'!I32+'06_DEBT_SCHEDULES'!I41+'06_DEBT_SCHEDULES'!I50+'06_DEBT_SCHEDULES'!I59) | J22: =-('06_DEBT_SCHEDULES'!J32+'06_DEBT_SCHEDULES'!J41+'06_DEBT_SCHEDULES'!J50+'06_DEBT_SCHEDULES'!J59) | K22: =-('06_DEBT_SCHEDULES'!K32+'06_DEBT_SCHEDULES'!K41+'06_DEBT_SCHEDULES'!K50+'06_DEBT_SCHEDULES'!K59) | L22: =-('06_DEBT_SCHEDULES'!L32+'06_DEBT_SCHEDULES'!L41+'06_DEBT_SCHEDULES'!L50+'06_DEBT_SCHEDULES'!L59)
B23: Cash after mandatory amort | C23: DKKm | E23: =E21+E22 | F23: =F21+F22 | G23: =G21+G22 | H23: =H21+H22 | I23: =I21+I22 | J23: =J21+J22 | K23: =K21+K22 | L23: =L21+L22
B24: Sweep % (active) | C24: % | E24: ='01_CONTROL'!$G$54 | F24: ='01_CONTROL'!$G$54 | G24: ='01_CONTROL'!$G$54 | H24: ='01_CONTROL'!$G$54 | I24: ='01_CONTROL'!$G$54 | J24: ='01_CONTROL'!$G$54 | K24: ='01_CONTROL'!$G$54 | L24: ='01_CONTROL'!$G$54
B25: Cash available for optional sweep | C25: DKKm | E25: =MAX(0,E23)*E24 | F25: =MAX(0,F23)*F24 | G25: =MAX(0,G23)*G24 | H25: =MAX(0,H23)*H24 | I25: =MAX(0,I23)*I24 | J25: =MAX(0,J23)*J24 | K25: =MAX(0,K23)*K24 | L25: =MAX(0,L23)*L24
B26: Retained cash (non-swept) | C26: DKKm | E26: =MAX(0,E23)-E25 | F26: =MAX(0,F23)-F25 | G26: =MAX(0,G23)-G25 | H26: =MAX(0,H23)-H25 | I26: =MAX(0,I23)-I25 | J26: =MAX(0,J23)-J25 | K26: =MAX(0,K23)-K25 | L26: =MAX(0,L23)-L25
B27: Cash deficit (requires revolver draw) | C27: DKKm | E27: =-MIN(0,E23) | F27: =-MIN(0,F23) | G27: =-MIN(0,G23) | H27: =-MIN(0,H23) | I27: =-MIN(0,I23) | J27: =-MIN(0,J23) | K27: =-MIN(0,K23) | L27: =-MIN(0,L23)
B28: Interest sum helper (positive) | C28: DKKm | E28: 0 | F28: =('06_DEBT_SCHEDULES'!F27+'06_DEBT_SCHEDULES'!F36+'06_DEBT_SCHEDULES'!F45+'06_DEBT_SCHEDULES'!F54+'06_DEBT_SCHEDULES'!F63) | G28: =('06_DEBT_SCHEDULES'!G27+'06_DEBT_SCHEDULES'!G36+'06_DEBT_SCHEDULES'!G45+'06_DEBT_SCHEDULES'!G54+'06_DEBT_SCHEDULES'!G63) | H28: =('06_DEBT_SCHEDULES'!H27+'06_DEBT_SCHEDULES'!H36+'06_DEBT_SCHEDULES'!H45+'06_DEBT_SCHEDULES'!H54+'06_DEBT_SCHEDULES'!H63) | I28: =('06_DEBT_SCHEDULES'!I27+'06_DEBT_SCHEDULES'!I36+'06_DEBT_SCHEDULES'!I45+'06_DEBT_SCHEDULES'!I54+'06_DEBT_SCHEDULES'!I63) | J28: =('06_DEBT_SCHEDULES'!J27+'06_DEBT_SCHEDULES'!J36+'06_DEBT_SCHEDULES'!J45+'06_DEBT_SCHEDULES'!J54+'06_DEBT_SCHEDULES'!J63) | K28: =('06_DEBT_SCHEDULES'!K27+'06_DEBT_SCHEDULES'!K36+'06_DEBT_SCHEDULES'!K45+'06_DEBT_SCHEDULES'!K54+'06_DEBT_SCHEDULES'!K63) | L28: =('06_DEBT_SCHEDULES'!L27+'06_DEBT_SCHEDULES'!L36+'06_DEBT_SCHEDULES'!L45+'06_DEBT_SCHEDULES'!L54+'06_DEBT_SCHEDULES'!L63)
B29: ALLOCATION: REVOLVER THEN SWEEP ORDER
B30: Revolver draw | C30: DKKm | E30: 0 | F30: =MIN('06_DEBT_SCHEDULES'!$E$14-'06_DEBT_SCHEDULES'!F22, F27) | G30: =MIN('06_DEBT_SCHEDULES'!$E$14-'06_DEBT_SCHEDULES'!G22, G27) | H30: =MIN('06_DEBT_SCHEDULES'!$E$14-'06_DEBT_SCHEDULES'!H22, H27) | I30: =MIN('06_DEBT_SCHEDULES'!$E$14-'06_DEBT_SCHEDULES'!I22, I27) | J30: =MIN('06_DEBT_SCHEDULES'!$E$14-'06_DEBT_SCHEDULES'!J22, J27) | K30: =MIN('06_DEBT_SCHEDULES'!$E$14-'06_DEBT_SCHEDULES'!K22, K27) | L30: =MIN('06_DEBT_SCHEDULES'!$E$14-'06_DEBT_SCHEDULES'!L22, L27)
B31: Revolver repay | C31: DKKm | E31: 0 | F31: =MIN('06_DEBT_SCHEDULES'!F22, F25) | G31: =MIN('06_DEBT_SCHEDULES'!G22, G25) | H31: =MIN('06_DEBT_SCHEDULES'!H22, H25) | I31: =MIN('06_DEBT_SCHEDULES'!I22, I25) | J31: =MIN('06_DEBT_SCHEDULES'!J22, J25) | K31: =MIN('06_DEBT_SCHEDULES'!K22, K25) | L31: =MIN('06_DEBT_SCHEDULES'!L22, L25)
B32: Remaining sweep after revolver | C32: DKKm | E32: 0 | F32: =MAX(0,F25-F31) | G32: =MAX(0,G25-G31) | H32: =MAX(0,H25-H31) | I32: =MAX(0,I25-I31) | J32: =MAX(0,J25-J31) | K32: =MAX(0,K25-K31) | L32: =MAX(0,L25-L31)
B33: Sweep to Term Loan B | C33: DKKm | E33: 0 | F33: =MIN(F32, MAX(0,'06_DEBT_SCHEDULES'!F40-'06_DEBT_SCHEDULES'!F41)) | G33: =MIN(G32, MAX(0,'06_DEBT_SCHEDULES'!G40-'06_DEBT_SCHEDULES'!G41)) | H33: =MIN(H32, MAX(0,'06_DEBT_SCHEDULES'!H40-'06_DEBT_SCHEDULES'!H41)) | I33: =MIN(I32, MAX(0,'06_DEBT_SCHEDULES'!I40-'06_DEBT_SCHEDULES'!I41)) | J33: =MIN(J32, MAX(0,'06_DEBT_SCHEDULES'!J40-'06_DEBT_SCHEDULES'!J41)) | K33: =MIN(K32, MAX(0,'06_DEBT_SCHEDULES'!K40-'06_DEBT_SCHEDULES'!K41)) | L33: =MIN(L32, MAX(0,'06_DEBT_SCHEDULES'!L40-'06_DEBT_SCHEDULES'!L41))
B34: Sweep to Term Loan A | C34: DKKm | E34: 0 | F34: =MIN(MAX(0,F32-F33), MAX(0,'06_DEBT_SCHEDULES'!F31-'06_DEBT_SCHEDULES'!F32)) | G34: =MIN(MAX(0,G32-G33), MAX(0,'06_DEBT_SCHEDULES'!G31-'06_DEBT_SCHEDULES'!G32)) | H34: =MIN(MAX(0,H32-H33), MAX(0,'06_DEBT_SCHEDULES'!H31-'06_DEBT_SCHEDULES'!H32)) | I34: =MIN(MAX(0,I32-I33), MAX(0,'06_DEBT_SCHEDULES'!I31-'06_DEBT_SCHEDULES'!I32)) | J34: =MIN(MAX(0,J32-J33), MAX(0,'06_DEBT_SCHEDULES'!J31-'06_DEBT_SCHEDULES'!J32)) | K34: =MIN(MAX(0,K32-K33), MAX(0,'06_DEBT_SCHEDULES'!K31-'06_DEBT_SCHEDULES'!K32)) | L34: =MIN(MAX(0,L32-L33), MAX(0,'06_DEBT_SCHEDULES'!L31-'06_DEBT_SCHEDULES'!L32))
B35: Sweep to SSN | C35: DKKm | E35: 0 | F35: =MIN(MAX(0,F32-F33-F34), MAX(0,'06_DEBT_SCHEDULES'!F49-'06_DEBT_SCHEDULES'!F50)) | G35: =MIN(MAX(0,G32-G33-G34), MAX(0,'06_DEBT_SCHEDULES'!G49-'06_DEBT_SCHEDULES'!G50)) | H35: =MIN(MAX(0,H32-H33-H34), MAX(0,'06_DEBT_SCHEDULES'!H49-'06_DEBT_SCHEDULES'!H50)) | I35: =MIN(MAX(0,I32-I33-I34), MAX(0,'06_DEBT_SCHEDULES'!I49-'06_DEBT_SCHEDULES'!I50)) | J35: =MIN(MAX(0,J32-J33-J34), MAX(0,'06_DEBT_SCHEDULES'!J49-'06_DEBT_SCHEDULES'!J50)) | K35: =MIN(MAX(0,K32-K33-K34), MAX(0,'06_DEBT_SCHEDULES'!K49-'06_DEBT_SCHEDULES'!K50)) | L35: =MIN(MAX(0,L32-L33-L34), MAX(0,'06_DEBT_SCHEDULES'!L49-'06_DEBT_SCHEDULES'!L50))
B36: Sweep to Mezz/PIK | C36: DKKm | E36: 0 | F36: =MIN(MAX(0,F32-F33-F34-F35), MAX(0,'06_DEBT_SCHEDULES'!F58-'06_DEBT_SCHEDULES'!F59)) | G36: =MIN(MAX(0,G32-G33-G34-G35), MAX(0,'06_DEBT_SCHEDULES'!G58-'06_DEBT_SCHEDULES'!G59)) | H36: =MIN(MAX(0,H32-H33-H34-H35), MAX(0,'06_DEBT_SCHEDULES'!H58-'06_DEBT_SCHEDULES'!H59)) | I36: =MIN(MAX(0,I32-I33-I34-I35), MAX(0,'06_DEBT_SCHEDULES'!I58-'06_DEBT_SCHEDULES'!I59)) | J36: =MIN(MAX(0,J32-J33-J34-J35), MAX(0,'06_DEBT_SCHEDULES'!J58-'06_DEBT_SCHEDULES'!J59)) | K36: =MIN(MAX(0,K32-K33-K34-K35), MAX(0,'06_DEBT_SCHEDULES'!K58-'06_DEBT_SCHEDULES'!K59)) | L36: =MIN(MAX(0,L32-L33-L34-L35), MAX(0,'06_DEBT_SCHEDULES'!L58-'06_DEBT_SCHEDULES'!L59))
B38: CASH BALANCE
B40: Residual sweep (not allocated) | C40: DKKm | E40: 0 | F40: =MAX(0,F32-F33-F34-F35-F36) | G40: =MAX(0,G32-G33-G34-G35-G36) | H40: =MAX(0,H32-H33-H34-H35-H36) | I40: =MAX(0,I32-I33-I34-I35-I36) | J40: =MAX(0,J32-J33-J34-J35-J36) | K40: =MAX(0,K32-K33-K34-K35-K36) | L40: =MAX(0,L32-L33-L34-L35-L36)
B41: Ending cash balance | C41: DKKm | E41: ='01_CONTROL'!$D$33 | F41: =IF(F27>0,0,F26+F40) | G41: =IF(G27>0,0,G26+G40) | H41: =IF(H27>0,0,H26+H40) | I41: =IF(I27>0,0,I26+I40) | J41: =IF(J27>0,0,J26+J40) | K41: =IF(K27>0,0,K26+K40) | L41: =IF(L27>0,0,L26+L40)
B42: Cash bridge check (should be 0) | C42: DKKm | E42: 0 | F42: =F23 - (F26+F31+F33+F34+F35+F36+F40) + F30 | G42: =G23 - (G26+G31+G33+G34+G35+G36+G40) + G30 | H42: =H23 - (H26+H31+H33+H34+H35+H36+H40) + H30 | I42: =I23 - (I26+I31+I33+I34+I35+I36+I40) + I30 | J42: =J23 - (J26+J31+J33+J34+J35+J36+J40) + J30 | K42: =K23 - (K26+K31+K33+K34+K35+K36+K40) + K30 | L42: =L23 - (L26+L31+L33+L34+L35+L36+L40) + L30

Sheet 08_EXIT_AND_EQUITY_BRIDGE
B1: LBO Model Builder (Training Simulation)
B2: CHECKS: | C2: =HYPERLINK("#'90_CHECKS'!B6",'90_CHECKS'!$C$22)
B3: Checks: | C3: =HYPERLINK("#'90_CHECKS'!B2","Go to 90_CHECKS")
B4: Units: | C4: DKKm
B5: Version: | C5: v0.1
B6: Date: | C6: 46069
B10: EXIT AND EQUITY BRIDGE
B12: EXIT ASSUMPTIONS AND EV
B14: Exit year (hold period, years) | D14: ='01_CONTROL'!$D$14
B15: Exit EBITDA (DKKm) | D15: =INDEX('04_OPERATING_MODEL'!$E$15:$L$15,1,Hold_Col)
B16: Exit method | D16: ='01_CONTROL'!$D$17
B17: Exit multiple (x) | D17: ='01_CONTROL'!$D$18
B18: Exit equity value target (DKKm) | D18: ='01_CONTROL'!$D$19
B19: Exit fees (% EV) | D19: ='01_CONTROL'!$D$35
B21: EV TO EQUITY BRIDGE (DKKM)
B23: Exit EV (DKKm) | D23: =IF(Exit_Method="Exit Multiple", D15*Exit_Multiple, (Exit_Equity_Target + D24 - D25)/(1-D19))
B24: Less: net debt at exit | D24: =INDEX('06_DEBT_SCHEDULES'!$E$67:$L$67,1,Hold_Col)
B25: Plus: cash at exit | D25: =INDEX('07_CASH_FLOW_WATERFALL'!$E$41:$L$41,1,Hold_Col)
B26: Less: exit fees | D26: =D23*D19
B27: Exit equity proceeds | D27: =D23-D24+D25-D26
B29: EQUITY PROCEEDS SPLIT (DKKM)
B31: Sponsor equity invested | D31: ='05_SOURCES_AND_USES'!$D$38
B32: Mgmt equity invested | D32: ='05_SOURCES_AND_USES'!$D$39
B33: Total equity invested | D33: ='05_SOURCES_AND_USES'!$D$40
B34: Sponsor ownership (%) | D34: =IF(D33=0,0,D31/D33)
B35: Sponsor proceeds at exit | D35: =D27*D34
B36: Mgmt proceeds at exit | D36: =D27-D35

Sheet 09_RETURNS
B1: LBO Model Builder (Training Simulation)
B2: CHECKS: | C2: =HYPERLINK("#'90_CHECKS'!B6",'90_CHECKS'!$C$22)
B3: Checks: | C3: =HYPERLINK("#'90_CHECKS'!B2","Go to 90_CHECKS")
B4: Units: | C4: DKKm
B5: Version: | C5: v0.1
B6: Date: | C6: 46069
E9: ='04_OPERATING_MODEL'!E9 | F9: ='04_OPERATING_MODEL'!F9 | G9: ='04_OPERATING_MODEL'!G9 | H9: ='04_OPERATING_MODEL'!H9 | I9: ='04_OPERATING_MODEL'!I9 | J9: ='04_OPERATING_MODEL'!J9 | K9: ='04_OPERATING_MODEL'!K9 | L9: ='04_OPERATING_MODEL'!L9
B10: RETURNS
B12: EQUITY CASH FLOWS (DKKM)
B14: Sponsor equity CF | C14: DKKm | E14: =-'05_SOURCES_AND_USES'!$D$38 | F14: =IF(F9=Hold_Y,'08_EXIT_AND_EQUITY_BRIDGE'!$D$35,0) | G14: =IF(G9=Hold_Y,'08_EXIT_AND_EQUITY_BRIDGE'!$D$35,0) | H14: =IF(H9=Hold_Y,'08_EXIT_AND_EQUITY_BRIDGE'!$D$35,0) | I14: =IF(I9=Hold_Y,'08_EXIT_AND_EQUITY_BRIDGE'!$D$35,0) | J14: =IF(J9=Hold_Y,'08_EXIT_AND_EQUITY_BRIDGE'!$D$35,0) | K14: =IF(K9=Hold_Y,'08_EXIT_AND_EQUITY_BRIDGE'!$D$35,0) | L14: =IF(L9=Hold_Y,'08_EXIT_AND_EQUITY_BRIDGE'!$D$35,0)
B15: Mgmt equity CF | C15: DKKm | E15: =-'05_SOURCES_AND_USES'!$D$39 | F15: =IF(F9=Hold_Y,'08_EXIT_AND_EQUITY_BRIDGE'!$D$36,0) | G15: =IF(G9=Hold_Y,'08_EXIT_AND_EQUITY_BRIDGE'!$D$36,0) | H15: =IF(H9=Hold_Y,'08_EXIT_AND_EQUITY_BRIDGE'!$D$36,0) | I15: =IF(I9=Hold_Y,'08_EXIT_AND_EQUITY_BRIDGE'!$D$36,0) | J15: =IF(J9=Hold_Y,'08_EXIT_AND_EQUITY_BRIDGE'!$D$36,0) | K15: =IF(K9=Hold_Y,'08_EXIT_AND_EQUITY_BRIDGE'!$D$36,0) | L15: =IF(L9=Hold_Y,'08_EXIT_AND_EQUITY_BRIDGE'!$D$36,0)
B16: Total equity CF | C16: DKKm | E16: =E14+E15 | F16: =F14+F15 | G16: =G14+G15 | H16: =H14+H15 | I16: =I14+I15 | J16: =J14+J15 | K16: =K14+K15 | L16: =L14+L15
B18: KEY METRICS
B20: Sponsor IRR | D20: =IRR(OFFSET($E$14,0,0,1,Hold_Col))
B21: Sponsor MOIC | D21: =IF('05_SOURCES_AND_USES'!$D$38=0,0,'08_EXIT_AND_EQUITY_BRIDGE'!$D$35/'05_SOURCES_AND_USES'!$D$38)
B22: Mgmt IRR | D22: =IRR(OFFSET($E$15,0,0,1,Hold_Col))
B23: Total equity IRR | D23: =IRR(OFFSET($E$16,0,0,1,Hold_Col))
B24: Total equity MOIC | D24: =IF('05_SOURCES_AND_USES'!$D$40=0,0,'08_EXIT_AND_EQUITY_BRIDGE'!$D$27/'05_SOURCES_AND_USES'!$D$40)
B25: Deleveraging (Net debt entry -> exit) | D25: ='05_SOURCES_AND_USES'!$D$37 - '08_EXIT_AND_EQUITY_BRIDGE'!$D$24

Sheet 10_COVENANTS_AND_CREDIT_METRICS
B1: LBO Model Builder (Training Simulation)
B2: CHECKS: | C2: =HYPERLINK("#'90_CHECKS'!B6",'90_CHECKS'!$C$22)
B3: Checks: | C3: =HYPERLINK("#'90_CHECKS'!B2","Go to 90_CHECKS")
B4: Units: | C4: DKKm
B5: Version: | C5: v0.1
B6: Date: | C6: 46069
B7: Period end | E7: 46022 | F7: 46387 | G7: 46752 | H7: 47118 | I7: 47483 | J7: 47848 | K7: 48213 | L7: 48579
B8: Period | E8: LTM | F8: 2026E | G8: 2027E | H8: 2028E | I8: 2029E | J8: 2030E | K8: 2031E | L8: 2032E
B9: Year # | E9: 0 | F9: 1 | G9: 2 | H9: 3 | I9: 4 | J9: 5 | K9: 6 | L9: 7
B10: COVENANTS AND CREDIT METRICS
B12: CREDIT METRICS (DKKM / X)
B14: EBITDA | C14: DKKm | E14: ='04_OPERATING_MODEL'!E15 | F14: ='04_OPERATING_MODEL'!F15 | G14: ='04_OPERATING_MODEL'!G15 | H14: ='04_OPERATING_MODEL'!H15 | I14: ='04_OPERATING_MODEL'!I15 | J14: ='04_OPERATING_MODEL'!J15 | K14: ='04_OPERATING_MODEL'!K15 | L14: ='04_OPERATING_MODEL'!L15
B15: Total debt (ending) | C15: DKKm | E15: ='06_DEBT_SCHEDULES'!E67 | F15: ='06_DEBT_SCHEDULES'!F67 | G15: ='06_DEBT_SCHEDULES'!G67 | H15: ='06_DEBT_SCHEDULES'!H67 | I15: ='06_DEBT_SCHEDULES'!I67 | J15: ='06_DEBT_SCHEDULES'!J67 | K15: ='06_DEBT_SCHEDULES'!K67 | L15: ='06_DEBT_SCHEDULES'!L67
B16: Cash (ending) | C16: DKKm | E16: ='07_CASH_FLOW_WATERFALL'!E41 | F16: ='07_CASH_FLOW_WATERFALL'!F41 | G16: ='07_CASH_FLOW_WATERFALL'!G41 | H16: ='07_CASH_FLOW_WATERFALL'!H41 | I16: ='07_CASH_FLOW_WATERFALL'!I41 | J16: ='07_CASH_FLOW_WATERFALL'!J41 | K16: ='07_CASH_FLOW_WATERFALL'!K41 | L16: ='07_CASH_FLOW_WATERFALL'!L41
B17: Net debt | C17: DKKm | E17: =E15-E16 | F17: =F15-F16 | G17: =G15-G16 | H17: =H15-H16 | I17: =I15-I16 | J17: =J15-J16 | K17: =K15-K16 | L17: =L15-L16
B18: Gross leverage (x) | C18: x | E18: =IF(E14=0,0,E15/E14) | F18: =IF(F14=0,0,F15/F14) | G18: =IF(G14=0,0,G15/G14) | H18: =IF(H14=0,0,H15/H14) | I18: =IF(I14=0,0,I15/I14) | J18: =IF(J14=0,0,J15/J14) | K18: =IF(K14=0,0,K15/K14) | L18: =IF(L14=0,0,L15/L14)
B19: Net leverage (x) | C19: x | E19: =IF(E14=0,0,E17/E14) | F19: =IF(F14=0,0,F17/F14) | G19: =IF(G14=0,0,G17/G14) | H19: =IF(H14=0,0,H17/H14) | I19: =IF(I14=0,0,I17/I14) | J19: =IF(J14=0,0,J17/J14) | K19: =IF(K14=0,0,K17/K14) | L19: =IF(L14=0,0,L17/L14)
B20: Cash interest (positive) | C20: DKKm | E20: ='07_CASH_FLOW_WATERFALL'!E28 | F20: ='07_CASH_FLOW_WATERFALL'!F28 | G20: ='07_CASH_FLOW_WATERFALL'!G28 | H20: ='07_CASH_FLOW_WATERFALL'!H28 | I20: ='07_CASH_FLOW_WATERFALL'!I28 | J20: ='07_CASH_FLOW_WATERFALL'!J28 | K20: ='07_CASH_FLOW_WATERFALL'!K28 | L20: ='07_CASH_FLOW_WATERFALL'!L28
B21: Interest coverage (x) | C21: x | E21: =IF(E20=0,0,E14/E20) | F21: =IF(F20=0,0,F14/F20) | G21: =IF(G20=0,0,G14/G20) | H21: =IF(H20=0,0,H14/H20) | I21: =IF(I20=0,0,I14/I20) | J21: =IF(J20=0,0,J14/J20) | K21: =IF(K20=0,0,K14/K20) | L21: =IF(L20=0,0,L14/L20)
B22: Undrawn revolver | C22: DKKm | E22: ='06_DEBT_SCHEDULES'!$E$14-'06_DEBT_SCHEDULES'!E25 | F22: ='06_DEBT_SCHEDULES'!$F$14-'06_DEBT_SCHEDULES'!F25 | G22: ='06_DEBT_SCHEDULES'!$G$14-'06_DEBT_SCHEDULES'!G25 | H22: ='06_DEBT_SCHEDULES'!$H$14-'06_DEBT_SCHEDULES'!H25 | I22: ='06_DEBT_SCHEDULES'!$I$14-'06_DEBT_SCHEDULES'!I25 | J22: ='06_DEBT_SCHEDULES'!$J$14-'06_DEBT_SCHEDULES'!J25 | K22: ='06_DEBT_SCHEDULES'!$K$14-'06_DEBT_SCHEDULES'!K25 | L22: ='06_DEBT_SCHEDULES'!$L$14-'06_DEBT_SCHEDULES'!L25
B23: Liquidity (cash + undrawn) | C23: DKKm | E23: =E16+E22 | F23: =F16+F22 | G23: =G16+G22 | H23: =H16+H22 | I23: =I16+I22 | J23: =J16+J22 | K23: =K16+K22 | L23: =L16+L22
B25: COVENANT HEADROOM
B27: Net leverage headroom (max - actual) | C27: x | E27: =Coven_NetLev_Max-E19 | F27: =Coven_NetLev_Max-F19 | G27: =Coven_NetLev_Max-G19 | H27: =Coven_NetLev_Max-H19 | I27: =Coven_NetLev_Max-I19 | J27: =Coven_NetLev_Max-J19 | K27: =Coven_NetLev_Max-K19 | L27: =Coven_NetLev_Max-L19
B28: Interest coverage headroom (actual - min) | C28: x | E28: =E21-Coven_IntCov_Min | F28: =F21-Coven_IntCov_Min | G28: =G21-Coven_IntCov_Min | H28: =H21-Coven_IntCov_Min | I28: =I21-Coven_IntCov_Min | J28: =J21-Coven_IntCov_Min | K28: =K21-Coven_IntCov_Min | L28: =L21-Coven_IntCov_Min
B29: Liquidity headroom (actual - target) | C29: DKKm | E29: =E23-Min_Liq_Target | F29: =F23-Min_Liq_Target | G29: =G23-Min_Liq_Target | H29: =H23-Min_Liq_Target | I29: =I23-Min_Liq_Target | J29: =J23-Min_Liq_Target | K29: =K23-Min_Liq_Target | L29: =L23-Min_Liq_Target
B32: SUMMARY (FOR DASHBOARD TILES)
B34: Peak net leverage (x) | D34: =MAX($F$19:$L$19)
B35: Min liquidity (DKKm) | D35: =MIN($F$23:$L$23)
B36: Min covenant headroom (net lev, x) | D36: =MIN($F$27:$L$27)
B37: Min covenant headroom (int cov, x) | D37: =MIN($F$28:$L$28)

Sheet 11_SENSITIVITIES
B2: CHECKS: | C2: =HYPERLINK("#'90_CHECKS'!B6",'90_CHECKS'!$C$22)
B4: Sensitivities (data tables)
B6: Data tables compute in Excel. Set Calculation to Automatic.
B8: IRR heatmap: Exit multiple vs Revenue growth (proxy for EBITDA CAGR)
C12: ='09_RETURNS'!$D$20 | D12: -0.02 | E12: 0 | F12: 0.02 | G12: 0.04 | H12: 0.06 | I12: 0.08 | J12: 0.1
C13: 7
C14: 8
C15: 9 | K15: SENSITIVITY HELPERS (links to core model)
C16: 10 | K16: LTM EBITDA (DKKm) | L16: ='01_CONTROL'!$D$32
C17: 11 | K17: Leverage target (x) | L17: ='01_CONTROL'!$D$48
K18: Total new debt (DKKm) | L18: =$L$16*$L$17
K19: Debt at exit (DKKm) | L19: =INDEX('06_DEBT_SCHEDULES'!$E$67:$L$67,1,Hold_Col)
K20: Cash at exit (DKKm) | L20: =INDEX('07_CASH_FLOW_WATERFALL'!$E$41:$L$41,1,Hold_Col)
K21: Exit EBITDA (DKKm) | L21: =INDEX('04_OPERATING_MODEL'!$E$15:$L$15,1,Hold_Col)
K22: Exit fees (% EV) | L22: ='01_CONTROL'!$D$35
D23: 9 | E23: 10 | F23: 11 | G23: 12 | H23: 13 | I23: 14 | K23: Advisory fee (% EV) | L23: ='01_CONTROL'!$D$56
C24: 7 | D24: =IFERROR(IF(((D$23*$L$16)*(1+$L$23)+$L$18*$L$24-$L$18)<=0,NA(),((($C24*$L$21)-$L$19+$L$20-($C24*$L$21)*$L$22)/((D$23*$L$16)*(1+$L$23)+$L$18*$L$24-$L$18))^(1/Hold_Y)-1),NA()) | E24: =IFERROR(IF(((E$23*$L$16)*(1+$L$23)+$L$18*$L$24-$L$18)<=0,NA(),((($C24*$L$21)-$L$19+$L$20-($C24*$L$21)*$L$22)/((E$23*$L$16)*(1+$L$23)+$L$18*$L$24-$L$18))^(1/Hold_Y)-1),NA()) | F24: =IFERROR(IF(((F$23*$L$16)*(1+$L$23)+$L$18*$L$24-$L$18)<=0,NA(),((($C24*$L$21)-$L$19+$L$20-($C24*$L$21)*$L$22)/((F$23*$L$16)*(1+$L$23)+$L$18*$L$24-$L$18))^(1/Hold_Y)-1),NA()) | G24: =IFERROR(IF(((G$23*$L$16)*(1+$L$23)+$L$18*$L$24-$L$18)<=0,NA(),((($C24*$L$21)-$L$19+$L$20-($C24*$L$21)*$L$22)/((G$23*$L$16)*(1+$L$23)+$L$18*$L$24-$L$18))^(1/Hold_Y)-1),NA()) | H24: =IFERROR(IF(((H$23*$L$16)*(1+$L$23)+$L$18*$L$24-$L$18)<=0,NA(),((($C24*$L$21)-$L$19+$L$20-($C24*$L$21)*$L$22)/((H$23*$L$16)*(1+$L$23)+$L$18*$L$24-$L$18))^(1/Hold_Y)-1),NA()) | I24: =IFERROR(IF(((I$23*$L$16)*(1+$L$23)+$L$18*$L$24-$L$18)<=0,NA(),((($C24*$L$21)-$L$19+$L$20-($C24*$L$21)*$L$22)/((I$23*$L$16)*(1+$L$23)+$L$18*$L$24-$L$18))^(1/Hold_Y)-1),NA()) | K24: Financing fee (% debt) | L24: ='01_CONTROL'!$D$57
C25: 8 | D25: =IFERROR(IF(((D$23*$L$16)*(1+$L$23)+$L$18*$L$24-$L$18)<=0,NA(),((($C25*$L$21)-$L$19+$L$20-($C25*$L$21)*$L$22)/((D$23*$L$16)*(1+$L$23)+$L$18*$L$24-$L$18))^(1/Hold_Y)-1),NA()) | E25: =IFERROR(IF(((E$23*$L$16)*(1+$L$23)+$L$18*$L$24-$L$18)<=0,NA(),((($C25*$L$21)-$L$19+$L$20-($C25*$L$21)*$L$22)/((E$23*$L$16)*(1+$L$23)+$L$18*$L$24-$L$18))^(1/Hold_Y)-1),NA()) | F25: =IFERROR(IF(((F$23*$L$16)*(1+$L$23)+$L$18*$L$24-$L$18)<=0,NA(),((($C25*$L$21)-$L$19+$L$20-($C25*$L$21)*$L$22)/((F$23*$L$16)*(1+$L$23)+$L$18*$L$24-$L$18))^(1/Hold_Y)-1),NA()) | G25: =IFERROR(IF(((G$23*$L$16)*(1+$L$23)+$L$18*$L$24-$L$18)<=0,NA(),((($C25*$L$21)-$L$19+$L$20-($C25*$L$21)*$L$22)/((G$23*$L$16)*(1+$L$23)+$L$18*$L$24-$L$18))^(1/Hold_Y)-1),NA()) | H25: =IFERROR(IF(((H$23*$L$16)*(1+$L$23)+$L$18*$L$24-$L$18)<=0,NA(),((($C25*$L$21)-$L$19+$L$20-($C25*$L$21)*$L$22)/((H$23*$L$16)*(1+$L$23)+$L$18*$L$24-$L$18))^(1/Hold_Y)-1),NA()) | I25: =IFERROR(IF(((I$23*$L$16)*(1+$L$23)+$L$18*$L$24-$L$18)<=0,NA(),((($C25*$L$21)-$L$19+$L$20-($C25*$L$21)*$L$22)/((I$23*$L$16)*(1+$L$23)+$L$18*$L$24-$L$18))^(1/Hold_Y)-1),NA()) | K25: Mgmt rollover (% equity) | L25: ='01_CONTROL'!$D$55
C26: 9 | D26: =IFERROR(IF(((D$23*$L$16)*(1+$L$23)+$L$18*$L$24-$L$18)<=0,NA(),((($C26*$L$21)-$L$19+$L$20-($C26*$L$21)*$L$22)/((D$23*$L$16)*(1+$L$23)+$L$18*$L$24-$L$18))^(1/Hold_Y)-1),NA()) | E26: =IFERROR(IF(((E$23*$L$16)*(1+$L$23)+$L$18*$L$24-$L$18)<=0,NA(),((($C26*$L$21)-$L$19+$L$20-($C26*$L$21)*$L$22)/((E$23*$L$16)*(1+$L$23)+$L$18*$L$24-$L$18))^(1/Hold_Y)-1),NA()) | F26: =IFERROR(IF(((F$23*$L$16)*(1+$L$23)+$L$18*$L$24-$L$18)<=0,NA(),((($C26*$L$21)-$L$19+$L$20-($C26*$L$21)*$L$22)/((F$23*$L$16)*(1+$L$23)+$L$18*$L$24-$L$18))^(1/Hold_Y)-1),NA()) | G26: =IFERROR(IF(((G$23*$L$16)*(1+$L$23)+$L$18*$L$24-$L$18)<=0,NA(),((($C26*$L$21)-$L$19+$L$20-($C26*$L$21)*$L$22)/((G$23*$L$16)*(1+$L$23)+$L$18*$L$24-$L$18))^(1/Hold_Y)-1),NA()) | H26: =IFERROR(IF(((H$23*$L$16)*(1+$L$23)+$L$18*$L$24-$L$18)<=0,NA(),((($C26*$L$21)-$L$19+$L$20-($C26*$L$21)*$L$22)/((H$23*$L$16)*(1+$L$23)+$L$18*$L$24-$L$18))^(1/Hold_Y)-1),NA()) | I26: =IFERROR(IF(((I$23*$L$16)*(1+$L$23)+$L$18*$L$24-$L$18)<=0,NA(),((($C26*$L$21)-$L$19+$L$20-($C26*$L$21)*$L$22)/((I$23*$L$16)*(1+$L$23)+$L$18*$L$24-$L$18))^(1/Hold_Y)-1),NA()) | K26: Cumulative unlevered FCF (Y1..Hold) | L26: =SUM('04_OPERATING_MODEL'!$F$37:INDEX('04_OPERATING_MODEL'!$F$37:$L$37,1,Hold_Y))
C27: 10 | D27: =IFERROR(IF(((D$23*$L$16)*(1+$L$23)+$L$18*$L$24-$L$18)<=0,NA(),((($C27*$L$21)-$L$19+$L$20-($C27*$L$21)*$L$22)/((D$23*$L$16)*(1+$L$23)+$L$18*$L$24-$L$18))^(1/Hold_Y)-1),NA()) | E27: =IFERROR(IF(((E$23*$L$16)*(1+$L$23)+$L$18*$L$24-$L$18)<=0,NA(),((($C27*$L$21)-$L$19+$L$20-($C27*$L$21)*$L$22)/((E$23*$L$16)*(1+$L$23)+$L$18*$L$24-$L$18))^(1/Hold_Y)-1),NA()) | F27: =IFERROR(IF(((F$23*$L$16)*(1+$L$23)+$L$18*$L$24-$L$18)<=0,NA(),((($C27*$L$21)-$L$19+$L$20-($C27*$L$21)*$L$22)/((F$23*$L$16)*(1+$L$23)+$L$18*$L$24-$L$18))^(1/Hold_Y)-1),NA()) | G27: =IFERROR(IF(((G$23*$L$16)*(1+$L$23)+$L$18*$L$24-$L$18)<=0,NA(),((($C27*$L$21)-$L$19+$L$20-($C27*$L$21)*$L$22)/((G$23*$L$16)*(1+$L$23)+$L$18*$L$24-$L$18))^(1/Hold_Y)-1),NA()) | H27: =IFERROR(IF(((H$23*$L$16)*(1+$L$23)+$L$18*$L$24-$L$18)<=0,NA(),((($C27*$L$21)-$L$19+$L$20-($C27*$L$21)*$L$22)/((H$23*$L$16)*(1+$L$23)+$L$18*$L$24-$L$18))^(1/Hold_Y)-1),NA()) | I27: =IFERROR(IF(((I$23*$L$16)*(1+$L$23)+$L$18*$L$24-$L$18)<=0,NA(),((($C27*$L$21)-$L$19+$L$20-($C27*$L$21)*$L$22)/((I$23*$L$16)*(1+$L$23)+$L$18*$L$24-$L$18))^(1/Hold_Y)-1),NA()) | K27: TLB spread (proxy) | L27: ='01_CONTROL'!$D$65
C28: 11 | D28: =IFERROR(IF(((D$23*$L$16)*(1+$L$23)+$L$18*$L$24-$L$18)<=0,NA(),((($C28*$L$21)-$L$19+$L$20-($C28*$L$21)*$L$22)/((D$23*$L$16)*(1+$L$23)+$L$18*$L$24-$L$18))^(1/Hold_Y)-1),NA()) | E28: =IFERROR(IF(((E$23*$L$16)*(1+$L$23)+$L$18*$L$24-$L$18)<=0,NA(),((($C28*$L$21)-$L$19+$L$20-($C28*$L$21)*$L$22)/((E$23*$L$16)*(1+$L$23)+$L$18*$L$24-$L$18))^(1/Hold_Y)-1),NA()) | F28: =IFERROR(IF(((F$23*$L$16)*(1+$L$23)+$L$18*$L$24-$L$18)<=0,NA(),((($C28*$L$21)-$L$19+$L$20-($C28*$L$21)*$L$22)/((F$23*$L$16)*(1+$L$23)+$L$18*$L$24-$L$18))^(1/Hold_Y)-1),NA()) | G28: =IFERROR(IF(((G$23*$L$16)*(1+$L$23)+$L$18*$L$24-$L$18)<=0,NA(),((($C28*$L$21)-$L$19+$L$20-($C28*$L$21)*$L$22)/((G$23*$L$16)*(1+$L$23)+$L$18*$L$24-$L$18))^(1/Hold_Y)-1),NA()) | H28: =IFERROR(IF(((H$23*$L$16)*(1+$L$23)+$L$18*$L$24-$L$18)<=0,NA(),((($C28*$L$21)-$L$19+$L$20-($C28*$L$21)*$L$22)/((H$23*$L$16)*(1+$L$23)+$L$18*$L$24-$L$18))^(1/Hold_Y)-1),NA()) | I28: =IFERROR(IF(((I$23*$L$16)*(1+$L$23)+$L$18*$L$24-$L$18)<=0,NA(),((($C28*$L$21)-$L$19+$L$20-($C28*$L$21)*$L$22)/((I$23*$L$16)*(1+$L$23)+$L$18*$L$24-$L$18))^(1/Hold_Y)-1),NA()) | K28: Base entry EV (DKKm) | L28: ='05_SOURCES_AND_USES'!$D$16
C29: 12 | D29: =IFERROR(IF(((D$23*$L$16)*(1+$L$23)+$L$18*$L$24-$L$18)<=0,NA(),((($C29*$L$21)-$L$19+$L$20-($C29*$L$21)*$L$22)/((D$23*$L$16)*(1+$L$23)+$L$18*$L$24-$L$18))^(1/Hold_Y)-1),NA()) | E29: =IFERROR(IF(((E$23*$L$16)*(1+$L$23)+$L$18*$L$24-$L$18)<=0,NA(),((($C29*$L$21)-$L$19+$L$20-($C29*$L$21)*$L$22)/((E$23*$L$16)*(1+$L$23)+$L$18*$L$24-$L$18))^(1/Hold_Y)-1),NA()) | F29: =IFERROR(IF(((F$23*$L$16)*(1+$L$23)+$L$18*$L$24-$L$18)<=0,NA(),((($C29*$L$21)-$L$19+$L$20-($C29*$L$21)*$L$22)/((F$23*$L$16)*(1+$L$23)+$L$18*$L$24-$L$18))^(1/Hold_Y)-1),NA()) | G29: =IFERROR(IF(((G$23*$L$16)*(1+$L$23)+$L$18*$L$24-$L$18)<=0,NA(),((($C29*$L$21)-$L$19+$L$20-($C29*$L$21)*$L$22)/((G$23*$L$16)*(1+$L$23)+$L$18*$L$24-$L$18))^(1/Hold_Y)-1),NA()) | H29: =IFERROR(IF(((H$23*$L$16)*(1+$L$23)+$L$18*$L$24-$L$18)<=0,NA(),((($C29*$L$21)-$L$19+$L$20-($C29*$L$21)*$L$22)/((H$23*$L$16)*(1+$L$23)+$L$18*$L$24-$L$18))^(1/Hold_Y)-1),NA()) | I29: =IFERROR(IF(((I$23*$L$16)*(1+$L$23)+$L$18*$L$24-$L$18)<=0,NA(),((($C29*$L$21)-$L$19+$L$20-($C29*$L$21)*$L$22)/((I$23*$L$16)*(1+$L$23)+$L$18*$L$24-$L$18))^(1/Hold_Y)-1),NA()) | K29: Base entry uses excl. financing fee (DKKm) | L29: =$L$28*(1+$L$23)+'05_SOURCES_AND_USES'!$D$19
K30: Base exit EV (DKKm) | L30: =Exit_Multiple*$L$21
B33: IRR: EXIT MULTIPLE vs EBITDA CAGR (approx, debt & cash at exit held constant)
B35: Varies leverage target and benchmark rate | D35: -0.02 | E35: 0 | F35: 0.02 | G35: 0.04 | H35: 0.06 | I35: 0.08
C36: 7 | D36: =IFERROR(IF(='05_SOURCES_AND_USES'!$D$40<=0,NA(),((($C36*($L$16*(1+D$35)^Hold_Y))-$L$19+$L$20-($C36*($L$16*(1+D$35)^Hold_Y))*$L$22)/='05_SOURCES_AND_USES'!$D$40)^(1/Hold_Y)-1),NA()) | E36: =IFERROR(IF(='05_SOURCES_AND_USES'!$D$40<=0,NA(),((($C36*($L$16*(1+E$35)^Hold_Y))-$L$19+$L$20-($C36*($L$16*(1+E$35)^Hold_Y))*$L$22)/='05_SOURCES_AND_USES'!$D$40)^(1/Hold_Y)-1),NA()) | F36: =IFERROR(IF(='05_SOURCES_AND_USES'!$D$40<=0,NA(),((($C36*($L$16*(1+F$35)^Hold_Y))-$L$19+$L$20-($C36*($L$16*(1+F$35)^Hold_Y))*$L$22)/='05_SOURCES_AND_USES'!$D$40)^(1/Hold_Y)-1),NA()) | G36: =IFERROR(IF(='05_SOURCES_AND_USES'!$D$40<=0,NA(),((($C36*($L$16*(1+G$35)^Hold_Y))-$L$19+$L$20-($C36*($L$16*(1+G$35)^Hold_Y))*$L$22)/='05_SOURCES_AND_USES'!$D$40)^(1/Hold_Y)-1),NA()) | H36: =IFERROR(IF(='05_SOURCES_AND_USES'!$D$40<=0,NA(),((($C36*($L$16*(1+H$35)^Hold_Y))-$L$19+$L$20-($C36*($L$16*(1+H$35)^Hold_Y))*$L$22)/='05_SOURCES_AND_USES'!$D$40)^(1/Hold_Y)-1),NA()) | I36: =IFERROR(IF(='05_SOURCES_AND_USES'!$D$40<=0,NA(),((($C36*($L$16*(1+I$35)^Hold_Y))-$L$19+$L$20-($C36*($L$16*(1+I$35)^Hold_Y))*$L$22)/='05_SOURCES_AND_USES'!$D$40)^(1/Hold_Y)-1),NA())
B37: Leverage (x) | C37: 8 | D37: =IFERROR(IF(='05_SOURCES_AND_USES'!$D$40<=0,NA(),((($C37*($L$16*(1+D$35)^Hold_Y))-$L$19+$L$20-($C37*($L$16*(1+D$35)^Hold_Y))*$L$22)/='05_SOURCES_AND_USES'!$D$40)^(1/Hold_Y)-1),NA()) | E37: =IFERROR(IF(='05_SOURCES_AND_USES'!$D$40<=0,NA(),((($C37*($L$16*(1+E$35)^Hold_Y))-$L$19+$L$20-($C37*($L$16*(1+E$35)^Hold_Y))*$L$22)/='05_SOURCES_AND_USES'!$D$40)^(1/Hold_Y)-1),NA()) | F37: =IFERROR(IF(='05_SOURCES_AND_USES'!$D$40<=0,NA(),((($C37*($L$16*(1+F$35)^Hold_Y))-$L$19+$L$20-($C37*($L$16*(1+F$35)^Hold_Y))*$L$22)/='05_SOURCES_AND_USES'!$D$40)^(1/Hold_Y)-1),NA()) | G37: =IFERROR(IF(='05_SOURCES_AND_USES'!$D$40<=0,NA(),((($C37*($L$16*(1+G$35)^Hold_Y))-$L$19+$L$20-($C37*($L$16*(1+G$35)^Hold_Y))*$L$22)/='05_SOURCES_AND_USES'!$D$40)^(1/Hold_Y)-1),NA()) | H37: =IFERROR(IF(='05_SOURCES_AND_USES'!$D$40<=0,NA(),((($C37*($L$16*(1+H$35)^Hold_Y))-$L$19+$L$20-($C37*($L$16*(1+H$35)^Hold_Y))*$L$22)/='05_SOURCES_AND_USES'!$D$40)^(1/Hold_Y)-1),NA()) | I37: =IFERROR(IF(='05_SOURCES_AND_USES'!$D$40<=0,NA(),((($C37*($L$16*(1+I$35)^Hold_Y))-$L$19+$L$20-($C37*($L$16*(1+I$35)^Hold_Y))*$L$22)/='05_SOURCES_AND_USES'!$D$40)^(1/Hold_Y)-1),NA())
B38: 3.5 | C38: 9 | D38: =IFERROR(IF(='05_SOURCES_AND_USES'!$D$40<=0,NA(),((($C38*($L$16*(1+D$35)^Hold_Y))-$L$19+$L$20-($C38*($L$16*(1+D$35)^Hold_Y))*$L$22)/='05_SOURCES_AND_USES'!$D$40)^(1/Hold_Y)-1),NA()) | E38: =IFERROR(IF(='05_SOURCES_AND_USES'!$D$40<=0,NA(),((($C38*($L$16*(1+E$35)^Hold_Y))-$L$19+$L$20-($C38*($L$16*(1+E$35)^Hold_Y))*$L$22)/='05_SOURCES_AND_USES'!$D$40)^(1/Hold_Y)-1),NA()) | F38: =IFERROR(IF(='05_SOURCES_AND_USES'!$D$40<=0,NA(),((($C38*($L$16*(1+F$35)^Hold_Y))-$L$19+$L$20-($C38*($L$16*(1+F$35)^Hold_Y))*$L$22)/='05_SOURCES_AND_USES'!$D$40)^(1/Hold_Y)-1),NA()) | G38: =IFERROR(IF(='05_SOURCES_AND_USES'!$D$40<=0,NA(),((($C38*($L$16*(1+G$35)^Hold_Y))-$L$19+$L$20-($C38*($L$16*(1+G$35)^Hold_Y))*$L$22)/='05_SOURCES_AND_USES'!$D$40)^(1/Hold_Y)-1),NA()) | H38: =IFERROR(IF(='05_SOURCES_AND_USES'!$D$40<=0,NA(),((($C38*($L$16*(1+H$35)^Hold_Y))-$L$19+$L$20-($C38*($L$16*(1+H$35)^Hold_Y))*$L$22)/='05_SOURCES_AND_USES'!$D$40)^(1/Hold_Y)-1),NA()) | I38: =IFERROR(IF(='05_SOURCES_AND_USES'!$D$40<=0,NA(),((($C38*($L$16*(1+I$35)^Hold_Y))-$L$19+$L$20-($C38*($L$16*(1+I$35)^Hold_Y))*$L$22)/='05_SOURCES_AND_USES'!$D$40)^(1/Hold_Y)-1),NA())
B39: 4 | C39: 10 | D39: =IFERROR(IF(='05_SOURCES_AND_USES'!$D$40<=0,NA(),((($C39*($L$16*(1+D$35)^Hold_Y))-$L$19+$L$20-($C39*($L$16*(1+D$35)^Hold_Y))*$L$22)/='05_SOURCES_AND_USES'!$D$40)^(1/Hold_Y)-1),NA()) | E39: =IFERROR(IF(='05_SOURCES_AND_USES'!$D$40<=0,NA(),((($C39*($L$16*(1+E$35)^Hold_Y))-$L$19+$L$20-($C39*($L$16*(1+E$35)^Hold_Y))*$L$22)/='05_SOURCES_AND_USES'!$D$40)^(1/Hold_Y)-1),NA()) | F39: =IFERROR(IF(='05_SOURCES_AND_USES'!$D$40<=0,NA(),((($C39*($L$16*(1+F$35)^Hold_Y))-$L$19+$L$20-($C39*($L$16*(1+F$35)^Hold_Y))*$L$22)/='05_SOURCES_AND_USES'!$D$40)^(1/Hold_Y)-1),NA()) | G39: =IFERROR(IF(='05_SOURCES_AND_USES'!$D$40<=0,NA(),((($C39*($L$16*(1+G$35)^Hold_Y))-$L$19+$L$20-($C39*($L$16*(1+G$35)^Hold_Y))*$L$22)/='05_SOURCES_AND_USES'!$D$40)^(1/Hold_Y)-1),NA()) | H39: =IFERROR(IF(='05_SOURCES_AND_USES'!$D$40<=0,NA(),((($C39*($L$16*(1+H$35)^Hold_Y))-$L$19+$L$20-($C39*($L$16*(1+H$35)^Hold_Y))*$L$22)/='05_SOURCES_AND_USES'!$D$40)^(1/Hold_Y)-1),NA()) | I39: =IFERROR(IF(='05_SOURCES_AND_USES'!$D$40<=0,NA(),((($C39*($L$16*(1+I$35)^Hold_Y))-$L$19+$L$20-($C39*($L$16*(1+I$35)^Hold_Y))*$L$22)/='05_SOURCES_AND_USES'!$D$40)^(1/Hold_Y)-1),NA())
