Workbook
Name g_StartYear: '03_GLOBAL_PARAMS'!$F$7
Name g_CloseDate: '03_GLOBAL_PARAMS'!$F$8
Name g_Scenario: '03_GLOBAL_PARAMS'!$F$9
Name g_Consideration: '03_GLOBAL_PARAMS'!$F$10
Name g_TaxRate: '03_GLOBAL_PARAMS'!$F$11
Name g_MinCash: '03_GLOBAL_PARAMS'!$F$12
Name g_Sweep_On: '03_GLOBAL_PARAMS'!$F$13
Name g_NoCircular_Attest: '03_GLOBAL_PARAMS'!$F$14
Name g_NoExternal_Attest: '03_GLOBAL_PARAMS'!$F$15
Name in_A_Revenue_Y0: '10_INPUTS_ACQUIRER'!$F$7
Name in_A_EBITDA_Y0: '10_INPUTS_ACQUIRER'!$F$8
Name in_A_DA_Y0: '10_INPUTS_ACQUIRER'!$F$9
Name in_A_Interest_Y0: '10_INPUTS_ACQUIRER'!$F$10
Name in_A_Taxes_Y0: '10_INPUTS_ACQUIRER'!$F$11
Name in_A_NI_Y0: '10_INPUTS_ACQUIRER'!$F$12
Name in_A_BS_Cash: '10_INPUTS_ACQUIRER'!$F$15
Name in_A_BS_Debt: '10_INPUTS_ACQUIRER'!$F$16
Name in_A_BS_NWC: '10_INPUTS_ACQUIRER'!$F$17
Name in_A_BS_PPE: '10_INPUTS_ACQUIRER'!$F$18
Name in_A_BS_OtherAssets: '10_INPUTS_ACQUIRER'!$F$19
Name in_A_BS_OtherLiab: '10_INPUTS_ACQUIRER'!$F$20
Name in_A_BS_Equity: '10_INPUTS_ACQUIRER'!$F$21
Name in_A_Growth_Row: '10_INPUTS_ACQUIRER'!$F$24:$K$24
Name in_A_EBITDA_Margin_Row: '10_INPUTS_ACQUIRER'!$F$25:$K$25
Name in_A_DA_Pct_Row: '10_INPUTS_ACQUIRER'!$F$26:$K$26
Name in_A_Capex_Pct_Row: '10_INPUTS_ACQUIRER'!$F$27:$K$27
Name in_A_NWC_Pct_Row: '10_INPUTS_ACQUIRER'!$F$28:$K$28
Name in_A_Dividend_Pct_Row: '10_INPUTS_ACQUIRER'!$F$29:$K$29
Name in_A_Shares_Basic: '10_INPUTS_ACQUIRER'!$F$32
Name in_A_Shares_Diluted: '10_INPUTS_ACQUIRER'!$F$33
Name in_A_SharePrice: '10_INPUTS_ACQUIRER'!$F$34
Name in_T_Revenue_Y0: '11_INPUTS_TARGET'!$F$7
Name in_T_EBITDA_Y0: '11_INPUTS_TARGET'!$F$8
Name in_T_DA_Y0: '11_INPUTS_TARGET'!$F$9
Name in_T_NI_Y0: '11_INPUTS_TARGET'!$F$10
Name in_T_ARR_End_Y0: '11_INPUTS_TARGET'!$F$11
Name in_T_ARR_to_Rev: '11_INPUTS_TARGET'!$F$14
Name calc_T_RevenueFromARR_Row: '11_INPUTS_TARGET'!$F$21:$K$21
Name calc_T_EndARR_Row: '11_INPUTS_TARGET'!$F$19:$K$19
Name in_T_EBITDA_Margin_Row: '11_INPUTS_TARGET'!$F$24:$K$24
Name in_T_DA_Pct_Row: '11_INPUTS_TARGET'!$F$25:$K$25
Name in_T_Capex_Pct_Row: '11_INPUTS_TARGET'!$F$26:$K$26
Name in_T_NWC_Pct_Row: '11_INPUTS_TARGET'!$F$27:$K$27
Name in_T_BS_Cash: '11_INPUTS_TARGET'!$F$30
Name in_T_BS_Debt: '11_INPUTS_TARGET'!$F$31
Name in_T_BS_NWC: '11_INPUTS_TARGET'!$F$32
Name in_T_BS_PPE: '11_INPUTS_TARGET'!$F$33
Name in_T_BS_OtherAssets: '11_INPUTS_TARGET'!$F$34
Name in_T_BS_OtherLiab: '11_INPUTS_TARGET'!$F$35
Name in_T_BS_Equity: '11_INPUTS_TARGET'!$F$36
Name in_EquityValue_SEK: '12_INPUTS_DEAL_TERMS'!$F$7
Name in_NetDebt_SEK: '12_INPUTS_DEAL_TERMS'!$F$8
Name in_DebtRepaid_SEK: '12_INPUTS_DEAL_TERMS'!$F$9
Name in_TxnFees_DKK: '12_INPUTS_DEAL_TERMS'!$F$10
Name in_CashPct: '12_INPUTS_DEAL_TERMS'!$F$13
Name in_DebtPct: '12_INPUTS_DEAL_TERMS'!$F$14
Name in_StockPct: '12_INPUTS_DEAL_TERMS'!$F$15
Name calc_MixSum: '12_INPUTS_DEAL_TERMS'!$F$16
Name in_BaseRate: '12_INPUTS_DEAL_TERMS'!$F$19
Name in_T1_Margin: '12_INPUTS_DEAL_TERMS'!$F$20

Sheet 00_DASHBOARD
B1: 00_DASHBOARD IC view
B5: LINE ITEM | C5: UNITS | D5: NOTES / SOURCES / FLAGS | F5: =03_GLOBAL_PARAMS!F24 | G5: =03_GLOBAL_PARAMS!G24 | H5: =03_GLOBAL_PARAMS!H24 | I5: =03_GLOBAL_PARAMS!I24 | J5: =03_GLOBAL_PARAMS!J24 | K5: =03_GLOBAL_PARAMS!K24
B6: KEY TILES (LINKS ONLY)
B7: EPS acc/dil % | C7: Year 1 | E7: EPS acc/dil % | F7: Year 2 | H7: EPS acc/dil % | I7: Year 5 | K7: Pro forma EPS | L7: Year 1
B8: =out_AccDil_Y1 | E8: =out_AccDil_Y2 | H8: =out_AccDil_Y5 | K8: =out_PF_EPS_Y1
B10: Pro forma EPS | C10: Year 2 | E10: Pro forma EPS | F10: Year 5 | H10: Net debt / EBITDA | I10: Close | K10: Net debt / EBITDA | L10: Year 1
B11: =out_PF_EPS_Y2 | E11: =out_PF_EPS_Y5 | H11: =out_ND_EBITDA_Close | K11: =out_ND_EBITDA_Y1
B13: Net debt / EBITDA | C13: Year 5 | E13: Purchase multiple EV/EBITDA | F13: Close | H13: Purchase multiple EV/Revenue | I13: Close | K13: Synergy run-rate | L13: DKKm
B14: =out_ND_EBITDA_Y5 | E14: =out_EV_EBITDA | H14: =out_EV_REV | K14: =out_SynergyRun
B16: Synergy ramp achieved | C16: Year 1 | E16: Goodwill created | F16: DKKm | H16: Intangibles created | I16: DKKm | K16: Checks status (1/0) | L16: All clear
B17: =out_SynergyRamp_Y1 | E17: =out_Goodwill | H17: =out_Intangibles | K17: =check_AllClear
B22: CHARTS
B33: Heatmap: Acc/Dil % (Year 1)
C34: =31_OUTPUT_SENSITIVITIES!F9 | D34: =31_OUTPUT_SENSITIVITIES!G9 | E34: =31_OUTPUT_SENSITIVITIES!H9 | F34: =31_OUTPUT_SENSITIVITIES!I9 | G34: =31_OUTPUT_SENSITIVITIES!J9
B35: =31_OUTPUT_SENSITIVITIES!E10 | C35: =31_OUTPUT_SENSITIVITIES!F10 | D35: =31_OUTPUT_SENSITIVITIES!G10 | E35: =31_OUTPUT_SENSITIVITIES!H10 | F35: =31_OUTPUT_SENSITIVITIES!I10 | G35: =31_OUTPUT_SENSITIVITIES!J10
B36: =31_OUTPUT_SENSITIVITIES!E11 | C36: =31_OUTPUT_SENSITIVITIES!F11 | D36: =31_OUTPUT_SENSITIVITIES!G11 | E36: =31_OUTPUT_SENSITIVITIES!H11 | F36: =31_OUTPUT_SENSITIVITIES!I11 | G36: =31_OUTPUT_SENSITIVITIES!J11
B37: =31_OUTPUT_SENSITIVITIES!E12 | C37: =31_OUTPUT_SENSITIVITIES!F12 | D37: =31_OUTPUT_SENSITIVITIES!G12 | E37: =31_OUTPUT_SENSITIVITIES!H12 | F37: =31_OUTPUT_SENSITIVITIES!I12 | G37: =31_OUTPUT_SENSITIVITIES!J12
B38: =31_OUTPUT_SENSITIVITIES!E13 | C38: =31_OUTPUT_SENSITIVITIES!F13 | D38: =31_OUTPUT_SENSITIVITIES!G13 | E38: =31_OUTPUT_SENSITIVITIES!H13 | F38: =31_OUTPUT_SENSITIVITIES!I13 | G38: =31_OUTPUT_SENSITIVITIES!J13
B39: =31_OUTPUT_SENSITIVITIES!E14 | C39: =31_OUTPUT_SENSITIVITIES!F14 | D39: =31_OUTPUT_SENSITIVITIES!G14 | E39: =31_OUTPUT_SENSITIVITIES!H14 | F39: =31_OUTPUT_SENSITIVITIES!I14 | G39: =31_OUTPUT_SENSITIVITIES!J14
B41: WHAT THIS MEANS
B42: - Bullet 1 (link narrative to outputs above)
B43: - Bullet 2 (link narrative to outputs above)
B44: - Bullet 3 (link narrative to outputs above)
B45: - Bullet 4 (link narrative to outputs above)
B46: - Bullet 5 (link narrative to outputs above)
B48: TOP RISKS
B49: - Risk 1: map to a sensitivity in 31_OUTPUT_SENSITIVITIES
B50: - Risk 2: map to a sensitivity in 31_OUTPUT_SENSITIVITIES
B51: - Risk 3: map to a sensitivity in 31_OUTPUT_SENSITIVITIES
B52: - Risk 4: map to a sensitivity in 31_OUTPUT_SENSITIVITIES
B53: - Risk 5: map to a sensitivity in 31_OUTPUT_SENSITIVITIES
B55: CHECKS STATUS
B56: All checks clear (1/0): | F56: =check_AllClear

Sheet 01_COVER
B1: 01_COVER Print ready cover
B5: LINE ITEM | C5: UNITS | D5: NOTES / SOURCES / FLAGS | F5: =03_GLOBAL_PARAMS!F24 | G5: =03_GLOBAL_PARAMS!G24 | H5: =03_GLOBAL_PARAMS!H24 | I5: =03_GLOBAL_PARAMS!I24 | J5: =03_GLOBAL_PARAMS!J24 | K5: =03_GLOBAL_PARAMS!K24
B6: DEAL SUMMARY
B7: Acquirer | C7: Text | F7: Netcompany A/S
B8: Target | C8: Text | F8: Lime Technologies (Sweden)
B9: Reporting currency | C9: Text | F9: DKK
B10: Model version | C10: Text | F10: v0.1
B11: Model date | C11: Date | F11: 46069
B12: Author | C12: Text | F12: Analyst
B14: CASE LOCK BULLETS
B15: 1. Target locked: Lime Technologies (Sweden), Nordic CRM SaaS subscription model.
B16: 2. Fit hypothesis: accelerates Netcompany product/platform expansion with recurring software revenue exposure.
B17: 3. Cross-border: SEK functional economics converted to DKK reporting, explicit FX sensitivity (SEK/DKK).
B18: 4. Deal logic tested via: EPS bridge (synergies vs financing vs PPA amortisation vs share issuance).
B19: 5. Training case only: illustrative assumptions where public data is unavailable.
B22: DISCLAIMER
B23: Training case only. Inputs are illustrative where public data is unavailable. Not investment advice.

Sheet 02_TOC
B1: 02_TOC Clickable index
B5: LINE ITEM | C5: UNITS | D5: NOTES / SOURCES / FLAGS | F5: =03_GLOBAL_PARAMS!F24 | G5: =03_GLOBAL_PARAMS!G24 | H5: =03_GLOBAL_PARAMS!H24 | I5: =03_GLOBAL_PARAMS!I24 | J5: =03_GLOBAL_PARAMS!J24 | K5: =03_GLOBAL_PARAMS!K24
B6: TAB INDEX
B7: Tab name | C7: Purpose | D7: Link
B8: 00_DASHBOARD | C8: IC view: KPIs, charts, narrative, check status | D8: Go to 00_DASHBOARD
B9: 01_COVER | C9: Cover page and case lock bullets | D9: Go to 01_COVER
B10: 02_TOC | C10: Navigation | D10: Go to 02_TOC
B11: 03_GLOBAL_PARAMS | C11: Controls and timeline | D11: Go to 03_GLOBAL_PARAMS
B12: 10_INPUTS_ACQUIRER | C12: Acquirer base and drivers | D12: Go to 10_INPUTS_ACQUIRER
B13: 11_INPUTS_TARGET | C13: Target SaaS drivers and base | D13: Go to 11_INPUTS_TARGET
B14: 12_INPUTS_DEAL_TERMS | C14: Deal terms and financing inputs | D14: Go to 12_INPUTS_DEAL_TERMS
B15: 13_INPUTS_SYNERGIES | C15: Synergies and one-offs | D15: Go to 13_INPUTS_SYNERGIES
B16: 14_INPUTS_FX_AND_ACCOUNTING | C16: FX rates and PPA elections | D16: Go to 14_INPUTS_FX_AND_ACCOUNTING
B17: 20_CALCS_SOURCES_USES | C17: Sources & Uses | D17: Go to 20_CALCS_SOURCES_USES
B18: 21_CALCS_FINANCING | C18: Debt schedules | D18: Go to 21_CALCS_FINANCING
... B27: 99_APPENDIX_DATA | C27: External data zone | D27: Go to 99_APPENDIX_DATA

Sheet 03_GLOBAL_PARAMS
B1: 03_GLOBAL_PARAMS Control panel and timeline
B5: LINE ITEM | C5: UNITS | D5: NOTES / SOURCES / FLAGS | F5: =03_GLOBAL_PARAMS!F24 | G5: =03_GLOBAL_PARAMS!G24 | H5: =03_GLOBAL_PARAMS!H24 | I5: =03_GLOBAL_PARAMS!I24 | J5: =03_GLOBAL_PARAMS!J24 | K5: =03_GLOBAL_PARAMS!K24
B6: MODEL CONTROLS
B7: Model start year (Y0) | C7: Year | F7: 2026
B8: Deal close date | C8: Date | F8: 46203
B9: Scenario | C9: Text | F9: Base
B10: Consideration | C10: Text | F10: Mixed
B11: Group tax rate | C11: % | F11: 0.22
B12: Min cash balance | C12: DKKm | F12: 50
B13: Cash sweep on (1/0) | C13: Flag | F13: 1
B14: Manual: no circular refs checked (1/0) | C14: Flag | F14: 0
B15: Manual: no external links outside 99 tab (1/0) | C15: Flag | F15: 0
B18: TIMELINE
B19: Calendar year | F19: =g_StartYear+0 | G19: =g_StartYear+1 | H19: =g_StartYear+2 | I19: =g_StartYear+3 | J19: =g_StartYear+4 | K19: =g_StartYear+5
B20: Model year label | F20: ="Year_0" | G20: ="Year_1" | H20: ="Year_2" | I20: ="Year_3" | J20: ="Year_4" | K20: ="Year_5"

Sheet 10_INPUTS_ACQUIRER
B1: 10_INPUTS_ACQUIRER Acquirer inputs
B5: LINE ITEM | C5: UNITS | D5: NOTES / SOURCES / FLAGS | F5: =03_GLOBAL_PARAMS!F24 | G5: =03_GLOBAL_PARAMS!G24 | H5: =03_GLOBAL_PARAMS!H24 | I5: =03_GLOBAL_PARAMS!I24 | J5: =03_GLOBAL_PARAMS!J24 | K5: =03_GLOBAL_PARAMS!K24
B6: REPORTED BASE YEAR FINANCIALS (DKKM)
B7: Revenue | C7: DKKm | F7: 15000
B8: EBITDA | C8: DKKm | F8: 3000
B9: D&A | C9: DKKm | F9: 600
B10: Interest expense | C10: DKKm | F10: -250
B11: Taxes | C11: DKKm | F11: -600
B12: Net income | C12: DKKm | F12: 1550
B14: BALANCE SHEET AT CLOSE (DKKM)
B15: Cash | C15: DKKm | F15: 800
B16: Debt | C16: DKKm | F16: 4000
B17: Net working capital | C17: DKKm | F17: 200
B18: PP&E | C18: DKKm | F18: 1200
B19: Other assets | C19: DKKm | F19: 5000
B20: Other liabilities | C20: DKKm | F20: 2100
B21: Equity (book) | C21: DKKm | F21: 4900
B23: PROJECTION DRIVERS
B24: Revenue growth % | C24: % | F24: 0 | G24: 0.06 | H24: 0.05 | I24: 0.04 | J24: 0.04 | K24: 0.03
B25: EBITDA margin % | C25: % | F25: 0.2 | G25: 0.21 | H25: 0.21 | I25: 0.22 | J25: 0.22 | K25: 0.22
B26: D&A % of revenue | C26: % | F26: 0.04 | G26: 0.04 | H26: 0.04 | I26: 0.04 | J26: 0.04 | K26: 0.04
B27: Capex % of revenue | C27: % | F27: 0.03 | G27: 0.03 | H27: 0.03 | I27: 0.03 | J27: 0.03 | K27: 0.03
B28: NWC % of revenue | C28: % | F28: 0.02 | G28: 0.02 | H28: 0.02 | I28: 0.02 | J28: 0.02 | K28: 0.02
B29: Dividends (% of NI) | C29: % | F29: 0 | G29: 0 | H29: 0 | I29: 0 | J29: 0 | K29: 0
B31: SHARE DATA
B32: Basic shares (mm) | C32: mm | F32: 450
B33: Diluted shares (mm) | C33: mm | F33: 460
B34: Share price (DKK) | C34: DKK | F34: 350

Sheet 11_INPUTS_TARGET
B1: 11_INPUTS_TARGET Target inputs (SaaS module)
B5: LINE ITEM | C5: UNITS | D5: NOTES / SOURCES / FLAGS | F5: =03_GLOBAL_PARAMS!F24 | G5: =03_GLOBAL_PARAMS!G24 | H5: =03_GLOBAL_PARAMS!H24 | I5: =03_GLOBAL_PARAMS!I24 | J5: =03_GLOBAL_PARAMS!J24 | K5: =03_GLOBAL_PARAMS!K24
B6: HISTORICAL BASE (SEKM)
B7: Revenue | C7: SEKm | F7: 1800
B8: EBITDA | C8: SEKm | F8: 250
B9: D&A | C9: SEKm | F9: 70
B10: Net income | C10: SEKm | F10: 115
B11: ARR (end) | C11: SEKm | F11: 1900
B13: SAAS ARR BRIDGE (SEKM)
B14: ARR to Revenue factor | C14: x | F14: 0.95
B15: Start ARR | C15: SEKm | F15: 1900 | G15: =F19 | H15: =G19 | I15: =H19 | J15: =I19 | K15: =J19
B16: New ARR | C16: SEKm | F16: 0 | G16: 250 | H16: 280 | I16: 300 | J16: 320 | K16: 330
B17: Churned ARR | C17: SEKm | F17: 0 | G17: -120 | H17: -130 | I17: -140 | J17: -150 | K17: -155
B18: FX impact ARR | C18: SEKm | F18: 0 | G18: 0 | H18: 0 | I18: 0 | J18: 0 | K18: 0
B19: End ARR | C19: SEKm | F19: =F15+F16+F17+F18 | G19: =G15+G16+G17+G18 | H19: =H15+H16+H17+H18 | I19: =I15+I16+I17+I18 | J19: =J15+J16+J17+J18 | K19: =K15+K16+K17+K18
B20: Avg ARR | C20: SEKm | F20: =(F15+F19)/2 | G20: =(G15+G19)/2 | H20: =(H15+H19)/2 | I20: =(I15+I19)/2 | J20: =(J15+J19)/2 | K20: =(K15+K19)/2
B21: Revenue (from ARR) | C21: SEKm | F21: =F20*in_T_ARR_to_Rev | G21: =G20*in_T_ARR_to_Rev | H21: =H20*in_T_ARR_to_Rev | I21: =I20*in_T_ARR_to_Rev | J21: =J20*in_T_ARR_to_Rev | K21: =K20*in_T_ARR_to_Rev
B23: TARGET OPERATING DRIVERS
B24: EBITDA margin % | C24: % | F24: 0.14 | G24: 0.15 | H24: 0.16 | I24: 0.17 | J24: 0.17 | K24: 0.17
B25: D&A % of revenue | C25: % | F25: 0.04 | G25: 0.04 | H25: 0.04 | I25: 0.04 | J25: 0.04 | K25: 0.04
B26: Capex % of revenue | C26: % | F26: 0.03 | G26: 0.03 | H26: 0.03 | I26: 0.03 | J26: 0.03 | K26: 0.03
B27: NWC % of revenue | C27: % | F27: 0.02 | G27: 0.02 | H27: 0.02 | I27: 0.02 | J27: 0.02 | K27: 0.02
B29: TARGET BALANCE SHEET AT CLOSE (SEKM)
B30: Cash | C30: SEKm | F30: 250
B31: Debt | C31: SEKm | F31: 600
B32: Net working capital | C32: SEKm | F32: 50
B33: PP&E | C33: SEKm | F33: 200
B34: Other assets | C34: SEKm | F34: 800
B35: Other liabilities | C35: SEKm | F35: 350
B36: Equity (book) | C36: SEKm | F36: 600

Sheet 12_INPUTS_DEAL_TERMS
B1: 12_INPUTS_DEAL_TERMS Transaction and financing inputs
B5: LINE ITEM | C5: UNITS | D5: NOTES / SOURCES / FLAGS | F5: =03_GLOBAL_PARAMS!F24 | G5: =03_GLOBAL_PARAMS!G24 | H5: =03_GLOBAL_PARAMS!H24 | I5: =03_GLOBAL_PARAMS!I24 | J5: =03_GLOBAL_PARAMS!J24 | K5: =03_GLOBAL_PARAMS!K24
B6: PURCHASE PRICE AND FEES
B7: Equity value (SEKm) | C7: SEKm | F7: 3500
B8: Net debt assumed (SEKm) | C8: SEKm | F8: 350
B9: Debt repaid at close (SEKm) | C9: SEKm | F9: 0
B10: Transaction fees expensed (DKKm) | C10: DKKm | F10: 30
B12: CONSIDERATION MIX (EQUITY VALUE)
B13: Cash % | C13: % | F13: 0.2
B14: Debt % | C14: % | F14: 0.5
B15: Stock % | C15: % | F15: 0.3
B16: Mix sum | C16: % | D16: Must equal 100% | F16: =in_CashPct+in_DebtPct+in_StockPct
B18: FINANCING TERMS
B19: Base rate % | C19: % | F19: 0.03
B20: Tranche 1 margin % | C20: % | F20: 0.03
B21: Tranche 1 mandatory amort % | C21: % | F21: 0.05
B22: Tranche 2 margin % | C22: % | F22: 0.04
B23: Tranche 2 mandatory amort % | C23: % | F23: 0
B24: Tranche 1 share of new debt % | C24: % | F24: 0.7

Sheet 13_INPUTS_SYNERGIES
B1: 13_INPUTS_SYNERGIES Synergies and integration
B5: LINE ITEM | C5: UNITS | D5: NOTES / SOURCES / FLAGS | F5: =03_GLOBAL_PARAMS!F24 | G5: =03_GLOBAL_PARAMS!G24 | H5: =03_GLOBAL_PARAMS!H24 | I5: =03_GLOBAL_PARAMS!I24 | J5: =03_GLOBAL_PARAMS!J24 | K5: =03_GLOBAL_PARAMS!K24
B6: SYNERGY INPUTS
B7: Cost synergy run rate | C7: DKKm | F7: 120
B8: Revenue synergy run rate (optional) | C8: DKKm | F8: 0
B10: RAMP CURVE BY YEAR
B11: Ramp % achieved | C11: % | F11: 0 | G11: 0.4 | H11: 0.7 | I11: 0.9 | J11: 1 | K11: 1
B13: ONE OFF INTEGRATION COSTS BY YEAR
B14: Integration costs | C14: DKKm | F14: 0 | G14: -60 | H14: -30 | I14: -10 | J14: 0 | K14: 0

Sheet 14_INPUTS_FX_AND_ACCOUNTING
B1: 14_INPUTS_FX_AND_ACCOUNTING FX and accounting elections
B5: LINE ITEM | C5: UNITS | D5: NOTES / SOURCES / FLAGS | F5: =03_GLOBAL_PARAMS!F24 | G5: =03_GLOBAL_PARAMS!G24 | H5: =03_GLOBAL_PARAMS!H24 | I5: =03_GLOBAL_PARAMS!I24 | J5: =03_GLOBAL_PARAMS!J24 | K5: =03_GLOBAL_PARAMS!K24
B6: FX RATES (DKK PER SEK)
B7: Spot at close (DKK/SEK) | C7: DKK/SEK | F7: 0.65
B8: Average by year (DKK/SEK) | C8: DKK/SEK | F8: 0.65 | G8: 0.65 | H8: 0.66 | I8: 0.66 | J8: 0.67 | K8: 0.67
B9: FX avg used (after shock) | C9: DKK/SEK | F9: =IF(in_FX_Sens_On=1,INDEX(in_FX_Avg_Row,1,COLUMN()-5)*(1+in_FX_Shock),INDEX(in_FX_Avg_Row,1,COLUMN()-5)) | G9: =IF(in_FX_Sens_On=1,INDEX(in_FX_Avg_Row,1,COLUMN()-5)*(1+in_FX_Shock),INDEX(in_FX_Avg_Row,1,COLUMN()-5)) | H9: =IF(in_FX_Sens_On=1,INDEX(in_FX_Avg_Row,1,COLUMN()-5)*(1+in_FX_Shock),INDEX(in_FX_Avg_Row,1,COLUMN()-5)) | I9: =IF(in_FX_Sens_On=1,INDEX(in_FX_Avg_Row,1,COLUMN()-5)*(1+in_FX_Shock),INDEX(in_FX_Avg_Row,1,COLUMN()-5)) | J9: =IF(in_FX_Sens_On=1,INDEX(in_FX_Avg_Row,1,COLUMN()-5)*(1+in_FX_Shock),INDEX(in_FX_Avg_Row,1,COLUMN()-5)) | K9: =IF(in_FX_Sens_On=1,INDEX(in_FX_Avg_Row,1,COLUMN()-5)*(1+in_FX_Shock),INDEX(in_FX_Avg_Row,1,COLUMN()-5))
B11: FX SENSITIVITY CONTROLS
B12: FX shock % | C12: % | F12: 0
B13: FX sensitivity on (1/0) | C13: Flag | F13: 0
B15: PPA INTANGIBLES (FAIR VALUE) AND LIVES
B16: Customer relationships FV | C16: DKKm | F16: 600
B17: Customer relationships life (years) | C17: Years | F17: 8
B18: Developed technology FV | C18: DKKm | F18: 500
B19: Developed technology life (years) | C19: Years | F19: 5
B20: Brand / trade name FV | C20: DKKm | F20: 200
B21: Brand / trade name life (years) | C21: Years | F21: 10
B22: Deferred tax on intangibles on (1/0) | C22: Flag | F22: 1

Sheet 20_CALCS_SOURCES_USES
B1: 20_CALCS_SOURCES_USES Sources and uses
B5: LINE ITEM | C5: UNITS | D5: NOTES / SOURCES / FLAGS | F5: =03_GLOBAL_PARAMS!F24 | G5: =03_GLOBAL_PARAMS!G24 | H5: =03_GLOBAL_PARAMS!H24 | I5: =03_GLOBAL_PARAMS!I24 | J5: =03_GLOBAL_PARAMS!J24 | K5: =03_GLOBAL_PARAMS!K24
B6: FX USED (DKK PER SEK)
B7: FX spot used (DKK/SEK) | C7: DKK/SEK | F7: =IF(in_FX_Sens_On=1,in_FX_Spot*(1+in_FX_Shock),in_FX_Spot)
B9: PURCHASE PRICE (DKKM)
B10: Equity value | C10: DKKm | F10: =in_EquityValue_SEK*calc_FX_Spot_Used
B11: Net debt assumed | C11: DKKm | F11: =in_NetDebt_SEK*calc_FX_Spot_Used
B12: Enterprise value | C12: DKKm | F12: =calc_EquityValue_DKK+calc_NetDebt_DKK
B13: Debt repaid at close | C13: DKKm | F13: =in_DebtRepaid_SEK*calc_FX_Spot_Used
B14: Txn fees expensed | C14: DKKm | F14: =in_TxnFees_DKK
B16: USES (DKKM)
B17: Equity purchase price | C17: DKKm | F17: =calc_EquityValue_DKK
B18: Debt repaid at close | C18: DKKm | F18: =calc_DebtRepaid_DKK
B19: Transaction fees expensed | C19: DKKm | F19: =calc_TxnFees_DKK
B20: Total uses | C20: DKKm | F20: =SUM(F17:F19)
B22: SOURCES (DKKM)
B23: Cash on hand used | C23: DKKm | F23: =in_CashPct*calc_EquityValue_DKK+calc_TxnFees_DKK
B24: New debt raised | C24: DKKm | F24: =in_DebtPct*calc_EquityValue_DKK+calc_DebtRepaid_DKK
B25: Stock issued value | C25: DKKm | F25: =in_StockPct*calc_EquityValue_DKK
B26: Total sources | C26: DKKm | F26: =SUM(F23:F25)
B28: Sources - Uses check | C28: DKKm | F28: =F26-F20

Sheet 21_CALCS_FINANCING
B1: 21_CALCS_FINANCING Debt schedules and interest
B5: LINE ITEM | C5: UNITS | D5: NOTES / SOURCES / FLAGS | F5: =03_GLOBAL_PARAMS!F24 | G5: =03_GLOBAL_PARAMS!G24 | H5: =03_GLOBAL_PARAMS!H24 | I5: =03_GLOBAL_PARAMS!I24 | J5: =03_GLOBAL_PARAMS!J24 | K5: =03_GLOBAL_PARAMS!K24
B6: NEW DEBT ALLOCATION
B7: Total new debt | C7: DKKm | F7: =calc_NewDebt_DKK
B8: Tranche 1 amount | C8: DKKm | F8: =calc_NewDebtTotal*in_T1_Share
B9: Tranche 2 amount | C9: DKKm | F9: =calc_NewDebtTotal-calc_T1_Amount
B11: TRANCHE 1 SCHEDULE
B12: Beginning balance | C12: DKKm | F12: =calc_T1_Amount | G12: =F15 | H12: =G15 | I12: =H15 | J12: =I15 | K12: =J15
B13: Mandatory amortisation | C13: DKKm | F13: 0 | G13: =-G12*in_T1_Amort | H13: =-H12*in_T1_Amort | I13: =-I12*in_T1_Amort | J13: =-J12*in_T1_Amort | K13: =-K12*in_T1_Amort
B14: Cash sweep repayment | C14: DKKm | F14: 0 | G14: =-MIN(25_CALCS_PRO_FORMA_CF!G8, MAX(0,G12+G13)) | H14: =-MIN(25_CALCS_PRO_FORMA_CF!H8, MAX(0,H12+H13)) | I14: =-MIN(25_CALCS_PRO_FORMA_CF!I8, MAX(0,I12+I13)) | J14: =-MIN(25_CALCS_PRO_FORMA_CF!J8, MAX(0,J12+J13)) | K14: =-MIN(25_CALCS_PRO_FORMA_CF!K8, MAX(0,K12+K13))
B15: Ending balance | C15: DKKm | F15: =F12+F13+F14 | G15: =G12+G13+G14 | H15: =H12+H13+H14 | I15: =I12+I13+I14 | J15: =J12+J13+J14 | K15: =K12+K13+K14
B16: Interest rate | C16: % | F16: =in_BaseRate+in_T1_Margin | G16: =in_BaseRate+in_T1_Margin | H16: =in_BaseRate+in_T1_Margin | I16: =in_BaseRate+in_T1_Margin | J16: =in_BaseRate+in_T1_Margin | K16: =in_BaseRate+in_T1_Margin
B17: Interest expense | C17: DKKm | F17: 0 | G17: =-((G12+G15)/2)*G16 | H17: =-((H12+H15)/2)*H16 | I17: =-((I12+I15)/2)*I16 | J17: =-((J12+J15)/2)*J16 | K17: =-((K12+K15)/2)*K16
B20: TRANCHE 2 SCHEDULE
B21: Beginning balance | C21: DKKm | F21: =calc_T2_Amount | G21: =F24 | H21: =G24 | I21: =H24 | J21: =I24 | K21: =J24
B22: Mandatory amortisation | C22: DKKm | F22: 0 | G22: =-G21*in_T2_Amort | H22: =-H21*in_T2_Amort | I22: =-I21*in_T2_Amort | J22: =-J21*in_T2_Amort | K22: =-K21*in_T2_Amort
B23: Cash sweep repayment | C23: DKKm | F23: 0 | G23: =-MIN(MAX(0,25_CALCS_PRO_FORMA_CF!G8 + G14), MAX(0,G21+G22)) | H23: =-MIN(MAX(0,25_CALCS_PRO_FORMA_CF!H8 + H14), MAX(0,H21+H22)) | I23: =-MIN(MAX(0,25_CALCS_PRO_FORMA_CF!I8 + I14), MAX(0,I21+I22)) | J23: =-MIN(MAX(0,25_CALCS_PRO_FORMA_CF!J8 + J14), MAX(0,J21+J22)) | K23: =-MIN(MAX(0,25_CALCS_PRO_FORMA_CF!K8 + K14), MAX(0,K21+K22))
B24: Ending balance | C24: DKKm | F24: =F21+F22+F23 | G24: =G21+G22+G23 | H24: =H21+H22+H23 | I24: =I21+I22+I23 | J24: =J21+J22+J23 | K24: =K21+K22+K23
B25: Interest rate | C25: % | F25: =in_BaseRate+in_T2_Margin | G25: =in_BaseRate+in_T2_Margin | H25: =in_BaseRate+in_T2_Margin | I25: =in_BaseRate+in_T2_Margin | J25: =in_BaseRate+in_T2_Margin | K25: =in_BaseRate+in_T2_Margin
B26: Interest expense | C26: DKKm | F26: 0 | G26: =-((G21+G24)/2)*G25 | H26: =-((H21+H24)/2)*H25 | I26: =-((I21+I24)/2)*I25 | J26: =-((J21+J24)/2)*J25 | K26: =-((K21+K24)/2)*K25
B29: TOTALS
B30: Ending balance total new debt | C30: DKKm | F30: =F15+F24 | G30: =G15+G24 | H30: =H15+H24 | I30: =I15+I24 | J30: =J15+J24 | K30: =K15+K24
B31: Interest expense total new debt | C31: DKKm | F31: =F17+F26 | G31: =G17+G26 | H31: =H17+H26 | I31: =I17+I26 | J31: =J17+J26 | K31: =K17+K26
B33: Debt roll check T1 | C33: DKKm | F33: =F12+F13+F14-F15 | G33: =G12+G13+G14-G15 | H33: =H12+H13+H14-H15 | I33: =I12+I13+I14-I15 | J33: =J12+J13+J14-J15 | K33: =K12+K13+K14-K15
B34: Debt roll check T2 | C34: DKKm | F34: =F21+F22+F23-F24 | G34: =G21+G22+G23-G24 | H34: =H21+H22+H23-H24 | I34: =I21+I22+I23-I24 | J34: =J21+J22+J23-J24 | K34: =K21+K22+K23-K24

Sheet 22_CALCS_PPA
B1: 22_CALCS_PPA Purchase price allocation
B5: LINE ITEM | C5: UNITS | D5: NOTES / SOURCES / FLAGS | F5: =03_GLOBAL_PARAMS!F24 | G5: =03_GLOBAL_PARAMS!G24 | H5: =03_GLOBAL_PARAMS!H24 | I5: =03_GLOBAL_PARAMS!I24 | J5: =03_GLOBAL_PARAMS!J24 | K5: =03_GLOBAL_PARAMS!K24
B6: BRIDGE (DKKM)
B7: Enterprise value | C7: DKKm | F7: =calc_EV_DKK
B8: Target book net assets | C8: DKKm | F8: =in_T_BS_Equity*calc_FX_Spot_Used
B9: Identifiable intangibles FV | C9: DKKm | F9: =in_PPA_Cust_FV+in_PPA_Tech_FV+in_PPA_Brand_FV
B10: Deferred tax liability | C10: DKKm | F10: =IF(in_PPA_DTL_On=1,calc_Intangibles_FV*g_TaxRate,0)
B11: Goodwill | C11: DKKm | F11: =calc_EV_DKK-(calc_TargetNetAssets_DKK+calc_Intangibles_FV-calc_PPA_DTL)
B13: AMORTISATION SCHEDULE (DKKM, NEGATIVE EXPENSE)
B14: Customer relationships amort | C14: DKKm | F14: 0 | G14: =IFERROR(-in_PPA_Cust_FV/in_PPA_Cust_Life,0) | H14: =IFERROR(-in_PPA_Cust_FV/in_PPA_Cust_Life,0) | I14: =IFERROR(-in_PPA_Cust_FV/in_PPA_Cust_Life,0) | J14: =IFERROR(-in_PPA_Cust_FV/in_PPA_Cust_Life,0) | K14: =IFERROR(-in_PPA_Cust_FV/in_PPA_Cust_Life,0)
B15: Developed technology amort | C15: DKKm | F15: 0 | G15: =IFERROR(-in_PPA_Tech_FV/in_PPA_Tech_Life,0) | H15: =IFERROR(-in_PPA_Tech_FV/in_PPA_Tech_Life,0) | I15: =IFERROR(-in_PPA_Tech_FV/in_PPA_Tech_Life,0) | J15: =IFERROR(-in_PPA_Tech_FV/in_PPA_Tech_Life,0) | K15: =IFERROR(-in_PPA_Tech_FV/in_PPA_Tech_Life,0)
B16: Brand amort | C16: DKKm | F16: 0 | G16: =IFERROR(-in_PPA_Brand_FV/in_PPA_Brand_Life,0) | H16: =IFERROR(-in_PPA_Brand_FV/in_PPA_Brand_Life,0) | I16: =IFERROR(-in_PPA_Brand_FV/in_PPA_Brand_Life,0) | J16: =IFERROR(-in_PPA_Brand_FV/in_PPA_Brand_Life,0) | K16: =IFERROR(-in_PPA_Brand_FV/in_PPA_Brand_Life,0)
B17: Total PPA amort | C17: DKKm | F17: 0 | G17: =SUM(G14:G16) | H17: =SUM(H14:H16) | I17: =SUM(I14:I16) | J17: =SUM(J14:J16) | K17: =SUM(K14:K16)

Sheet 23_CALCS_PRO_FORMA_IS
B1: 23_CALCS_PRO_FORMA_IS Pro forma income statement (DKKm)
B5: LINE ITEM | C5: UNITS | D5: NOTES / SOURCES / FLAGS | F5: =03_GLOBAL_PARAMS!F24 | G5: =03_GLOBAL_PARAMS!G24 | H5: =03_GLOBAL_PARAMS!H24 | I5: =03_GLOBAL_PARAMS!I24 | J5: =03_GLOBAL_PARAMS!J24 | K5: =03_GLOBAL_PARAMS!K24
B6: ACQUIRER STANDALONE (DKKM)
B7: Acquirer Revenue | C7: DKKm | F7: =in_A_Revenue_Y0 | G7: =F7*(1+INDEX(in_A_Growth_Row,1,COLUMN()-5)) | H7: =G7*(1+INDEX(in_A_Growth_Row,1,COLUMN()-5)) | I7: =H7*(1+INDEX(in_A_Growth_Row,1,COLUMN()-5)) | J7: =I7*(1+INDEX(in_A_Growth_Row,1,COLUMN()-5)) | K7: =J7*(1+INDEX(in_A_Growth_Row,1,COLUMN()-5))
B8: Acquirer EBITDA | C8: DKKm | F8: =F7*INDEX(in_A_EBITDA_Margin_Row,1,COLUMN()-5) | G8: =G7*INDEX(in_A_EBITDA_Margin_Row,1,COLUMN()-5) | H8: =H7*INDEX(in_A_EBITDA_Margin_Row,1,COLUMN()-5) | I8: =I7*INDEX(in_A_EBITDA_Margin_Row,1,COLUMN()-5) | J8: =J7*INDEX(in_A_EBITDA_Margin_Row,1,COLUMN()-5) | K8: =K7*INDEX(in_A_EBITDA_Margin_Row,1,COLUMN()-5)
B9: Acquirer D&A | C9: DKKm | F9: =-F7*INDEX(in_A_DA_Pct_Row,1,COLUMN()-5) | G9: =-G7*INDEX(in_A_DA_Pct_Row,1,COLUMN()-5) | H9: =-H7*INDEX(in_A_DA_Pct_Row,1,COLUMN()-5) | I9: =-I7*INDEX(in_A_DA_Pct_Row,1,COLUMN()-5) | J9: =-J7*INDEX(in_A_DA_Pct_Row,1,COLUMN()-5) | K9: =-K7*INDEX(in_A_DA_Pct_Row,1,COLUMN()-5)
B10: Acquirer EBIT | C10: DKKm | F10: =F8+F9 | G10: =G8+G9 | H10: =H8+H9 | I10: =I8+I9 | J10: =J8+J9 | K10: =K8+K9
B11: Acquirer Interest | C11: DKKm | F11: =in_A_Interest_Y0 | G11: =in_A_Interest_Y0 | H11: =in_A_Interest_Y0 | I11: =in_A_Interest_Y0 | J11: =in_A_Interest_Y0 | K11: =in_A_Interest_Y0
B12: Acquirer Taxes | C12: DKKm | F12: =-MAX(0,(F10+F11))*g_TaxRate | G12: =-MAX(0,(G10+G11))*g_TaxRate | H12: =-MAX(0,(H10+H11))*g_TaxRate | I12: =-MAX(0,(I10+I11))*g_TaxRate | J12: =-MAX(0,(J10+J11))*g_TaxRate | K12: =-MAX(0,(K10+K11))*g_TaxRate
B13: Acquirer Net income | C13: DKKm | F13: =F10+F11+F12 | G13: =G10+G11+G12 | H13: =H10+H11+H12 | I13: =I10+I11+I12 | J13: =J10+J11+J12 | K13: =K10+K11+K12
B15: TARGET STANDALONE TRANSLATED (DKKM)
B16: Target Revenue (SEKm) | C16: SEKm | F16: =in_T_Revenue_Y0 | G16: =INDEX(calc_T_RevenueFromARR_Row,1,COLUMN()-5) | H16: =INDEX(calc_T_RevenueFromARR_Row,1,COLUMN()-5) | I16: =INDEX(calc_T_RevenueFromARR_Row,1,COLUMN()-5) | J16: =INDEX(calc_T_RevenueFromARR_Row,1,COLUMN()-5) | K16: =INDEX(calc_T_RevenueFromARR_Row,1,COLUMN()-5)
B17: Target Revenue (DKKm) | C17: DKKm | F17: =F16*INDEX(calc_FX_Avg_Used_Row,1,COLUMN()-5) | G17: =G16*INDEX(calc_FX_Avg_Used_Row,1,COLUMN()-5) | H17: =H16*INDEX(calc_FX_Avg_Used_Row,1,COLUMN()-5) | I17: =I16*INDEX(calc_FX_Avg_Used_Row,1,COLUMN()-5) | J17: =J16*INDEX(calc_FX_Avg_Used_Row,1,COLUMN()-5) | K17: =K16*INDEX(calc_FX_Avg_Used_Row,1,COLUMN()-5)
B18: Target EBITDA (DKKm) | C18: DKKm | F18: =F17*INDEX(in_T_EBITDA_Margin_Row,1,COLUMN()-5) | G18: =G17*INDEX(in_T_EBITDA_Margin_Row,1,COLUMN()-5) | H18: =H17*INDEX(in_T_EBITDA_Margin_Row,1,COLUMN()-5) | I18: =I17*INDEX(in_T_EBITDA_Margin_Row,1,COLUMN()-5) | J18: =J17*INDEX(in_T_EBITDA_Margin_Row,1,COLUMN()-5) | K18: =K17*INDEX(in_T_EBITDA_Margin_Row,1,COLUMN()-5)
B19: Target D&A (DKKm) | C19: DKKm | F19: =-F17*INDEX(in_T_DA_Pct_Row,1,COLUMN()-5) | G19: =-G17*INDEX(in_T_DA_Pct_Row,1,COLUMN()-5) | H19: =-H17*INDEX(in_T_DA_Pct_Row,1,COLUMN()-5) | I19: =-I17*INDEX(in_T_DA_Pct_Row,1,COLUMN()-5) | J19: =-J17*INDEX(in_T_DA_Pct_Row,1,COLUMN()-5) | K19: =-K17*INDEX(in_T_DA_Pct_Row,1,COLUMN()-5)
B20: Target EBIT (DKKm) | C20: DKKm | F20: =F18+F19 | G20: =G18+G19 | H20: =H18+H19 | I20: =I18+I19 | J20: =J18+J19 | K20: =K18+K19
B21: Target Net income (DKKm) | C21: DKKm | F21: =F20 - MAX(0,F20)*g_TaxRate | G21: =G20 - MAX(0,G20)*g_TaxRate | H21: =H20 - MAX(0,H20)*g_TaxRate | I21: =I20 - MAX(0,I20)*g_TaxRate | J21: =J20 - MAX(0,J20)*g_TaxRate | K21: =K20 - MAX(0,K20)*g_TaxRate
B23: DEAL EFFECTS (DKKM)
B24: Synergies (DKKm) | C24: DKKm | F24: =in_SynergyRunRate*INDEX(in_SynergyRamp_Row,1,COLUMN()-5) | G24: =in_SynergyRunRate*INDEX(in_SynergyRamp_Row,1,COLUMN()-5) | H24: =in_SynergyRunRate*INDEX(in_SynergyRamp_Row,1,COLUMN()-5) | I24: =in_SynergyRunRate*INDEX(in_SynergyRamp_Row,1,COLUMN()-5) | J24: =in_SynergyRunRate*INDEX(in_SynergyRamp_Row,1,COLUMN()-5) | K24: =in_SynergyRunRate*INDEX(in_SynergyRamp_Row,1,COLUMN()-5)
B25: Integration costs (DKKm) | C25: DKKm | F25: =INDEX(in_Integration_Row,1,COLUMN()-5) | G25: =INDEX(in_Integration_Row,1,COLUMN()-5) | H25: =INDEX(in_Integration_Row,1,COLUMN()-5) | I25: =INDEX(in_Integration_Row,1,COLUMN()-5) | J25: =INDEX(in_Integration_Row,1,COLUMN()-5) | K25: =INDEX(in_Integration_Row,1,COLUMN()-5)
B26: PPA amort (DKKm) | C26: DKKm | F26: =INDEX(calc_PPA_Amort_Row,1,COLUMN()-5) | G26: =INDEX(calc_PPA_Amort_Row,1,COLUMN()-5) | H26: =INDEX(calc_PPA_Amort_Row,1,COLUMN()-5) | I26: =INDEX(calc_PPA_Amort_Row,1,COLUMN()-5) | J26: =INDEX(calc_PPA_Amort_Row,1,COLUMN()-5) | K26: =INDEX(calc_PPA_Amort_Row,1,COLUMN()-5)
B27: New debt interest (DKKm) | C27: DKKm | F27: =INDEX(calc_NewDebt_Interest_Row,1,COLUMN()-5) | G27: =INDEX(calc_NewDebt_Interest_Row,1,COLUMN()-5) | H27: =INDEX(calc_NewDebt_Interest_Row,1,COLUMN()-5) | I27: =INDEX(calc_NewDebt_Interest_Row,1,COLUMN()-5) | J27: =INDEX(calc_NewDebt_Interest_Row,1,COLUMN()-5) | K27: =INDEX(calc_NewDebt_Interest_Row,1,COLUMN()-5)
B29: PRO FORMA TOTALS (DKKM)
B30: Pro forma Revenue | C30: DKKm | F30: =F7+F17 | G30: =G7+G17 | H30: =H7+H17 | I30: =I7+I17 | J30: =J7+J17 | K30: =K7+K17
B31: Pro forma EBITDA | C31: DKKm | F31: =F8+F18+F24+F25 | G31: =G8+G18+G24+G25 | H31: =H8+H18+H24+H25 | I31: =I8+I18+I24+I25 | J31: =J8+J18+J24+J25 | K31: =K8+K18+K24+K25
B32: Pro forma EBIT | C32: DKKm | F32: =F31+F9+F19+F26 | G32: =G31+G9+G19+G26 | H32: =H31+H9+H19+H26 | I32: =I31+I9+I19+I26 | J32: =J31+J9+J19+J26 | K32: =K31+K9+K19+K26
B33: Pro forma PBT | C33: DKKm | F33: =F32+F11+F27 | G33: =G32+G11+G27 | H33: =H32+H11+H27 | I33: =I32+I11+I27 | J33: =J32+J11+J27 | K33: =K32+K11+K27
B34: Pro forma Taxes | C34: DKKm | F34: =-MAX(0,F33)*g_TaxRate | G34: =-MAX(0,G33)*g_TaxRate | H34: =-MAX(0,H33)*g_TaxRate | I34: =-MAX(0,I33)*g_TaxRate | J34: =-MAX(0,J33)*g_TaxRate | K34: =-MAX(0,K33)*g_TaxRate
B35: Pro forma Net income | C35: DKKm | F35: =F33+F34 | G35: =G33+G34 | H35: =H33+H34 | I35: =I33+I34 | J35: =J33+J34 | K35: =K33+K34

Sheet 24_CALCS_PRO_FORMA_BS
B1: 24_CALCS_PRO_FORMA_BS Balance sheet (DKKm) and balance check
B5: LINE ITEM | C5: UNITS | D5: NOTES / SOURCES / FLAGS | F5: =03_GLOBAL_PARAMS!F24 | G5: =03_GLOBAL_PARAMS!G24 | H5: =03_GLOBAL_PARAMS!H24 | I5: =03_GLOBAL_PARAMS!I24 | J5: =03_GLOBAL_PARAMS!J24 | K5: =03_GLOBAL_PARAMS!K24
B6: PRO FORMA BALANCE SHEET
B7: Cash | C7: DKKm | F7: =INDEX(25_CALCS_PRO_FORMA_CF!$F$30:$K$30,1,COLUMN()-5) | G7: =INDEX(25_CALCS_PRO_FORMA_CF!$F$30:$K$30,1,COLUMN()-5) | H7: =INDEX(25_CALCS_PRO_FORMA_CF!$F$30:$K$30,1,COLUMN()-5) | I7: =INDEX(25_CALCS_PRO_FORMA_CF!$F$30:$K$30,1,COLUMN()-5) | J7: =INDEX(25_CALCS_PRO_FORMA_CF!$F$30:$K$30,1,COLUMN()-5) | K7: =INDEX(25_CALCS_PRO_FORMA_CF!$F$30:$K$30,1,COLUMN()-5)
B8: Net working capital | C8: DKKm | F8: =INDEX(23_CALCS_PRO_FORMA_IS!$F$30:$K$30,1,COLUMN()-5)*0.02 | G8: =INDEX(23_CALCS_PRO_FORMA_IS!$F$30:$K$30,1,COLUMN()-5)*0.02 | H8: =INDEX(23_CALCS_PRO_FORMA_IS!$F$30:$K$30,1,COLUMN()-5)*0.02 | I8: =INDEX(23_CALCS_PRO_FORMA_IS!$F$30:$K$30,1,COLUMN()-5)*0.02 | J8: =INDEX(23_CALCS_PRO_FORMA_IS!$F$30:$K$30,1,COLUMN()-5)*0.02 | K8: =INDEX(23_CALCS_PRO_FORMA_IS!$F$30:$K$30,1,COLUMN()-5)*0.02
B9: PP&E | C9: DKKm | F9: =in_A_BS_PPE + in_T_BS_PPE*calc_FX_Spot_Used | G9: =F9 + INDEX(25_CALCS_PRO_FORMA_CF!$F$18:$K$18,1,COLUMN()-5) + (INDEX(23_CALCS_PRO_FORMA_IS!$F$9:$K$9,1,COLUMN()-5)+INDEX(23_CALCS_PRO_FORMA_IS!$F$19:$K$19,1,COLUMN()-5)) | H9: =G9 + INDEX(25_CALCS_PRO_FORMA_CF!$F$18:$K$18,1,COLUMN()-5) + (INDEX(23_CALCS_PRO_FORMA_IS!$F$9:$K$9,1,COLUMN()-5)+INDEX(23_CALCS_PRO_FORMA_IS!$F$19:$K$19,1,COLUMN()-5)) | I9: =H9 + INDEX(25_CALCS_PRO_FORMA_CF!$F$18:$K$18,1,COLUMN()-5) + (INDEX(23_CALCS_PRO_FORMA_IS!$F$9:$K$9,1,COLUMN()-5)+INDEX(23_CALCS_PRO_FORMA_IS!$F$19:$K$19,1,COLUMN()-5)) | J9: =I9 + INDEX(25_CALCS_PRO_FORMA_CF!$F$18:$K$18,1,COLUMN()-5) + (INDEX(23_CALCS_PRO_FORMA_IS!$F$9:$K$9,1,COLUMN()-5)+INDEX(23_CALCS_PRO_FORMA_IS!$F$19:$K$19,1,COLUMN()-5)) | K9: =J9 + INDEX(25_CALCS_PRO_FORMA_CF!$F$18:$K$18,1,COLUMN()-5) + (INDEX(23_CALCS_PRO_FORMA_IS!$F$9:$K$9,1,COLUMN()-5)+INDEX(23_CALCS_PRO_FORMA_IS!$F$19:$K$19,1,COLUMN()-5))
B10: Other assets | C10: DKKm | F10: =in_A_BS_OtherAssets + in_T_BS_OtherAssets*calc_FX_Spot_Used | G10: =in_A_BS_OtherAssets + in_T_BS_OtherAssets*calc_FX_Spot_Used | H10: =in_A_BS_OtherAssets + in_T_BS_OtherAssets*calc_FX_Spot_Used | I10: =in_A_BS_OtherAssets + in_T_BS_OtherAssets*calc_FX_Spot_Used | J10: =in_A_BS_OtherAssets + in_T_BS_OtherAssets*calc_FX_Spot_Used | K10: =in_A_BS_OtherAssets + in_T_BS_OtherAssets*calc_FX_Spot_Used
B11: Identifiable intangibles (net) | C11: DKKm | F11: =calc_Intangibles_FV | G11: =MAX(0,F11 + INDEX(22_CALCS_PPA!$F$17:$K$17,1,COLUMN()-5)) | H11: =MAX(0,G11 + INDEX(22_CALCS_PPA!$F$17:$K$17,1,COLUMN()-5)) | I11: =MAX(0,H11 + INDEX(22_CALCS_PPA!$F$17:$K$17,1,COLUMN()-5)) | J11: =MAX(0,I11 + INDEX(22_CALCS_PPA!$F$17:$K$17,1,COLUMN()-5)) | K11: =MAX(0,J11 + INDEX(22_CALCS_PPA!$F$17:$K$17,1,COLUMN()-5))
B12: Goodwill | C12: DKKm | F12: =calc_Goodwill | G12: =calc_Goodwill | H12: =calc_Goodwill | I12: =calc_Goodwill | J12: =calc_Goodwill | K12: =calc_Goodwill
B13: Total assets | C13: DKKm | F13: =SUM(F7:F12) | G13: =SUM(G7:G12) | H13: =SUM(H7:H12) | I13: =SUM(I7:I12) | J13: =SUM(J7:J12) | K13: =SUM(K7:K12)
B14: Debt (existing + new, net of repay) | C14: DKKm | F14: =in_A_BS_Debt + in_T_BS_Debt*calc_FX_Spot_Used + INDEX(calc_NewDebt_End_Row,1,1) - calc_DebtRepaid_DKK | G14: =in_A_BS_Debt + in_T_BS_Debt*calc_FX_Spot_Used + INDEX(calc_NewDebt_End_Row,1,COLUMN()-5) - calc_DebtRepaid_DKK | H14: =in_A_BS_Debt + in_T_BS_Debt*calc_FX_Spot_Used + INDEX(calc_NewDebt_End_Row,1,COLUMN()-5) - calc_DebtRepaid_DKK | I14: =in_A_BS_Debt + in_T_BS_Debt*calc_FX_Spot_Used + INDEX(calc_NewDebt_End_Row,1,COLUMN()-5) - calc_DebtRepaid_DKK | J14: =in_A_BS_Debt + in_T_BS_Debt*calc_FX_Spot_Used + INDEX(calc_NewDebt_End_Row,1,COLUMN()-5) - calc_DebtRepaid_DKK | K14: =in_A_BS_Debt + in_T_BS_Debt*calc_FX_Spot_Used + INDEX(calc_NewDebt_End_Row,1,COLUMN()-5) - calc_DebtRepaid_DKK
B15: Other liabilities | C15: DKKm | F15: =in_A_BS_OtherLiab + in_T_BS_OtherLiab*calc_FX_Spot_Used | G15: =in_A_BS_OtherLiab + in_T_BS_OtherLiab*calc_FX_Spot_Used | H15: =in_A_BS_OtherLiab + in_T_BS_OtherLiab*calc_FX_Spot_Used | I15: =in_A_BS_OtherLiab + in_T_BS_OtherLiab*calc_FX_Spot_Used | J15: =in_A_BS_OtherLiab + in_T_BS_OtherLiab*calc_FX_Spot_Used | K15: =in_A_BS_OtherLiab + in_T_BS_OtherLiab*calc_FX_Spot_Used
B16: Total liabilities | C16: DKKm | F16: =SUM(F14:F15) | G16: =SUM(G14:G15) | H16: =SUM(H14:H15) | I16: =SUM(I14:I15) | J16: =SUM(J14:J15) | K16: =SUM(K14:K15)
B17: Equity | C17: DKKm | F17: =F13-F16 | G17: =F17 + INDEX(calc_PF_NI_Row,1,COLUMN()-5) | H17: =G17 + INDEX(calc_PF_NI_Row,1,COLUMN()-5) | I17: =H17 + INDEX(calc_PF_NI_Row,1,COLUMN()-5) | J17: =I17 + INDEX(calc_PF_NI_Row,1,COLUMN()-5) | K17: =J17 + INDEX(calc_PF_NI_Row,1,COLUMN()-5)
B18: Total liabilities + equity | C18: DKKm | F18: =F16+F17 | G18: =G16+G17 | H18: =H16+H17 | I18: =I16+I17 | J18: =J16+J17 | K18: =K16+K17
B19: Balance check (Assets - L-E) | C19: DKKm | F19: =F13-F18 | G19: =G13-G18 | H19: =H13-H18 | I19: =I13-I18 | J19: =J13-J18 | K19: =K13-K18

Sheet 25_CALCS_PRO_FORMA_CF
B1: 25_CALCS_PRO_FORMA_CF Cash flow (DKKm) and cash roll forward
B5: LINE ITEM | C5: UNITS | D5: NOTES / SOURCES / FLAGS | F5: =03_GLOBAL_PARAMS!F24 | G5: =03_GLOBAL_PARAMS!G24 | H5: =03_GLOBAL_PARAMS!H24 | I5: =03_GLOBAL_PARAMS!I24 | J5: =03_GLOBAL_PARAMS!J24 | K5: =03_GLOBAL_PARAMS!K24
B6: CASH ROLL FORWARD
B7: Beginning cash | C7: DKKm | F7: =in_A_BS_Cash + in_T_BS_Cash*calc_FX_Spot_Used - calc_CashUsed_DKK | G7: =F30 | H7: =G30 | I7: =H30 | J7: =I30 | K7: =J30
B8: Cash available for sweep | C8: DKKm | F8: =MAX(0,F7-g_MinCash) | G8: =MAX(0,G7-g_MinCash) | H8: =MAX(0,H7-g_MinCash) | I8: =MAX(0,I7-g_MinCash) | J8: =MAX(0,J7-g_MinCash) | K8: =MAX(0,K7-g_MinCash)
B10: OPERATING CASH FLOW (SIMPLIFIED)
B11: EBITDA | C11: DKKm | F11: =INDEX(23_CALCS_PRO_FORMA_IS!$F$31:$K$31,1,COLUMN()-5) | G11: =INDEX(23_CALCS_PRO_FORMA_IS!$F$31:$K$31,1,COLUMN()-5) | H11: =INDEX(23_CALCS_PRO_FORMA_IS!$F$31:$K$31,1,COLUMN()-5) | I11: =INDEX(23_CALCS_PRO_FORMA_IS!$F$31:$K$31,1,COLUMN()-5) | J11: =INDEX(23_CALCS_PRO_FORMA_IS!$F$31:$K$31,1,COLUMN()-5) | K11: =INDEX(23_CALCS_PRO_FORMA_IS!$F$31:$K$31,1,COLUMN()-5)
B12: Cash taxes | C12: DKKm | F12: =INDEX(23_CALCS_PRO_FORMA_IS!$F$34:$K$34,1,COLUMN()-5) | G12: =INDEX(23_CALCS_PRO_FORMA_IS!$F$34:$K$34,1,COLUMN()-5) | H12: =INDEX(23_CALCS_PRO_FORMA_IS!$F$34:$K$34,1,COLUMN()-5) | I12: =INDEX(23_CALCS_PRO_FORMA_IS!$F$34:$K$34,1,COLUMN()-5) | J12: =INDEX(23_CALCS_PRO_FORMA_IS!$F$34:$K$34,1,COLUMN()-5) | K12: =INDEX(23_CALCS_PRO_FORMA_IS!$F$34:$K$34,1,COLUMN()-5)
B13: Change in NWC | C13: DKKm | F13: 0 | G13: =-(G8-F8) | H13: =-(H8-G8) | I13: =-(I8-H8) | J13: =-(J8-I8) | K13: =-(K8-J8)
B14: Net interest | C14: DKKm | F14: =INDEX(23_CALCS_PRO_FORMA_IS!$F$11:$K$11,1,COLUMN()-5)+INDEX(23_CALCS_PRO_FORMA_IS!$F$27:$K$27,1,COLUMN()-5) | G14: =INDEX(23_CALCS_PRO_FORMA_IS!$F$11:$K$11,1,COLUMN()-5)+INDEX(23_CALCS_PRO_FORMA_IS!$F$27:$K$27,1,COLUMN()-5) | H14: =INDEX(23_CALCS_PRO_FORMA_IS!$F$11:$K$11,1,COLUMN()-5)+INDEX(23_CALCS_PRO_FORMA_IS!$F$27:$K$27,1,COLUMN()-5) | I14: =INDEX(23_CALCS_PRO_FORMA_IS!$F$11:$K$11,1,COLUMN()-5)+INDEX(23_CALCS_PRO_FORMA_IS!$F$27:$K$27,1,COLUMN()-5) | J14: =INDEX(23_CALCS_PRO_FORMA_IS!$F$11:$K$11,1,COLUMN()-5)+INDEX(23_CALCS_PRO_FORMA_IS!$F$27:$K$27,1,COLUMN()-5) | K14: =INDEX(23_CALCS_PRO_FORMA_IS!$F$11:$K$11,1,COLUMN()-5)+INDEX(23_CALCS_PRO_FORMA_IS!$F$27:$K$27,1,COLUMN()-5)
B15: CFO | C15: DKKm | F15: =SUM(F11:F14) | G15: =SUM(G11:G14) | H15: =SUM(H11:H14) | I15: =SUM(I11:I14) | J15: =SUM(J11:J14) | K15: =SUM(K11:K14)
B17: INVESTING CASH FLOW
B18: Capex | C18: DKKm | F18: =-INDEX(23_CALCS_PRO_FORMA_IS!$F$30:$K$30,1,COLUMN()-5)*0.03 | G18: =-INDEX(23_CALCS_PRO_FORMA_IS!$F$30:$K$30,1,COLUMN()-5)*0.03 | H18: =-INDEX(23_CALCS_PRO_FORMA_IS!$F$30:$K$30,1,COLUMN()-5)*0.03 | I18: =-INDEX(23_CALCS_PRO_FORMA_IS!$F$30:$K$30,1,COLUMN()-5)*0.03 | J18: =-INDEX(23_CALCS_PRO_FORMA_IS!$F$30:$K$30,1,COLUMN()-5)*0.03 | K18: =-INDEX(23_CALCS_PRO_FORMA_IS!$F$30:$K$30,1,COLUMN()-5)*0.03
B19: CFI | C19: DKKm | F19: =F18 | G19: =G18 | H19: =H18 | I19: =I18 | J19: =J18 | K19: =K18
B21: FINANCING CASH FLOW
B22: Mandatory amort | C22: DKKm | F22: =INDEX(21_CALCS_FINANCING!$F$13:$K$13,1,COLUMN()-5)+INDEX(21_CALCS_FINANCING!$F$22:$K$22,1,COLUMN()-5) | G22: =INDEX(21_CALCS_FINANCING!$F$13:$K$13,1,COLUMN()-5)+INDEX(21_CALCS_FINANCING!$F$22:$K$22,1,COLUMN()-5) | H22: =INDEX(21_CALCS_FINANCING!$F$13:$K$13,1,COLUMN()-5)+INDEX(21_CALCS_FINANCING!$F$22:$K$22,1,COLUMN()-5) | I22: =INDEX(21_CALCS_FINANCING!$F$13:$K$13,1,COLUMN()-5)+INDEX(21_CALCS_FINANCING!$F$22:$K$22,1,COLUMN()-5) | J22: =INDEX(21_CALCS_FINANCING!$F$13:$K$13,1,COLUMN()-5)+INDEX(21_CALCS_FINANCING!$F$22:$K$22,1,COLUMN()-5) | K22: =INDEX(21_CALCS_FINANCING!$F$13:$K$13,1,COLUMN()-5)+INDEX(21_CALCS_FINANCING!$F$22:$K$22,1,COLUMN()-5)
B23: Sweep | C23: DKKm | F23: =INDEX(21_CALCS_FINANCING!$F$14:$K$14,1,COLUMN()-5)+INDEX(21_CALCS_FINANCING!$F$23:$K$23,1,COLUMN()-5) | G23: =INDEX(21_CALCS_FINANCING!$F$14:$K$14,1,COLUMN()-5)+INDEX(21_CALCS_FINANCING!$F$23:$K$23,1,COLUMN()-5) | H23: =INDEX(21_CALCS_FINANCING!$F$14:$K$14,1,COLUMN()-5)+INDEX(21_CALCS_FINANCING!$F$23:$K$23,1,COLUMN()-5) | I23: =INDEX(21_CALCS_FINANCING!$F$14:$K$14,1,COLUMN()-5)+INDEX(21_CALCS_FINANCING!$F$23:$K$23,1,COLUMN()-5) | J23: =INDEX(21_CALCS_FINANCING!$F$14:$K$14,1,COLUMN()-5)+INDEX(21_CALCS_FINANCING!$F$23:$K$23,1,COLUMN()-5) | K23: =INDEX(21_CALCS_FINANCING!$F$14:$K$14,1,COLUMN()-5)+INDEX(21_CALCS_FINANCING!$F$23:$K$23,1,COLUMN()-5)
B24: CFF | C24: DKKm | F24: =SUM(F22:F23) | G24: =SUM(G22:G23) | H24: =SUM(H22:H23) | I24: =SUM(I22:I23) | J24: =SUM(J22:J23) | K24: =SUM(K22:K23)
B26: CASH RECONCILIATION
B27: Net change in cash | C27: DKKm | F27: =F15+F19+F24 | G27: =G15+G19+G24 | H27: =H15+H19+H24 | I27: =I15+I19+I24 | J27: =J15+J19+J24 | K27: =K15+K19+K24
B28: Ending cash | C28: DKKm | F28: =F7+F27 | G28: =G7+G27 | H28: =H7+H27 | I28: =I7+I27 | J28: =J7+J27 | K28: =K7+K27
B30: Ending cash (feed) | C30: DKKm | F30: =F28 | G30: =G28 | H30: =H28 | I30: =I28 | J30: =J28 | K30: =K28

Sheet 26_CALCS_SHARES_AND_EPS
B1: 26_CALCS_SHARES_AND_EPS Shares, EPS, accretion/dilution
B5: LINE ITEM | C5: UNITS | D5: NOTES / SOURCES / FLAGS | F5: =03_GLOBAL_PARAMS!F24 | G5: =03_GLOBAL_PARAMS!G24 | H5: =03_GLOBAL_PARAMS!H24 | I5: =03_GLOBAL_PARAMS!I24 | J5: =03_GLOBAL_PARAMS!J24 | K5: =03_GLOBAL_PARAMS!K24
B6: SHARE COUNT
B7: Basic shares (mm) | C7: mm | F7: =in_A_Shares_Basic
B8: New shares issued (mm) | C8: mm | F8: =calc_StockValue_DKK/in_A_SharePrice
B9: Pro forma shares (mm) | C9: mm | F9: =F7+F8
B11: EPS AND ACCRETION/DILUTION
B12: Standalone EPS (DKK) | C12: DKK | F12: =INDEX(calc_A_NI_Row,1,COLUMN()-5)/in_A_Shares_Basic | G12: =INDEX(calc_A_NI_Row,1,COLUMN()-5)/in_A_Shares_Basic | H12: =INDEX(calc_A_NI_Row,1,COLUMN()-5)/in_A_Shares_Basic | I12: =INDEX(calc_A_NI_Row,1,COLUMN()-5)/in_A_Shares_Basic | J12: =INDEX(calc_A_NI_Row,1,COLUMN()-5)/in_A_Shares_Basic | K12: =INDEX(calc_A_NI_Row,1,COLUMN()-5)/in_A_Shares_Basic
B13: Pro forma EPS (DKK) | C13: DKK | F13: =INDEX(calc_PF_NI_Row,1,COLUMN()-5)/calc_PF_Shares_mm | G13: =INDEX(calc_PF_NI_Row,1,COLUMN()-5)/calc_PF_Shares_mm | H13: =INDEX(calc_PF_NI_Row,1,COLUMN()-5)/calc_PF_Shares_mm | I13: =INDEX(calc_PF_NI_Row,1,COLUMN()-5)/calc_PF_Shares_mm | J13: =INDEX(calc_PF_NI_Row,1,COLUMN()-5)/calc_PF_Shares_mm | K13: =INDEX(calc_PF_NI_Row,1,COLUMN()-5)/calc_PF_Shares_mm
B14: Accretion / dilution % | C14: % | F14: =IFERROR(F13/F12-1,0) | G14: =IFERROR(G13/G12-1,0) | H14: =IFERROR(H13/H12-1,0) | I14: =IFERROR(I13/I12-1,0) | J14: =IFERROR(J13/J12-1,0) | K14: =IFERROR(K13/K12-1,0)
B16: EPS BRIDGE (YEAR 1, DKKM)
B17: Acquirer net income | C17: DKKm | F17: =INDEX(calc_A_NI_Row,1,2)
B18: Add target net income | C18: DKKm | F18: =INDEX(calc_T_NI_Row,1,2)
B19: Add synergies (net of tax) | C19: DKKm | F19: =INDEX(23_CALCS_PRO_FORMA_IS!$F${d_idx['Synergies (DKKm)']}:$K${d_idx['Synergies (DKKm)']},1,2)*(1-g_TaxRate)
B20: Less integration costs (net of tax) | C20: DKKm | F20: =INDEX(23_CALCS_PRO_FORMA_IS!$F${d_idx['Integration costs (DKKm)']}:$K${d_idx['Integration costs (DKKm)']},1,2)*(1-g_TaxRate)
B21: Less interest (net of tax) | C21: DKKm | F21: =(INDEX(23_CALCS_PRO_FORMA_IS!$F${d_idx['New debt interest (DKKm)']}:$K${d_idx['New debt interest (DKKm)']},1,2))*(1-g_TaxRate)
B22: Less PPA amort (net of tax) | C22: DKKm | F22: =INDEX(calc_PPA_Amort_Row,1,2)*(1-g_TaxRate)
B23: Pro forma net income | C23: DKKm | F23: =INDEX(calc_PF_NI_Row,1,2)

Sheet 30_OUTPUT_SUMMARY
B1: 30_OUTPUT_SUMMARY Dashboard source table (links only)
B5: LINE ITEM | C5: UNITS | D5: NOTES / SOURCES / FLAGS | F5: =03_GLOBAL_PARAMS!F24 | G5: =03_GLOBAL_PARAMS!G24 | H5: =03_GLOBAL_PARAMS!H24 | I5: =03_GLOBAL_PARAMS!I24 | J5: =03_GLOBAL_PARAMS!J24 | K5: =03_GLOBAL_PARAMS!K24
B6: KEY METRICS
B7: Revenue | C7: DKKm | F7: ='23_CALCS_PRO_FORMA_IS'!F30 | G7: ='23_CALCS_PRO_FORMA_IS'!G30 | H7: ='23_CALCS_PRO_FORMA_IS'!H30 | I7: ='23_CALCS_PRO_FORMA_IS'!I30 | J7: ='23_CALCS_PRO_FORMA_IS'!J30 | K7: ='23_CALCS_PRO_FORMA_IS'!K30
B8: EBITDA | C8: DKKm | F8: ='23_CALCS_PRO_FORMA_IS'!F31 | G8: ='23_CALCS_PRO_FORMA_IS'!G31 | H8: ='23_CALCS_PRO_FORMA_IS'!H31 | I8: ='23_CALCS_PRO_FORMA_IS'!I31 | J8: ='23_CALCS_PRO_FORMA_IS'!J31 | K8: ='23_CALCS_PRO_FORMA_IS'!K31
B9: EBIT | C9: DKKm | F9: ='23_CALCS_PRO_FORMA_IS'!F32 | G9: ='23_CALCS_PRO_FORMA_IS'!G32 | H9: ='23_CALCS_PRO_FORMA_IS'!H32 | I9: ='23_CALCS_PRO_FORMA_IS'!I32 | J9: ='23_CALCS_PRO_FORMA_IS'!J32 | K9: ='23_CALCS_PRO_FORMA_IS'!K32
B10: Net income | C10: DKKm | F10: ='23_CALCS_PRO_FORMA_IS'!F35 | G10: ='23_CALCS_PRO_FORMA_IS'!G35 | H10: ='23_CALCS_PRO_FORMA_IS'!H35 | I10: ='23_CALCS_PRO_FORMA_IS'!I35 | J10: ='23_CALCS_PRO_FORMA_IS'!J35 | K10: ='23_CALCS_PRO_FORMA_IS'!K35
B11: Pro forma EPS | C11: DKK | F11: ='26_CALCS_SHARES_AND_EPS'!F13 | G11: ='26_CALCS_SHARES_AND_EPS'!G13 | H11: ='26_CALCS_SHARES_AND_EPS'!H13 | I11: ='26_CALCS_SHARES_AND_EPS'!I13 | J11: ='26_CALCS_SHARES_AND_EPS'!J13 | K11: ='26_CALCS_SHARES_AND_EPS'!K13
B12: Accretion/dilution % | C12: % | F12: ='26_CALCS_SHARES_AND_EPS'!F14 | G12: ='26_CALCS_SHARES_AND_EPS'!G14 | H12: ='26_CALCS_SHARES_AND_EPS'!H14 | I12: ='26_CALCS_SHARES_AND_EPS'!I14 | J12: ='26_CALCS_SHARES_AND_EPS'!J14 | K12: ='26_CALCS_SHARES_AND_EPS'!K14
B13: Cash | C13: DKKm | F13: ='24_CALCS_PRO_FORMA_BS'!F7 | G13: ='24_CALCS_PRO_FORMA_BS'!G7 | H13: ='24_CALCS_PRO_FORMA_BS'!H7 | I13: ='24_CALCS_PRO_FORMA_BS'!I7 | J13: ='24_CALCS_PRO_FORMA_BS'!J7 | K13: ='24_CALCS_PRO_FORMA_BS'!K7
B14: Total debt | C14: DKKm | F14: ='24_CALCS_PRO_FORMA_BS'!F14 | G14: ='24_CALCS_PRO_FORMA_BS'!G14 | H14: ='24_CALCS_PRO_FORMA_BS'!H14 | I14: ='24_CALCS_PRO_FORMA_BS'!I14 | J14: ='24_CALCS_PRO_FORMA_BS'!J14 | K14: ='24_CALCS_PRO_FORMA_BS'!K14
B15: Net debt | C15: DKKm | F15: =F14-F13 | G15: =G14-G13 | H15: =H14-H13 | I15: =I14-I13 | J15: =J14-J13 | K15: =K14-K13
B16: Net debt / EBITDA | C16: x | F16: =IFERROR(F15/F8,0) | G16: =IFERROR(G15/G8,0) | H16: =IFERROR(H15/H8,0) | I16: =IFERROR(I15/I8,0) | J16: =IFERROR(J15/J8,0) | K16: =IFERROR(K15/K8,0)
B17: EV/EBITDA (close) | C17: x | F17: =calc_EV_DKK/(in_T_EBITDA_Y0*calc_FX_Spot_Used) | G17: =calc_EV_DKK/(in_T_EBITDA_Y0*calc_FX_Spot_Used) | H17: =calc_EV_DKK/(in_T_EBITDA_Y0*calc_FX_Spot_Used) | I17: =calc_EV_DKK/(in_T_EBITDA_Y0*calc_FX_Spot_Used) | J17: =calc_EV_DKK/(in_T_EBITDA_Y0*calc_FX_Spot_Used) | K17: =calc_EV_DKK/(in_T_EBITDA_Y0*calc_FX_Spot_Used)
B18: EV/Revenue (close) | C18: x | F18: =calc_EV_DKK/(in_T_Revenue_Y0*calc_FX_Spot_Used) | G18: =calc_EV_DKK/(in_T_Revenue_Y0*calc_FX_Spot_Used) | H18: =calc_EV_DKK/(in_T_Revenue_Y0*calc_FX_Spot_Used) | I18: =calc_EV_DKK/(in_T_Revenue_Y0*calc_FX_Spot_Used) | J18: =calc_EV_DKK/(in_T_Revenue_Y0*calc_FX_Spot_Used) | K18: =calc_EV_DKK/(in_T_Revenue_Y0*calc_FX_Spot_Used)
B19: Synergy run-rate (DKKm) | C19: DKKm | F19: =in_SynergyRunRate | G19: =in_SynergyRunRate | H19: =in_SynergyRunRate | I19: =in_SynergyRunRate | J19: =in_SynergyRunRate | K19: =in_SynergyRunRate
B20: Synergy ramp % (Year1) | C20: % | F20: =INDEX(in_SynergyRamp_Row,1,COLUMN()-5) | G20: =INDEX(in_SynergyRamp_Row,1,COLUMN()-5) | H20: =INDEX(in_SynergyRamp_Row,1,COLUMN()-5) | I20: =INDEX(in_SynergyRamp_Row,1,COLUMN()-5) | J20: =INDEX(in_SynergyRamp_Row,1,COLUMN()-5) | K20: =INDEX(in_SynergyRamp_Row,1,COLUMN()-5)
B21: Goodwill created (DKKm) | C21: DKKm | F21: =calc_Goodwill | G21: =calc_Goodwill | H21: =calc_Goodwill | I21: =calc_Goodwill | J21: =calc_Goodwill | K21: =calc_Goodwill
B22: Intangibles created (DKKm) | C22: DKKm | F22: =calc_Intangibles_FV | G22: =calc_Intangibles_FV | H22: =calc_Intangibles_FV | I22: =calc_Intangibles_FV | J22: =calc_Intangibles_FV | K22: =calc_Intangibles_FV
B23: PPA amort (Year1) | C23: DKKm | F23: =INDEX(calc_PPA_Amort_Row,1,COLUMN()-5) | G23: =INDEX(calc_PPA_Amort_Row,1,COLUMN()-5) | H23: =INDEX(calc_PPA_Amort_Row,1,COLUMN()-5) | I23: =INDEX(calc_PPA_Amort_Row,1,COLUMN()-5) | J23: =INDEX(calc_PPA_Amort_Row,1,COLUMN()-5) | K23: =INDEX(calc_PPA_Amort_Row,1,COLUMN()-5)

Sheet 31_OUTPUT_SENSITIVITIES
B1: 31_OUTPUT_SENSITIVITIES Sensitivity pack
B5: LINE ITEM | C5: UNITS | D5: NOTES / SOURCES / FLAGS | F5: =03_GLOBAL_PARAMS!F24 | G5: =03_GLOBAL_PARAMS!G24 | H5: =03_GLOBAL_PARAMS!H24 | I5: =03_GLOBAL_PARAMS!I24 | J5: =03_GLOBAL_PARAMS!J24 | K5: =03_GLOBAL_PARAMS!K24
B6: HEATMAP: ACC/DIL % VS EV/EBITDA MULTIPLE AND SYNERGY RUN-RATE (YEAR 1)
B7: Multiple list (x) | C7: x | F7: 8 | G7: 10 | H7: 12 | I7: 14 | J7: 16
B8: Synergy list (DKKm) | C8: DKKm | F8: 0
F9: 8 | G9: 10 | H9: 12 | I9: 14 | J9: 16
E10: 0 | F10: =IFERROR(((INDEX(calc_A_NI_Row,1,2)+INDEX(calc_T_NI_Row,1,2)+(0*INDEX(in_SynergyRamp_Row,1,2))*(1-g_TaxRate)+(INDEX(in_Integration_Row,1,2))*(1-g_TaxRate)+((-(((8*(in_T_EBITDA_Y0*calc_FX_Spot_Used)) - calc_NetDebt_DKK)*in_DebtPct)*(in_BaseRate + in_T1_Margin)))*(1-g_TaxRate)+(INDEX(calc_PPA_Amort_Row,1,2))*(1-g_TaxRate))/(in_A_Shares_Basic + (((8*(in_T_EBITDA_Y0*calc_FX_Spot_Used)) - calc_NetDebt_DKK)*in_StockPct)/in_A_SharePrice))/26_CALCS_SHARES_AND_EPS!G12-1,0) | G10: =IFERROR(((INDEX(calc_A_NI_Row,1,2)+INDEX(calc_T_NI_Row,1,2)+(0*INDEX(in_SynergyRamp_Row,1,2))*(1-g_TaxRate)+(INDEX(in_Integration_Row,1,2))*(1-g_TaxRate)+((-(((10*(in_T_EBITDA_Y0*calc_FX_Spot_Used)) - calc_NetDebt_DKK)*in_DebtPct)*(in_BaseRate + in_T1_Margin)))*(1-g_TaxRate)+(INDEX(calc_PPA_Amort_Row,1,2))*(1-g_TaxRate))/(in_A_Shares_Basic + (((10*(in_T_EBITDA_Y0*calc_FX_Spot_Used)) - calc_NetDebt_DKK)*in_StockPct)/in_A_SharePrice))/26_CALCS_SHARES_AND_EPS!G12-1,0) | H10: =IFERROR(((INDEX(calc_A_NI_Row,1,2)+INDEX(calc_T_NI_Row,1,2)+(0*INDEX(in_SynergyRamp_Row,1,2))*(1-g_TaxRate)+(INDEX(in_Integration_Row,1,2))*(1-g_TaxRate)+((-(((12*(in_T_EBITDA_Y0*calc_FX_Spot_Used)) - calc_NetDebt_DKK)*in_DebtPct)*(in_BaseRate + in_T1_Margin)))*(1-g_TaxRate)+(INDEX(calc_PPA_Amort_Row,1,2))*(1-g_TaxRate))/(in_A_Shares_Basic + (((12*(in_T_EBITDA_Y0*calc_FX_Spot_Used)) - calc_NetDebt_DKK)*in_StockPct)/in_A_SharePrice))/26_CALCS_SHARES_AND_EPS!G12-1,0) | I10: =IFERROR(((INDEX(calc_A_NI_Row,1,2)+INDEX(calc_T_NI_Row,1,2)+(0*INDEX(in_SynergyRamp_Row,1,2))*(1-g_TaxRate)+(INDEX(in_Integration_Row,1,2))*(1-g_TaxRate)+((-(((14*(in_T_EBITDA_Y0*calc_FX_Spot_Used)) - calc_NetDebt_DKK)*in_DebtPct)*(in_BaseRate + in_T1_Margin)))*(1-g_TaxRate)+(INDEX(calc_PPA_Amort_Row,1,2))*(1-g_TaxRate))/(in_A_Shares_Basic + (((14*(in_T_EBITDA_Y0*calc_FX_Spot_Used)) - calc_NetDebt_DKK)*in_StockPct)/in_A_SharePrice))/26_CALCS_SHARES_AND_EPS!G12-1,0) | J10: =IFERROR(((INDEX(calc_A_NI_Row,1,2)+INDEX(calc_T_NI_Row,1,2)+(0*INDEX(in_SynergyRamp_Row,1,2))*(1-g_TaxRate)+(INDEX(in_Integration_Row,1,2))*(1-g_TaxRate)+((-(((16*(in_T_EBITDA_Y0*calc_FX_Spot_Used)) - calc_NetDebt_DKK)*in_DebtPct)*(in_BaseRate + in_T1_Margin)))*(1-g_TaxRate)+(INDEX(calc_PPA_Amort_Row,1,2))*(1-g_TaxRate))/(in_A_Shares_Basic + (((16*(in_T_EBITDA_Y0*calc_FX_Spot_Used)) - calc_NetDebt_DKK)*in_StockPct)/in_A_SharePrice))/26_CALCS_SHARES_AND_EPS!G12-1,0)
E11: 50 | F11: =IFERROR(((INDEX(calc_A_NI_Row,1,2)+INDEX(calc_T_NI_Row,1,2)+(50*INDEX(in_SynergyRamp_Row,1,2))*(1-g_TaxRate)+(INDEX(in_Integration_Row,1,2))*(1-g_TaxRate)+((-(((8*(in_T_EBITDA_Y0*calc_FX_Spot_Used)) - calc_NetDebt_DKK)*in_DebtPct)*(in_BaseRate + in_T1_Margin)))*(1-g_TaxRate)+(INDEX(calc_PPA_Amort_Row,1,2))*(1-g_TaxRate))/(in_A_Shares_Basic + (((8*(in_T_EBITDA_Y0*calc_FX_Spot_Used)) - calc_NetDebt_DKK)*in_StockPct)/in_A_SharePrice))/26_CALCS_SHARES_AND_EPS!G12-1,0) | G11: =IFERROR(((INDEX(calc_A_NI_Row,1,2)+INDEX(calc_T_NI_Row,1,2)+(50*INDEX(in_SynergyRamp_Row,1,2))*(1-g_TaxRate)+(INDEX(in_Integration_Row,1,2))*(1-g_TaxRate)+((-(((10*(in_T_EBITDA_Y0*calc_FX_Spot_Used)) - calc_NetDebt_DKK)*in_DebtPct)*(in_BaseRate + in_T1_Margin)))*(1-g_TaxRate)+(INDEX(calc_PPA_Amort_Row,1,2))*(1-g_TaxRate))/(in_A_Shares_Basic + (((10*(in_T_EBITDA_Y0*calc_FX_Spot_Used)) - calc_NetDebt_DKK)*in_StockPct)/in_A_SharePrice))/26_CALCS_SHARES_AND_EPS!G12-1,0) | H11: =IFERROR(((INDEX(calc_A_NI_Row,1,2)+INDEX(calc_T_NI_Row,1,2)+(50*INDEX(in_SynergyRamp_Row,1,2))*(1-g_TaxRate)+(INDEX(in_Integration_Row,1,2))*(1-g_TaxRate)+((-(((12*(in_T_EBITDA_Y0*calc_FX_Spot_Used)) - calc_NetDebt_DKK)*in_DebtPct)*(in_BaseRate + in_T1_Margin)))*(1-g_TaxRate)+(INDEX(calc_PPA_Amort_Row,1,2))*(1-g_TaxRate))/(in_A_Shares_Basic + (((12*(in_T_EBITDA_Y0*calc_FX_Spot_Used)) - calc_NetDebt_DKK)*in_StockPct)/in_A_SharePrice))/26_CALCS_SHARES_AND_EPS!G12-1,0) | I11: =IFERROR(((INDEX(calc_A_NI_Row,1,2)+INDEX(calc_T_NI_Row,1,2)+(50*INDEX(in_SynergyRamp_Row,1,2))*(1-g_TaxRate)+(INDEX(in_Integration_Row,1,2))*(1-g_TaxRate)+((-(((14*(in_T_EBITDA_Y0*calc_FX_Spot_Used)) - calc_NetDebt_DKK)*in_DebtPct)*(in_BaseRate + in_T1_Margin)))*(1-g_TaxRate)+(INDEX(calc_PPA_Amort_Row,1,2))*(1-g_TaxRate))/(in_A_Shares_Basic + (((14*(in_T_EBITDA_Y0*calc_FX_Spot_Used)) - calc_NetDebt_DKK)*in_StockPct)/in_A_SharePrice))/26_CALCS_SHARES_AND_EPS!G12-1,0) | J11: =IFERROR(((INDEX(calc_A_NI_Row,1,2)+INDEX(calc_T_NI_Row,1,2)+(50*INDEX(in_SynergyRamp_Row,1,2))*(1-g_TaxRate)+(INDEX(in_Integration_Row,1,2))*(1-g_TaxRate)+((-(((16*(in_T_EBITDA_Y0*calc_FX_Spot_Used)) - calc_NetDebt_DKK)*in_DebtPct)*(in_BaseRate + in_T1_Margin)))*(1-g_TaxRate)+(INDEX(calc_PPA_Amort_Row,1,2))*(1-g_TaxRate))/(in_A_Shares_Basic + (((16*(in_T_EBITDA_Y0*calc_FX_Spot_Used)) - calc_NetDebt_DKK)*in_StockPct)/in_A_SharePrice))/26_CALCS_SHARES_AND_EPS!G12-1,0)
E12: 100 | F12: =IFERROR(((INDEX(calc_A_NI_Row,1,2)+INDEX(calc_T_NI_Row,1,2)+(100*INDEX(in_SynergyRamp_Row,1,2))*(1-g_TaxRate)+(INDEX(in_Integration_Row,1,2))*(1-g_TaxRate)+((-(((8*(in_T_EBITDA_Y0*calc_FX_Spot_Used)) - calc_NetDebt_DKK)*in_DebtPct)*(in_BaseRate + in_T1_Margin)))*(1-g_TaxRate)+(INDEX(calc_PPA_Amort_Row,1,2))*(1-g_TaxRate))/(in_A_Shares_Basic + (((8*(in_T_EBITDA_Y0*calc_FX_Spot_Used)) - calc_NetDebt_DKK)*in_StockPct)/in_A_SharePrice))/26_CALCS_SHARES_AND_EPS!G12-1,0) | G12: =IFERROR(((INDEX(calc_A_NI_Row,1,2)+INDEX(calc_T_NI_Row,1,2)+(100*INDEX(in_SynergyRamp_Row,1,2))*(1-g_TaxRate)+(INDEX(in_Integration_Row,1,2))*(1-g_TaxRate)+((-(((10*(in_T_EBITDA_Y0*calc_FX_Spot_Used)) - calc_NetDebt_DKK)*in_DebtPct)*(in_BaseRate + in_T1_Margin)))*(1-g_TaxRate)+(INDEX(calc_PPA_Amort_Row,1,2))*(1-g_TaxRate))/(in_A_Shares_Basic + (((10*(in_T_EBITDA_Y0*calc_FX_Spot_Used)) - calc_NetDebt_DKK)*in_StockPct)/in_A_SharePrice))/26_CALCS_SHARES_AND_EPS!G12-1,0) | H12: =IFERROR(((INDEX(calc_A_NI_Row,1,2)+INDEX(calc_T_NI_Row,1,2)+(100*INDEX(in_SynergyRamp_Row,1,2))*(1-g_TaxRate)+(INDEX(in_Integration_Row,1,2))*(1-g_TaxRate)+((-(((12*(in_T_EBITDA_Y0*calc_FX_Spot_Used)) - calc_NetDebt_DKK)*in_DebtPct)*(in_BaseRate + in_T1_Margin)))*(1-g_TaxRate)+(INDEX(calc_PPA_Amort_Row,1,2))*(1-g_TaxRate))/(in_A_Shares_Basic + (((12*(in_T_EBITDA_Y0*calc_FX_Spot_Used)) - calc_NetDebt_DKK)*in_StockPct)/in_A_SharePrice))/26_CALCS_SHARES_AND_EPS!G12-1,0) | I12: =IFERROR(((INDEX(calc_A_NI_Row,1,2)+INDEX(calc_T_NI_Row,1,2)+(100*INDEX(in_SynergyRamp_Row,1,2))*(1-g_TaxRate)+(INDEX(in_Integration_Row,1,2))*(1-g_TaxRate)+((-(((14*(in_T_EBITDA_Y0*calc_FX_Spot_Used)) - calc_NetDebt_DKK)*in_DebtPct)*(in_BaseRate + in_T1_Margin)))*(1-g_TaxRate)+(INDEX(calc_PPA_Amort_Row,1,2))*(1-g_TaxRate))/(in_A_Shares_Basic + (((14*(in_T_EBITDA_Y0*calc_FX_Spot_Used)) - calc_NetDebt_DKK)*in_StockPct)/in_A_SharePrice))/26_CALCS_SHARES_AND_EPS!G12-1,0) | J12: =IFERROR(((INDEX(calc_A_NI_Row,1,2)+INDEX(calc_T_NI_Row,1,2)+(100*INDEX(in_SynergyRamp_Row,1,2))*(1-g_TaxRate)+(INDEX(in_Integration_Row,1,2))*(1-g_TaxRate)+((-(((16*(in_T_EBITDA_Y0*calc_FX_Spot_Used)) - calc_NetDebt_DKK)*in_DebtPct)*(in_BaseRate + in_T1_Margin)))*(1-g_TaxRate)+(INDEX(calc_PPA_Amort_Row,1,2))*(1-g_TaxRate))/(in_A_Shares_Basic + (((16*(in_T_EBITDA_Y0*calc_FX_Spot_Used)) - calc_NetDebt_DKK)*in_StockPct)/in_A_SharePrice))/26_CALCS_SHARES_AND_EPS!G12-1,0)
E13: 150 | F13: =IFERROR(((INDEX(calc_A_NI_Row,1,2)+INDEX(calc_T_NI_Row,1,2)+(150*INDEX(in_SynergyRamp_Row,1,2))*(1-g_TaxRate)+(INDEX(in_Integration_Row,1,2))*(1-g_TaxRate)+((-(((8*(in_T_EBITDA_Y0*calc_FX_Spot_Used)) - calc_NetDebt_DKK)*in_DebtPct)*(in_BaseRate + in_T1_Margin)))*(1-g_TaxRate)+(INDEX(calc_PPA_Amort_Row,1,2))*(1-g_TaxRate))/(in_A_Shares_Basic + (((8*(in_T_EBITDA_Y0*calc_FX_Spot_Used)) - calc_NetDebt_DKK)*in_StockPct)/in_A_SharePrice))/26_CALCS_SHARES_AND_EPS!G12-1,0) | G13: =IFERROR(((INDEX(calc_A_NI_Row,1,2)+INDEX(calc_T_NI_Row,1,2)+(150*INDEX(in_SynergyRamp_Row,1,2))*(1-g_TaxRate)+(INDEX(in_Integration_Row,1,2))*(1-g_TaxRate)+((-(((10*(in_T_EBITDA_Y0*calc_FX_Spot_Used)) - calc_NetDebt_DKK)*in_DebtPct)*(in_BaseRate + in_T1_Margin)))*(1-g_TaxRate)+(INDEX(calc_PPA_Amort_Row,1,2))*(1-g_TaxRate))/(in_A_Shares_Basic + (((10*(in_T_EBITDA_Y0*calc_FX_Spot_Used)) - calc_NetDebt_DKK)*in_StockPct)/in_A_SharePrice))/26_CALCS_SHARES_AND_EPS!G12-1,0) | H13: =IFERROR(((INDEX(calc_A_NI_Row,1,2)+INDEX(calc_T_NI_Row,1,2)+(150*INDEX(in_SynergyRamp_Row,1,2))*(1-g_TaxRate)+(INDEX(in_Integration_Row,1,2))*(1-g_TaxRate)+((-(((12*(in_T_EBITDA_Y0*calc_FX_Spot_Used)) - calc_NetDebt_DKK)*in_DebtPct)*(in_BaseRate + in_T1_Margin)))*(1-g_TaxRate)+(INDEX(calc_PPA_Amort_Row,1,2))*(1-g_TaxRate))/(in_A_Shares_Basic + (((12*(in_T_EBITDA_Y0*calc_FX_Spot_Used)) - calc_NetDebt_DKK)*in_StockPct)/in_A_SharePrice))/26_CALCS_SHARES_AND_EPS!G12-1,0) | I13: =IFERROR(((INDEX(calc_A_NI_Row,1,2)+INDEX(calc_T_NI_Row,1,2)+(150*INDEX(in_SynergyRamp_Row,1,2))*(1-g_TaxRate)+(INDEX(in_Integration_Row,1,2))*(1-g_TaxRate)+((-(((14*(in_T_EBITDA_Y0*calc_FX_Spot_Used)) - calc_NetDebt_DKK)*in_DebtPct)*(in_BaseRate + in_T1_Margin)))*(1-g_TaxRate)+(INDEX(calc_PPA_Amort_Row,1,2))*(1-g_TaxRate))/(in_A_Shares_Basic + (((14*(in_T_EBITDA_Y0*calc_FX_Spot_Used)) - calc_NetDebt_DKK)*in_StockPct)/in_A_SharePrice))/26_CALCS_SHARES_AND_EPS!G12-1,0) | J13: =IFERROR(((INDEX(calc_A_NI_Row,1,2)+INDEX(calc_T_NI_Row,1,2)+(150*INDEX(in_SynergyRamp_Row,1,2))*(1-g_TaxRate)+(INDEX(in_Integration_Row,1,2))*(1-g_TaxRate)+((-(((16*(in_T_EBITDA_Y0*calc_FX_Spot_Used)) - calc_NetDebt_DKK)*in_DebtPct)*(in_BaseRate + in_T1_Margin)))*(1-g_TaxRate)+(INDEX(calc_PPA_Amort_Row,1,2))*(1-g_TaxRate))/(in_A_Shares_Basic + (((16*(in_T_EBITDA_Y0*calc_FX_Spot_Used)) - calc_NetDebt_DKK)*in_StockPct)/in_A_SharePrice))/26_CALCS_SHARES_AND_EPS!G12-1,0)
