Workbook

Sheet 00_DASHBOARD
B2: VALUATION DASHBOARD
B3: All tiles link to output cells in 08_TRIANGULATION_RANGE (or 90_CHECKS for status).
B9: BASE CASE OUTPUTS
B10: Current share price | C10: CCY | F10: ='08_TRIANGULATION_RANGE'!$F$47 | H10: Method | I10: Low | J10: Range
B11: Shares outstanding (mm) | C11: mm | F11: ='08_TRIANGULATION_RANGE'!$F$48 | H11: Comps | I11: ='08_TRIANGULATION_RANGE'!$F$16 | J11: =IFERROR('08_TRIANGULATION_RANGE'!$F$18-'08_TRIANGULATION_RANGE'!$F$16,"")
B12: Market cap | C12: m | F12: ='08_TRIANGULATION_RANGE'!$F$49 | H12: DCF | I12: ='08_TRIANGULATION_RANGE'!$F$26 | J12: =IFERROR('08_TRIANGULATION_RANGE'!$F$28-'08_TRIANGULATION_RANGE'!$F$26,"")
B13: Net debt | C13: m | F13: ='08_TRIANGULATION_RANGE'!$F$50 | H13: Combined | I13: ='08_TRIANGULATION_RANGE'!$F$34 | J13: =IFERROR('08_TRIANGULATION_RANGE'!$F$36-'08_TRIANGULATION_RANGE'!$F$34,"")
B14: Enterprise value | C14: m | F14: ='08_TRIANGULATION_RANGE'!$F$51
B15: Equity value (Base) | C15: m | F15: ='08_TRIANGULATION_RANGE'!$F$64
B16: Implied price per share (Base) | C16: CCY | F16: ='08_TRIANGULATION_RANGE'!$F$52
B17: Upside vs current | C17: % | F17: ='08_TRIANGULATION_RANGE'!$F$53
B18: Downside vs current (Downside) | C18: % | F18: ='08_TRIANGULATION_RANGE'!$F$54
B19: Trading comps multiple used (EV/EBITDA) | C19: x | F19: =08_TRIANGULATION_RANGE!F72
B20: DCF status (ON/OFF) | F20: =08_TRIANGULATION_RANGE!F66
B21: WACC (Base) | C21: % | F21: =08_TRIANGULATION_RANGE!F67
B22: Terminal method | F22: =08_TRIANGULATION_RANGE!F70
B23: Mid-year convention | F23: =08_TRIANGULATION_RANGE!F71
B26: RANGE OUTPUTS
B27: Comps equity value P25 | C27: m | F27: ='08_TRIANGULATION_RANGE'!$F$55
B28: Comps equity value Median | C28: m | F28: ='08_TRIANGULATION_RANGE'!$F$56
B29: Comps equity value P75 | C29: m | F29: ='08_TRIANGULATION_RANGE'!$F$57
B31: DCF equity value Downside | C31: m | F31: ='08_TRIANGULATION_RANGE'!$F$58
B32: DCF equity value Base | C32: m | F32: ='08_TRIANGULATION_RANGE'!$F$59 | H32: Scenario | I32: Combined implied price
B33: DCF equity value Upside | C33: m | F33: ='08_TRIANGULATION_RANGE'!$F$60 | H33: Downside | I33: =='08_TRIANGULATION_RANGE'!$F$61
H34: Base | I34: =='08_TRIANGULATION_RANGE'!$F$62
B35: Combined implied price Downside | C35: CCY | F35: ='08_TRIANGULATION_RANGE'!$F$61 | H35: Upside | I35: =='08_TRIANGULATION_RANGE'!$F$63
B36: Combined implied price Base | C36: CCY | F36: ='08_TRIANGULATION_RANGE'!$F$62
B37: Combined implied price Upside | C37: CCY | F37: ='08_TRIANGULATION_RANGE'!$F$63
B40: CHECKS STATUS (FROM 90_CHECKS) | H40: Sensitivity heatmap (Implied price)
B41: Overall status | F41: ='90_CHECKS'!$F$3 | I41: =IF('01_CONTROL'!$F$15=1,'09_SENSITIVITIES'!G15,'09_SENSITIVITIES'!G25) | J41: =IF('01_CONTROL'!$F$15=1,'09_SENSITIVITIES'!H15,'09_SENSITIVITIES'!H25) | K41: =IF('01_CONTROL'!$F$15=1,'09_SENSITIVITIES'!I15,'09_SENSITIVITIES'!I25) | L41: =IF('01_CONTROL'!$F$15=1,'09_SENSITIVITIES'!J15,'09_SENSITIVITIES'!J25) | M41: =IF('01_CONTROL'!$F$15=1,'09_SENSITIVITIES'!K15,'09_SENSITIVITIES'!K25) | N41: =IF('01_CONTROL'!$F$15=1,'09_SENSITIVITIES'!L15,'09_SENSITIVITIES'!L25)
B42: Fail count | F42: ='90_CHECKS'!$F$4 | H42: =IF('01_CONTROL'!$F$15=1,'09_SENSITIVITIES'!$F$16,'09_SENSITIVITIES'!$F$26) | I42: =IF('01_CONTROL'!$F$15=1,'09_SENSITIVITIES'!G16,'09_SENSITIVITIES'!G26) | J42: =IF('01_CONTROL'!$F$15=1,'09_SENSITIVITIES'!H16,'09_SENSITIVITIES'!H26) | K42: =IF('01_CONTROL'!$F$15=1,'09_SENSITIVITIES'!I16,'09_SENSITIVITIES'!I26) | L42: =IF('01_CONTROL'!$F$15=1,'09_SENSITIVITIES'!J16,'09_SENSITIVITIES'!J26) | M42: =IF('01_CONTROL'!$F$15=1,'09_SENSITIVITIES'!K16,'09_SENSITIVITIES'!K26) | N42: =IF('01_CONTROL'!$F$15=1,'09_SENSITIVITIES'!L16,'09_SENSITIVITIES'!L26)
H43: =IF('01_CONTROL'!$F$15=1,'09_SENSITIVITIES'!$F$17,'09_SENSITIVITIES'!$F$27) | I43: =IF('01_CONTROL'!$F$15=1,'09_SENSITIVITIES'!G17,'09_SENSITIVITIES'!G27) | J43: =IF('01_CONTROL'!$F$15=1,'09_SENSITIVITIES'!H17,'09_SENSITIVITIES'!H27) | K43: =IF('01_CONTROL'!$F$15=1,'09_SENSITIVITIES'!I17,'09_SENSITIVITIES'!I27) | L43: =IF('01_CONTROL'!$F$15=1,'09_SENSITIVITIES'!J17,'09_SENSITIVITIES'!J27) | M43: =IF('01_CONTROL'!$F$15=1,'09_SENSITIVITIES'!K17,'09_SENSITIVITIES'!K27) | N43: =IF('01_CONTROL'!$F$15=1,'09_SENSITIVITIES'!L17,'09_SENSITIVITIES'!L27)
B44: Top 5 checks | H44: =IF('01_CONTROL'!$F$15=1,'09_SENSITIVITIES'!$F$18,'09_SENSITIVITIES'!$F$28) | I44: =IF('01_CONTROL'!$F$15=1,'09_SENSITIVITIES'!G18,'09_SENSITIVITIES'!G28) | J44: =IF('01_CONTROL'!$F$15=1,'09_SENSITIVITIES'!H18,'09_SENSITIVITIES'!H28) | K44: =IF('01_CONTROL'!$F$15=1,'09_SENSITIVITIES'!I18,'09_SENSITIVITIES'!I28) | L44: =IF('01_CONTROL'!$F$15=1,'09_SENSITIVITIES'!J18,'09_SENSITIVITIES'!J28) | M44: =IF('01_CONTROL'!$F$15=1,'09_SENSITIVITIES'!K18,'09_SENSITIVITIES'!K28) | N44: =IF('01_CONTROL'!$F$15=1,'09_SENSITIVITIES'!L18,'09_SENSITIVITIES'!L28)
B45: 1. | C45: ='90_CHECKS'!$B$9 | F45: ='90_CHECKS'!$G$9 | H45: =IF('01_CONTROL'!$F$15=1,'09_SENSITIVITIES'!$F$19,'09_SENSITIVITIES'!$F$29) | I45: =IF('01_CONTROL'!$F$15=1,'09_SENSITIVITIES'!G19,'09_SENSITIVITIES'!G29) | J45: =IF('01_CONTROL'!$F$15=1,'09_SENSITIVITIES'!H19,'09_SENSITIVITIES'!H29) | K45: =IF('01_CONTROL'!$F$15=1,'09_SENSITIVITIES'!I19,'09_SENSITIVITIES'!I29) | L45: =IF('01_CONTROL'!$F$15=1,'09_SENSITIVITIES'!J19,'09_SENSITIVITIES'!J29) | M45: =IF('01_CONTROL'!$F$15=1,'09_SENSITIVITIES'!K19,'09_SENSITIVITIES'!K29) | N45: =IF('01_CONTROL'!$F$15=1,'09_SENSITIVITIES'!L19,'09_SENSITIVITIES'!L29)
B46: 2. | C46: ='90_CHECKS'!$B$10 | F46: ='90_CHECKS'!$G$10 | H46: =IF('01_CONTROL'!$F$15=1,'09_SENSITIVITIES'!$F$20,'09_SENSITIVITIES'!$F$30) | I46: =IF('01_CONTROL'!$F$15=1,'09_SENSITIVITIES'!G20,'09_SENSITIVITIES'!G30) | J46: =IF('01_CONTROL'!$F$15=1,'09_SENSITIVITIES'!H20,'09_SENSITIVITIES'!H30) | K46: =IF('01_CONTROL'!$F$15=1,'09_SENSITIVITIES'!I20,'09_SENSITIVITIES'!I30) | L46: =IF('01_CONTROL'!$F$15=1,'09_SENSITIVITIES'!J20,'09_SENSITIVITIES'!J30) | M46: =IF('01_CONTROL'!$F$15=1,'09_SENSITIVITIES'!K20,'09_SENSITIVITIES'!K30) | N46: =IF('01_CONTROL'!$F$15=1,'09_SENSITIVITIES'!L20,'09_SENSITIVITIES'!L30)
B47: 3. | C47: ='90_CHECKS'!$B$11 | F47: ='90_CHECKS'!$G$11 | H47: =IF('01_CONTROL'!$F$15=1,'09_SENSITIVITIES'!$F$21,'09_SENSITIVITIES'!$F$31) | I47: =IF('01_CONTROL'!$F$15=1,'09_SENSITIVITIES'!G21,'09_SENSITIVITIES'!G31) | J47: =IF('01_CONTROL'!$F$15=1,'09_SENSITIVITIES'!H21,'09_SENSITIVITIES'!H31) | K47: =IF('01_CONTROL'!$F$15=1,'09_SENSITIVITIES'!I21,'09_SENSITIVITIES'!I31) | L47: =IF('01_CONTROL'!$F$15=1,'09_SENSITIVITIES'!J21,'09_SENSITIVITIES'!J31) | M47: =IF('01_CONTROL'!$F$15=1,'09_SENSITIVITIES'!K21,'09_SENSITIVITIES'!K31) | N47: =IF('01_CONTROL'!$F$15=1,'09_SENSITIVITIES'!L21,'09_SENSITIVITIES'!L31)
B48: 4. | C48: ='90_CHECKS'!$B$12 | F48: ='90_CHECKS'!$G$12
B49: 5. | C49: ='90_CHECKS'!$B$13 | F49: ='90_CHECKS'!$G$13
B52: INTERPRETATION (AUTO FILLED WHERE POSSIBLE)
B53: What drives valuation today | F53: ="Comps EV/EBITDA x "&TEXT('05_TRADING_COMPS'!$F$32,"0.0")&", DCF "&'01_CONTROL'!$F$12
...

Sheet 01_CONTROL
B2: 01_CONTROL
B3: Model
B4: Company
B5: Version
B6: Last updated | F6: =TODAY()
B8: SECTION
B9: Scenario (Base/Upside/Downside) | F9: Base
B10: Scenario index | F10: =MATCH(F9,{"Base","Upside","Downside"},0)
B11: Forecast horizon (years) | F11: 5
B12: DCF (ON/OFF) | F12: ON
B13: DCF flag | F13: =IF(F12="ON",1,0)
B14: Terminal method | F14: Perpetuity
B15: TV method flag (1=Perpetuity) | F15: =IF(F14="Perpetuity",1,0)
B16: Mid-year convention (ON/OFF) | F16: OFF
B17: Mid-year flag | F17: =IF(F16="ON",1,0)
B18: Currency | F18: DKK
B19: Units | F19: DKKm
B20: Shares units | F20: Shares in millions
B23: WACC ASSUMPTIONS
B24: Tax rate | F24: 0.22
B25: Risk-free rate | F25: 0.03
B26: Equity risk premium | F26: 0.05
B27: Beta | F27: 1
B28: Size / country adj (optional) | F28: 0
B29: Pre-tax cost of debt | F29: 0.05
B30: Target debt weight | F30: 0.3
B31: Target equity weight | F31: 0.7
B32: Weights sum to 100% | F32: =F30+F31
B34: Cost of equity | F34: =F25 + F27*F26 + F28
B35: After-tax cost of debt | F35: =F29*(1-F24)
B36: WACC (base) | F36: =F31*F34 + F30*F35
B40: NET DEBT DEFINITION TOGGLES
B41: Include leases in net debt | E41: Flag | F41: YES | G41: =IF(F41="YES",1,0)
B42: Include pension | E42: Flag | F42: NO | G42: =IF(F42="YES",1,0)
B43: Include minorities | E43: Flag | F43: YES | G43: =IF(F43="YES",1,0)
B44: Include investments | E44: Flag | F44: NO | G44: =IF(F44="YES",1,0)
B45: Include other adjustments | E45: Flag | F45: YES | G45: =IF(F45="YES",1,0)
B47: MODEL CALENDAR
B48: Base year (FY0) | F48: 2025
B50: Period index | F50: 0 | G50: 1 | H50: 2 | I50: 3 | J50: 4 | K50: 5 | L50: 6 | M50: 7 | N50: 8 | O50: 9 | P50: 10
...

Sheet 02_COMPANY_INPUTS
B2: 02_COMPANY_INPUTS
B3: Model
B4: Company
B5: Version
B6: Last updated | F6: =TODAY()
B8: SECTION
B9: EQUITY AND MARKET DATA
B10: Current share price | C10: CCY
B11: Shares outstanding (mm) | C11: mm
B12: Market cap | C12: m | F12: =IF(OR(F10="",F11=""),"",F10*F11)
B15: NET DEBT BRIDGE INPUTS
B16: Cash and equivalents | C16: m
B17: Gross debt | C17: m
B18: Lease liabilities | C18: m
B19: Pension liabilities | C19: m
B20: Minority interests | C20: m
B21: Investments / associates | C21: m
B22: Other adjustments | C22: m
B24: NET DEBT (PER TOGGLES)
B25: Include flags (from 01_CONTROL)
B26: Net debt (output) | C26: m | F26: =IF(COUNTA(F16:F22)=0,"",IFERROR(F17+'01_CONTROL'!$G$41*F18+'01_CONTROL'!$G$42*F19+'01_CONTROL'!$G$43*F20-F16-'01_CONTROL'!$G$44*F21+'01_CONTROL'!$G$45*F22,""))
B29: LTM KEY METRICS (INPUTS)
B30: LTM revenue | C30: m
B31: LTM EBITDA | C31: m
B32: LTM EBIT | C32: m
B33: LTM D&A | C33: m
B34: LTM capex | C34: m
B35: LTM NWC | C35: m
B37: DERIVED RATIOS (CALC)
B38: EBITDA margin | C38: % | F38: =IF($F$30="","",IFERROR($F$31/$F$30,""))
B39: D&A % of revenue | C39: % | F39: =IF($F$30="","",IFERROR($F$33/$F$30,""))
B40: Capex % of revenue | C40: % | F40: =IF($F$30="","",IFERROR($F$34/$F$30,""))
B41: NWC % of revenue | C41: % | F41: =IF($F$30="","",IFERROR($F$35/$F$30,""))

Sheet 03_HISTORICALS
B2: 03_HISTORICALS
B3: Model
B4: Company
B5: Version
B6: Last updated | F6: =TODAY()
B8: SECTION
B9: INCOME STATEMENT (HISTORICAL)
F10: FY-2 | G10: FY-1 | H10: FY0 | I10: LTM
B11: Revenue | C11: m
B12: EBITDA | C12: m
B13: D&A | C13: m
B14: EBIT | C14: m
B15: Taxes | C15: m
B16: Net income | C16: m
B17: EBITDA margin | C17: % | F17: =IFERROR(F12/F11,"") | G17: =IFERROR(G12/G11,"") | H17: =IFERROR(H12/H11,"") | I17: =IFERROR(I12/I11,"")
B19: BALANCE SHEET (WORKING CAPITAL)
F20: FY-2 | G20: FY-1 | H20: FY0 | I20: LTM
B21: Accounts receivable | C21: m
B22: Inventory | C22: m
B23: Accounts payable | C23: m
B24: Other current assets | C24: m
B25: Other current liabilities | C25: m
B26: Net working capital | C26: m
B27: PP&E (net) | C27: m
B29: CASH FLOW (KEY LINES)
F30: FY-2 | G30: FY-1 | H30: FY0 | I30: LTM
B31: D&A | C31: m
B32: Capex | C32: m
B33: Change in NWC | C33: m
B34: Unlevered FCF (proxy) | C34: m

Sheet 04_DRIVERS_AND_FORECAST
B2: 04_DRIVERS_AND_FORECAST
B3: Model
B4: Company
B5: Version
B6: Last updated | F6: =TODAY()
B8: SECTION
B9: CALENDAR
B10: Fiscal year | F10: ='01_CONTROL'!F51 | G10: ='01_CONTROL'!G51 | H10: ='01_CONTROL'!H51 | I10: ='01_CONTROL'!I51 | J10: ='01_CONTROL'!J51 | K10: ='01_CONTROL'!K51 | L10: ='01_CONTROL'!L51 | M10: ='01_CONTROL'!M51 | ... P10: ='01_CONTROL'!P51
B12: BASE CASE FORECAST
B13: Revenue | C13: m | F13: =IF('02_COMPANY_INPUTS'!$F$30="","",'02_COMPANY_INPUTS'!$F$30) | G13: =IF(OR('01_CONTROL'!G52<>1,F13=""),"",F13*(1+'01_CONTROL'!G60)) | H13: =IF(OR('01_CONTROL'!H52<>1,G13=""),"",G13*(1+'01_CONTROL'!H60)) | I13: =IF(OR('01_CONTROL'!I52<>1,H13=""),"",H13*(1+'01_CONTROL'!I60)) | J13: =IF(OR('01_CONTROL'!J52<>1,I13=""),"",I13*(1+'01_CONTROL'!J60)) | K13: =IF(OR('01_CONTROL'!K52<>1,J13=""),"",J13*(1+'01_CONTROL'!K60)) | L13: =IF(OR('01_CONTROL'!L52<>1,K13=""),"",K13*(1+'01_CONTROL'!L60)) | M13: =IF(OR('01_CONTROL'!M52<>1,L13=""),"",L13*(1+'01_CONTROL'!M60)) | N13: =IF(OR('01_CONTROL'!N52<>1,M13=""),"",M13*(1+'01_CONTROL'!N60)) | ... P13: =IF(OR('01_CONTROL'!P52<>1,O13=""),"",O13*(1+'01_CONTROL'!P60))
B14: EBITDA | C14: m | F14: =IF('02_COMPANY_INPUTS'!$F$31="","",'02_COMPANY_INPUTS'!$F$31) | G14: =IF(G13="","",G13*'01_CONTROL'!G61) | H14: =IF(H13="","",H13*'01_CONTROL'!H61) | I14: =IF(I13="","",I13*'01_CONTROL'!I61) | J14: =IF(J13="","",J13*'01_CONTROL'!J61) | K14: =IF(K13="","",K13*'01_CONTROL'!K61) | L14: =IF(L13="","",L13*'01_CONTROL'!L61) | M14: =IF(M13="","",M13*'01_CONTROL'!M61) | N14: =IF(N13="","",N13*'01_CONTROL'!N61) | ... P14: =IF(P13="","",P13*'01_CONTROL'!P61)
B15: D&A | C15: m | F15: =IF('02_COMPANY_INPUTS'!$F$33="","",'02_COMPANY_INPUTS'!$F$33) | G15: =IF(G13="","",G13*'01_CONTROL'!G62) | H15: =IF(H13="","",H13*'01_CONTROL'!H62) | I15: =IF(I13="","",I13*'01_CONTROL'!I62) | J15: =IF(J13="","",J13*'01_CONTROL'!J62) | K15: =IF(K13="","",K13*'01_CONTROL'!K62) | L15: =IF(L13="","",L13*'01_CONTROL'!L62) | M15: =IF(M13="","",M13*'01_CONTROL'!M62) | N15: =IF(N13="","",N13*'01_CONTROL'!N62) | ... P15: =IF(P13="","",P13*'01_CONTROL'!P62)
B16: EBIT | C16: m | F16: =IF(F14="","",F14-F15) | G16: =IF(G14="","",G14-G15) | H16: =IF(H14="","",H14-H15) | I16: =IF(I14="","",I14-I15) | J16: =IF(J14="","",J14-J15) | K16: =IF(K14="","",K14-K15) | L16: =IF(L14="","",L14-L15) | M16: =IF(M14="","",M14-M15) | ... P16: =IF(P14="","",P14-P15)
B17: Taxes on EBIT | C17: m | F17: =IF(F16="","",MAX(0,F16)*'01_CONTROL'!$F$24) | G17: =IF(G16="","",MAX(0,G16)*'01_CONTROL'!$F$24) | H17: =IF(H16="","",MAX(0,H16)*'01_CONTROL'!$F$24) | I17: =IF(I16="","",MAX(0,I16)*'01_CONTROL'!$F$24) | J17: =IF(J16="","",MAX(0,J16)*'01_CONTROL'!$F$24) | K17: =IF(K16="","",MAX(0,K16)*'01_CONTROL'!$F$24) | L17: =IF(L16="","",MAX(0,L16)*'01_CONTROL'!$F$24) | M17: =IF(M16="","",MAX(0,M16)*'01_CONTROL'!$F$24) | ... P17: =IF(P16="","",MAX(0,P16)*'01_CONTROL'!$F$24)
B18: NOPAT | C18: m | F18: =IF(F16="","",F16*(1-'01_CONTROL'!$F$24)) | G18: =IF(G16="","",G16*(1-'01_CONTROL'!$F$24)) | H18: =IF(H16="","",H16*(1-'01_CONTROL'!$F$24)) | I18: =IF(I16="","",I16*(1-'01_CONTROL'!$F$24)) | J18: =IF(J16="","",J16*(1-'01_CONTROL'!$F$24)) | K18: =IF(K16="","",K16*(1-'01_CONTROL'!$F$24)) | L18: =IF(L16="","",L16*(1-'01_CONTROL'!$F$24)) | M18: =IF(M16="","",M16*(1-'01_CONTROL'!$F$24)) | ... P18: =IF(P16="","",P16*(1-'01_CONTROL'!$F$24))
B19: Net working capital | C19: m | F19: =IF('02_COMPANY_INPUTS'!$F$35="","",'02_COMPANY_INPUTS'!$F$35) | G19: =IF(G13="","",G13*'01_CONTROL'!G64) | H19: =IF(H13="","",H13*'01_CONTROL'!H64) | I19: =IF(I13="","",I13*'01_CONTROL'!I64) | J19: =IF(J13="","",J13*'01_CONTROL'!J64) | K19: =IF(K13="","",K13*'01_CONTROL'!K64) | L19: =IF(L13="","",L13*'01_CONTROL'!L64) | M19: =IF(M13="","",M13*'01_CONTROL'!M64) | N19: =IF(N13="","",N13*'01_CONTROL'!N64) | ... P19: =IF(P13="","",P13*'01_CONTROL'!P64)
B20: Change in NWC | C20: m | F20: ="" | G20: =IF(G19="","",G19-F19) | H20: =IF(H19="","",H19-G19) | I20: =IF(I19="","",I19-H19) | J20: =IF(J19="","",J19-I19) | K20: =IF(K19="","",K19-J19) | L20: =IF(L19="","",L19-K19) | M20: =IF(M19="","",M19-L19) | N20: =IF(N19="","",N19-M19) | ... P20: =IF(P19="","",P19-O19)
B21: Capex | C21: m | F21: =IF('02_COMPANY_INPUTS'!$F$34="","",'02_COMPANY_INPUTS'!$F$34) | G21: =IF(G13="","",G13*'01_CONTROL'!G63) | H21: =IF(H13="","",H13*'01_CONTROL'!H63) | I21: =IF(I13="","",I13*'01_CONTROL'!I63) | J21: =IF(J13="","",J13*'01_CONTROL'!J63) | K21: =IF(K13="","",K13*'01_CONTROL'!K63) | L21: =IF(L13="","",L13*'01_CONTROL'!L63) | M21: =IF(M13="","",M13*'01_CONTROL'!M63) | N21: =IF(N13="","",N13*'01_CONTROL'!N63) | ... P21: =IF(P13="","",P13*'01_CONTROL'!P63)
B22: Unlevered FCF | C22: m | F22: =IF(F18="","",F18+F15-F21-F20) | G22: =IF(G18="","",G18+G15-G21-G20) | H22: =IF(H18="","",H18+H15-H21-H20) | I22: =IF(I18="","",I18+I15-I21-I20) | J22: =IF(J18="","",J18+J15-J21-J20) | K22: =IF(K18="","",K18+K15-K21-K20) | L22: =IF(L18="","",L18+L15-L21-L20) | M22: =IF(M18="","",M18+M15-M21-M20) | ... P22: =IF(P18="","",P18+P15-P21-P20)
B25: UPSIDE FORECAST
B26: Revenue | C26: m | F26: =IF('02_COMPANY_INPUTS'!$F$30="","",'02_COMPANY_INPUTS'!$F$30) | G26: =IF(OR('01_CONTROL'!G52<>1,F26=""),"",F26*(1+'01_CONTROL'!S60)) | H26: =IF(OR('01_CONTROL'!H52<>1,G26=""),"",G26*(1+'01_CONTROL'!T60)) | I26: =IF(OR('01_CONTROL'!I52<>1,H26=""),"",H26*(1+'01_CONTROL'!U60)) | J26: =IF(OR('01_CONTROL'!J52<>1,I26=""),"",I26*(1+'01_CONTROL'!V60)) | K26: =IF(OR('01_CONTROL'!K52<>1,J26=""),"",J26*(1+'01_CONTROL'!W60)) | L26: =IF(OR('01_CONTROL'!L52<>1,K26=""),"",K26*(1+'01_CONTROL'!X60)) | M26: =IF(OR('01_CONTROL'!M52<>1,L26=""),"",L26*(1+'01_CONTROL'!Y60)) | N26: =IF(OR('01_CONTROL'!N52<>1,M26=""),"",M26*(1+'01_CONTROL'!Z60)) | ... P26: =IF(OR('01_CONTROL'!P52<>1,O26=""),"",O26*(1+'01_CONTROL'!AB60))
B27: EBITDA | C27: m | F27: =IF('02_COMPANY_INPUTS'!$F$31="","",'02_COMPANY_INPUTS'!$F$31) | G27: =IF(G26="","",G26*'01_CONTROL'!S61) | H27: =IF(H26="","",H26*'01_CONTROL'!T61) | I27: =IF(I26="","",I26*'01_CONTROL'!U61) | J27: =IF(J26="","",J26*'01_CONTROL'!V61) | K27: =IF(K26="","",K26*'01_CONTROL'!W61) | L27: =IF(L26="","",L26*'01_CONTROL'!X61) | M27: =IF(M26="","",M26*'01_CONTROL'!Y61) | N27: =IF(N26="","",N26*'01_CONTROL'!Z61) | ... P27: =IF(P26="","",P26*'01_CONTROL'!AB61)
B28: D&A | C28: m | F28: =IF('02_COMPANY_INPUTS'!$F$33="","",'02_COMPANY_INPUTS'!$F$33) | G28: =IF(G26="","",G26*'01_CONTROL'!S62) | H28: =IF(H26="","",H26*'01_CONTROL'!T62) | I28: =IF(I26="","",I26*'01_CONTROL'!U62) | J28: =IF(J26="","",J26*'01_CONTROL'!V62) | K28: =IF(K26="","",K26*'01_CONTROL'!W62) | L28: =IF(L26="","",L26*'01_CONTROL'!X62) | M28: =IF(M26="","",M26*'01_CONTROL'!Y62) | N28: =IF(N26="","",N26*'01_CONTROL'!Z62) | ... P28: =IF(P26="","",P26*'01_CONTROL'!AB62)
B29: EBIT | C29: m | F29: =IF(F27="","",F27-F28) | G29: =IF(G27="","",G27-G28) | H29: =IF(H27="","",H27-H28) | I29: =IF(I27="","",I27-I28) | J29: =IF(J27="","",J27-J28) | K29: =IF(K27="","",K27-K28) | L29: =IF(L27="","",L27-L28) | M29: =IF(M27="","",M27-M28) | ... P29: =IF(P27="","",P27-P28)
B30: Taxes on EBIT | C30: m | F30: =IF(F29="","",MAX(0,F29)*'01_CONTROL'!$F$24) | G30: =IF(G29="","",MAX(0,G29)*'01_CONTROL'!$F$24) | H30: =IF(H29="","",MAX(0,H29)*'01_CONTROL'!$F$24) | I30: =IF(I29="","",MAX(0,I29)*'01_CONTROL'!$F$24) | J30: =IF(J29="","",MAX(0,J29)*'01_CONTROL'!$F$24) | K30: =IF(K29="","",MAX(0,K29)*'01_CONTROL'!$F$24) | L30: =IF(L29="","",MAX(0,L29)*'01_CONTROL'!$F$24) | M30: =IF(M29="","",MAX(0,M29)*'01_CONTROL'!$F$24) | ... P30: =IF(P29="","",MAX(0,P29)*'01_CONTROL'!$F$24)
B31: NOPAT | C31: m | F31: =IF(F29="","",F29*(1-'01_CONTROL'!$F$24)) | G31: =IF(G29="","",G29*(1-'01_CONTROL'!$F$24)) | H31: =IF(H29="","",H29*(1-'01_CONTROL'!$F$24)) | I31: =IF(I29="","",I29*(1-'01_CONTROL'!$F$24)) | J31: =IF(J29="","",J29*(1-'01_CONTROL'!$F$24)) | K31: =IF(K29="","",K29*(1-'01_CONTROL'!$F$24)) | L31: =IF(L29="","",L29*(1-'01_CONTROL'!$F$24)) | M31: =IF(M29="","",M29*(1-'01_CONTROL'!$F$24)) | ... P31: =IF(P29="","",P29*(1-'01_CONTROL'!$F$24))
B32: Net working capital | C32: m | F32: =IF('02_COMPANY_INPUTS'!$F$35="","",'02_COMPANY_INPUTS'!$F$35) | G32: =IF(G26="","",G26*'01_CONTROL'!S64) | H32: =IF(H26="","",H26*'01_CONTROL'!T64) | I32: =IF(I26="","",I26*'01_CONTROL'!U64) | J32: =IF(J26="","",J26*'01_CONTROL'!V64) | K32: =IF(K26="","",K26*'01_CONTROL'!W64) | L32: =IF(L26="","",L26*'01_CONTROL'!X64) | M32: =IF(M26="","",M26*'01_CONTROL'!Y64) | N32: =IF(N26="","",N26*'01_CONTROL'!Z64) | ... P32: =IF(P26="","",P26*'01_CONTROL'!AB64)
B33: Change in NWC | C33: m | F33: ="" | G33: =IF(G32="","",G32-F32) | H33: =IF(H32="","",H32-G32) | I33: =IF(I32="","",I32-H32) | J33: =IF(J32="","",J32-I32) | K33: =IF(K32="","",K32-J32) | L33: =IF(L32="","",L32-K32) | M33: =IF(M32="","",M32-L32) | N33: =IF(N32="","",N32-M32) | ... P33: =IF(P32="","",P32-O32)
B34: Capex | C34: m | F34: =IF('02_COMPANY_INPUTS'!$F$34="","",'02_COMPANY_INPUTS'!$F$34) | G34: =IF(G26="","",G26*'01_CONTROL'!S63) | H34: =IF(H26="","",H26*'01_CONTROL'!T63) | I34: =IF(I26="","",I26*'01_CONTROL'!U63) | J34: =IF(J26="","",J26*'01_CONTROL'!V63) | K34: =IF(K26="","",K26*'01_CONTROL'!W63) | L34: =IF(L26="","",L26*'01_CONTROL'!X63) | M34: =IF(M26="","",M26*'01_CONTROL'!Y63) | N34: =IF(N26="","",N26*'01_CONTROL'!Z63) | ... P34: =IF(P26="","",P26*'01_CONTROL'!AB63)
B35: Unlevered FCF | C35: m | F35: =IF(F31="","",F31+F28-F34-F33) | G35: =IF(G31="","",G31+G28-G34-G33) | H35: =IF(H31="","",H31+H28-H34-H33) | I35: =IF(I31="","",I31+I28-I34-I33) | J35: =IF(J31="","",J31+J28-J34-J33) | K35: =IF(K31="","",K31+K28-K34-K33) | L35: =IF(L31="","",L31+L28-L34-L33) | M35: =IF(M31="","",M31+M28-M34-M33) | ... P35: =IF(P31="","",P31+P28-P34-P33)
B38: DOWNSIDE FORECAST
B39: Revenue | C39: m | F39: =IF('02_COMPANY_INPUTS'!$F$30="","",'02_COMPANY_INPUTS'!$F$30) | G39: =IF(OR('01_CONTROL'!G52<>1,F39=""),"",F39*(1+'01_CONTROL'!AE60)) | H39: =IF(OR('01_CONTROL'!H52<>1,G39=""),"",G39*(1+'01_CONTROL'!AF60)) | I39: =IF(OR('01_CONTROL'!I52<>1,H39=""),"",H39*(1+'01_CONTROL'!AG60)) | J39: =IF(OR('01_CONTROL'!J52<>1,I39=""),"",I39*(1+'01_CONTROL'!AH60)) | K39: =IF(OR('01_CONTROL'!K52<>1,J39=""),"",J39*(1+'01_CONTROL'!AI60)) | L39: =IF(OR('01_CONTROL'!L52<>1,K39=""),"",K39*(1+'01_CONTROL'!AJ60)) | M39: =IF(OR('01_CONTROL'!M52<>1,L39=""),"",L39*(1+'01_CONTROL'!AK60)) | N39: =IF(OR('01_CONTROL'!N52<>1,M39=""),"",M39*(1+'01_CONTROL'!AL60)) | ... P39: =IF(OR('01_CONTROL'!P52<>1,O39=""),"",O39*(1+'01_CONTROL'!AN60))
B40: EBITDA | C40: m | F40: =IF('02_COMPANY_INPUTS'!$F$31="","",'02_COMPANY_INPUTS'!$F$31) | G40: =IF(G39="","",G39*'01_CONTROL'!AE61) | H40: =IF(H39="","",H39*'01_CONTROL'!AF61) | I40: =IF(I39="","",I39*'01_CONTROL'!AG61) | J40: =IF(J39="","",J39*'01_CONTROL'!AH61) | K40: =IF(K39="","",K39*'01_CONTROL'!AI61) | L40: =IF(L39="","",L39*'01_CONTROL'!AJ61) | M40: =IF(M39="","",M39*'01_CONTROL'!AK61) | N40: =IF(N39="","",N39*'01_CONTROL'!AL61) | ... P40: =IF(P39="","",P39*'01_CONTROL'!AN61)
B41: D&A | C41: m | F41: =IF('02_COMPANY_INPUTS'!$F$33="","",'02_COMPANY_INPUTS'!$F$33) | G41: =IF(G39="","",G39*'01_CONTROL'!AE62) | H41: =IF(H39="","",H39*'01_CONTROL'!AF62) | I41: =IF(I39="","",I39*'01_CONTROL'!AG62) | J41: =IF(J39="","",J39*'01_CONTROL'!AH62) | K41: =IF(K39="","",K39*'01_CONTROL'!AI62) | L41: =IF(L39="","",L39*'01_CONTROL'!AJ62) | M41: =IF(M39="","",M39*'01_CONTROL'!AK62) | N41: =IF(N39="","",N39*'01_CONTROL'!AL62) | ... P41: =IF(P39="","",P39*'01_CONTROL'!AN62)
B42: EBIT | C42: m | F42: =IF(F40="","",F40-F41) | G42: =IF(G40="","",G40-G41) | H42: =IF(H40="","",H40-H41) | I42: =IF(I40="","",I40-I41) | J42: =IF(J40="","",J40-J41) | K42: =IF(K40="","",K40-K41) | L42: =IF(L40="","",L40-L41) | M42: =IF(M40="","",M40-M41) | ... P42: =IF(P40="","",P40-P41)
B43: Taxes on EBIT | C43: m | F43: =IF(F42="","",MAX(0,F42)*'01_CONTROL'!$F$24) | G43: =IF(G42="","",MAX(0,G42)*'01_CONTROL'!$F$24) | H43: =IF(H42="","",MAX(0,H42)*'01_CONTROL'!$F$24) | I43: =IF(I42="","",MAX(0,I42)*'01_CONTROL'!$F$24) | J43: =IF(J42="","",MAX(0,J42)*'01_CONTROL'!$F$24) | K43: =IF(K42="","",MAX(0,K42)*'01_CONTROL'!$F$24) | L43: =IF(L42="","",MAX(0,L42)*'01_CONTROL'!$F$24) | M43: =IF(M42="","",MAX(0,M42)*'01_CONTROL'!$F$24) | ... P43: =IF(P42="","",MAX(0,P42)*'01_CONTROL'!$F$24)
B44: NOPAT | C44: m | F44: =IF(F42="","",F42*(1-'01_CONTROL'!$F$24)) | G44: =IF(G42="","",G42*(1-'01_CONTROL'!$F$24)) | H44: =IF(H42="","",H42*(1-'01_CONTROL'!$F$24)) | I44: =IF(I42="","",I42*(1-'01_CONTROL'!$F$24)) | J44: =IF(J42="","",J42*(1-'01_CONTROL'!$F$24)) | K44: =IF(K42="","",K42*(1-'01_CONTROL'!$F$24)) | L44: =IF(L42="","",L42*(1-'01_CONTROL'!$F$24)) | M44: =IF(M42="","",M42*(1-'01_CONTROL'!$F$24)) | ... P44: =IF(P42="","",P42*(1-'01_CONTROL'!$F$24))
B45: Net working capital | C45: m | F45: =IF('02_COMPANY_INPUTS'!$F$35="","",'02_COMPANY_INPUTS'!$F$35) | G45: =IF(G39="","",G39*'01_CONTROL'!AE64) | H45: =IF(H39="","",H39*'01_CONTROL'!AF64) | I45: =IF(I39="","",I39*'01_CONTROL'!AG64) | J45: =IF(J39="","",J39*'01_CONTROL'!AH64) | K45: =IF(K39="","",K39*'01_CONTROL'!AI64) | L45: =IF(L39="","",L39*'01_CONTROL'!AJ64) | M45: =IF(M39="","",M39*'01_CONTROL'!AK64) | N45: =IF(N39="","",N39*'01_CONTROL'!AL64) | ... P45: =IF(P39="","",P39*'01_CONTROL'!AN64)
B46: Change in NWC | C46: m | F46: ="" | G46: =IF(G45="","",G45-F45) | H46: =IF(H45="","",H45-G45) | I46: =IF(I45="","",I45-H45) | J46: =IF(J45="","",J45-I45) | K46: =IF(K45="","",K45-J45) | L46: =IF(L45="","",L45-K45) | M46: =IF(M45="","",M45-L45) | N46: =IF(N45="","",N45-M45) | ... P46: =IF(P45="","",P45-O45)
B47: Capex | C47: m | F47: =IF('02_COMPANY_INPUTS'!$F$34="","",'02_COMPANY_INPUTS'!$F$34) | G47: =IF(G39="","",G39*'01_CONTROL'!AE63) | H47: =IF(H39="","",H39*'01_CONTROL'!AF63) | I47: =IF(I39="","",I39*'01_CONTROL'!AG63) | J47: =IF(J39="","",J39*'01_CONTROL'!AH63) | K47: =IF(K39="","",K39*'01_CONTROL'!AI63) | L47: =IF(L39="","",L39*'01_CONTROL'!AJ63) | M47: =IF(M39="","",M39*'01_CONTROL'!AK63) | N47: =IF(N39="","",N39*'01_CONTROL'!AL63) | ... P47: =IF(P39="","",P39*'01_CONTROL'!AN63)
...

Sheet 05_TRADING_COMPS
B2: 05_TRADING_COMPS
B3: Model
B4: Company
B5: Version
B6: Last updated | F6: =TODAY()
B8: SECTION
B9: PEER SET AND MARKET DATA (USER INPUT)
B11: Company | C11: Ticker | D11: CCY | E11: Share price | F11: Shares (mm) | G11: Market cap | H11: Net debt | I11: EV | J11: LTM Rev | K11: LTM EBITDA | L11: LTM EBIT | M11: P/E (optional) | N11: EV/Rev | O11: EV/EBITDA | P11: EV/EBIT
G12: =IFERROR(E12*F12,"") | I12: =IFERROR(G12+H12,"") | N12: =IFERROR(I12/J12,"") | O12: =IFERROR(I12/K12,"") | P12: =IFERROR(I12/L12,"")
G13: =IFERROR(E13*F13,"") | I13: =IFERROR(G13+H13,"") | N13: =IFERROR(I13/J13,"") | O13: =IFERROR(I13/K13,"") | P13: =IFERROR(I13/L13,"")
G14: =IFERROR(E14*F14,"") | I14: =IFERROR(G14+H14,"") | N14: =IFERROR(I14/J14,"") | O14: =IFERROR(I14/K14,"") | P14: =IFERROR(I14/L14,"")
G15: =IFERROR(E15*F15,"") | I15: =IFERROR(G15+H15,"") | N15: =IFERROR(I15/J15,"") | O15: =IFERROR(I15/K15,"") | P15: =IFERROR(I15/L15,"")
G16: =IFERROR(E16*F16,"") | I16: =IFERROR(G16+H16,"") | N16: =IFERROR(I16/J16,"") | O16: =IFERROR(I16/K16,"") | P16: =IFERROR(I16/L16,"")
G17: =IFERROR(E17*F17,"") | I17: =IFERROR(G17+H17,"") | N17: =IFERROR(I17/J17,"") | O17: =IFERROR(I17/K17,"") | P17: =IFERROR(I17/L17,"")
G18: =IFERROR(E18*F18,"") | I18: =IFERROR(G18+H18,"") | N18: =IFERROR(I18/J18,"") | O18: =IFERROR(I18/K18,"") | P18: =IFERROR(I18/L18,"")
G19: =IFERROR(E19*F19,"") | I19: =IFERROR(G19+H19,"") | N19: =IFERROR(I19/J19,"") | O19: =IFERROR(I19/K19,"") | P19: =IFERROR(I19/L19,"")
G20: =IFERROR(E20*F20,"") | I20: =IFERROR(G20+H20,"") | N20: =IFERROR(I20/J20,"") | O20: =IFERROR(I20/K20,"") | P20: =IFERROR(I20/L20,"")
G21: =IFERROR(E21*F21,"") | I21: =IFERROR(G21+H21,"") | N21: =IFERROR(I21/J21,"") | O21: =IFERROR(I21/K21,"") | P21: =IFERROR(I21/L21,"")
G22: =IFERROR(E22*F22,"") | I22: =IFERROR(G22+H22,"") | N22: =IFERROR(I22/J22,"") | O22: =IFERROR(I22/K22,"") | P22: =IFERROR(I22/L22,"")
G23: =IFERROR(E23*F23,"") | I23: =IFERROR(G23+H23,"") | N23: =IFERROR(I23/J23,"") | O23: =IFERROR(I23/K23,"") | P23: =IFERROR(I23/L23,"")
B26: SUMMARY STATISTICS (COMPUTED)
B27: EV/Rev | C27: x | D27: P25 | E27: Median | F27: =IFERROR(QUARTILE.INC(N12:N23,1),"") | G27: =IFERROR(MEDIAN(N12:N23),"") | H27: =IFERROR(QUARTILE.INC(N12:N23,3),"")
B28: EV/EBITDA | C28: x | D28: P25 | E28: Median | F28: =IFERROR(QUARTILE.INC(O12:O23,1),"") | G28: =IFERROR(MEDIAN(O12:O23),"") | H28: =IFERROR(QUARTILE.INC(O12:O23,3),"")
B29: EV/EBIT | C29: x | D29: P25 | E29: Median | F29: =IFERROR(QUARTILE.INC(P12:P23,1),"") | G29: =IFERROR(MEDIAN(P12:P23),"") | H29: =IFERROR(QUARTILE.INC(P12:P23,3),"")
B31: SELECTED MULTIPLE(S) (BASE CASE)
B32: Selected EV/EBITDA multiple | C32: x | F32: =IF('01_CONTROL'!$F$84,'01_CONTROL'!$F$85,$G$28)
B34: IMPLIED VALUATION (COMPANY)
B35: Company LTM EBITDA | C35: m | F35: ='02_COMPANY_INPUTS'!$F$31
B36: Implied enterprise value | C36: m | F36: =IF($F$35="","",IFERROR($F$32*$F$35,""))
B37: Net debt (per toggles) | C37: m | F37: ='02_COMPANY_INPUTS'!$F$26
B38: Implied equity value | C38: m | F38: =IF($F$36="","",IFERROR($F$36-$F$37,""))
B39: Shares outstanding (mm) | C39: mm | F39: ='02_COMPANY_INPUTS'!$F$11
B40: Implied price per share | C40: CCY | F40: =IF(OR($F$38="",$F$39="", $F$39=0),"",IFERROR($F$38/$F$39,""))
B42: COMPS IMPLIED RANGE (EV/EBITDA)
B43: Equity value P25 | C43: m | F43: =IF('02_COMPANY_INPUTS'!$F$31="","",IFERROR(F28*'02_COMPANY_INPUTS'!$F$31-'02_COMPANY_INPUTS'!$F$26,""))
B44: Equity value Median | C44: m | F44: =IF('02_COMPANY_INPUTS'!$F$31="","",IFERROR(G28*'02_COMPANY_INPUTS'!$F$31-'02_COMPANY_INPUTS'!$F$26,""))
B45: Equity value P75 | C45: m | F45: =IF('02_COMPANY_INPUTS'!$F$31="","",IFERROR(H28*'02_COMPANY_INPUTS'!$F$31-'02_COMPANY_INPUTS'!$F$26,""))

Sheet 06_DCF_WACC
B2: 06_DCF_WACC
B3: Model
B4: Company
B5: Version
B6: Last updated | F6: =TODAY()
B8: SECTION
B9: INPUTS (FROM 01_CONTROL)
B10: Tax rate | F10: ='01_CONTROL'!$F$24
B11: Risk-free rate | F11: ='01_CONTROL'!$F$25
B12: Equity risk premium | F12: ='01_CONTROL'!$F$26
B13: Beta | F13: ='01_CONTROL'!$F$27
B14: Size / country adj | F14: ='01_CONTROL'!$F$28
B15: Pre-tax cost of debt | F15: ='01_CONTROL'!$F$29
B16: Debt weight | F16: ='01_CONTROL'!$F$30
B17: Equity weight | F17: ='01_CONTROL'!$F$31
B19: WACC COMPUTATION
B20: WACC used (output) | C20: % | E20: WACC (output) | F20: ='01_CONTROL'!$F$36
B21: Cost of equity | C21: % | F21: ='01_CONTROL'!$F$34
B22: After-tax cost of debt | C22: % | F22: ='01_CONTROL'!$F$35
B24: SANITY CHECKS
B25: WACC min | C25: % | F25: 0.06
B26: WACC max | C26: % | F26: 0.12
B27: WACC within range | F27: =IF(AND($F$20>=$F$25,$F$20<=$F$26),1,0)

Sheet 07_DCF_FCF_AND_VALUATION
B2: 07_DCF_FCF_AND_VALUATION
B3: Model
B4: Company
B5: Version
B6: Last updated | F6: =TODAY()
B8: SECTION
B9: CALENDAR AND DISCOUNTING
B10: Fiscal year | F10: ='01_CONTROL'!F51 | G10: ='01_CONTROL'!G51 | H10: ='01_CONTROL'!H51 | I10: ='01_CONTROL'!I51 | J10: ='01_CONTROL'!J51 | K10: ='01_CONTROL'!K51 | L10: ='01_CONTROL'!L51 | M10: ='01_CONTROL'!M51 | ... P10: ='01_CONTROL'!P51
B11: t | F11: ='01_CONTROL'!F53 | G11: ='01_CONTROL'!G53 | H11: ='01_CONTROL'!H53 | I11: ='01_CONTROL'!I53 | J11: ='01_CONTROL'!J53 | K11: ='01_CONTROL'!K53 | L11: ='01_CONTROL'!L53 | M11: ='01_CONTROL'!M53 | ... P11: ='01_CONTROL'!P53
B12: Discount factor | G12: =IF('01_CONTROL'!G52=1,1/(1+'06_DCF_WACC'!$F$20)^('01_CONTROL'!G53-IF('01_CONTROL'!$F$17=1,0.5,0)),"") | H12: =IF('01_CONTROL'!H52=1,1/(1+'06_DCF_WACC'!$F$20)^('01_CONTROL'!H53-IF('01_CONTROL'!$F$17=1,0.5,0)),"") | I12: =IF('01_CONTROL'!I52=1,1/(1+'06_DCF_WACC'!$F$20)^('01_CONTROL'!I53-IF('01_CONTROL'!$F$17=1,0.5,0)),"") | J12: =IF('01_CONTROL'!J52=1,1/(1+'06_DCF_WACC'!$F$20)^('01_CONTROL'!J53-IF('01_CONTROL'!$F$17=1,0.5,0)),"") | K12: =IF('01_CONTROL'!K52=1,1/(1+'06_DCF_WACC'!$F$20)^('01_CONTROL'!K53-IF('01_CONTROL'!$F$17=1,0.5,0)),"") | L12: =IF('01_CONTROL'!L52=1,1/(1+'06_DCF_WACC'!$F$20)^('01_CONTROL'!L53-IF('01_CONTROL'!$F$17=1,0.5,0)),"") | M12: =IF('01_CONTROL'!M52=1,1/(1+'06_DCF_WACC'!$F$20)^('01_CONTROL'!M53-IF('01_CONTROL'!$F$17=1,0.5,0)),"") | N12: =IF('01_CONTROL'!N52=1,1/(1+'06_DCF_WACC'!$F$20)^('01_CONTROL'!N53-IF('01_CONTROL'!$F$17=1,0.5,0)),"") | ... P12: =IF('01_CONTROL'!P52=1,1/(1+'06_DCF_WACC'!$F$20)^('01_CONTROL'!P53-IF('01_CONTROL'!$F$17=1,0.5,0)),"")
B14: DCF DOWNSIDE
B15: EBITDA | C15: m | F15: ='04_DRIVERS_AND_FORECAST'!F40 | G15: ='04_DRIVERS_AND_FORECAST'!G40 | H15: ='04_DRIVERS_AND_FORECAST'!H40 | I15: ='04_DRIVERS_AND_FORECAST'!I40 | J15: ='04_DRIVERS_AND_FORECAST'!J40 | K15: ='04_DRIVERS_AND_FORECAST'!K40 | L15: ='04_DRIVERS_AND_FORECAST'!L40 | M15: ='04_DRIVERS_AND_FORECAST'!M40 | ... P15: ='04_DRIVERS_AND_FORECAST'!P40
B16: Unlevered FCF | C16: m | F16: ='04_DRIVERS_AND_FORECAST'!F48 | G16: ='04_DRIVERS_AND_FORECAST'!G48 | H16: ='04_DRIVERS_AND_FORECAST'!H48 | I16: ='04_DRIVERS_AND_FORECAST'!I48 | J16: ='04_DRIVERS_AND_FORECAST'!J48 | K16: ='04_DRIVERS_AND_FORECAST'!K48 | L16: ='04_DRIVERS_AND_FORECAST'!L48 | M16: ='04_DRIVERS_AND_FORECAST'!M48 | ... P16: ='04_DRIVERS_AND_FORECAST'!P48
B17: PV of FCF | C17: m | G17: =IF('01_CONTROL'!G52=1,IF(G16="","",G16*G12),"") | H17: =IF('01_CONTROL'!H52=1,IF(H16="","",H16*H12),"") | I17: =IF('01_CONTROL'!I52=1,IF(I16="","",I16*I12),"") | J17: =IF('01_CONTROL'!J52=1,IF(J16="","",J16*J12),"") | K17: =IF('01_CONTROL'!K52=1,IF(K16="","",K16*K12),"") | L17: =IF('01_CONTROL'!L52=1,IF(L16="","",L16*L12),"") | M17: =IF('01_CONTROL'!M52=1,IF(M16="","",M16*M12),"") | N17: =IF('01_CONTROL'!N52=1,IF(N16="","",N16*N12),"") | ... P17: =IF('01_CONTROL'!P52=1,IF(P16="","",P16*P12),"")
B19: PV of FCFs (sum) | C19: m | F19: =IF(OR('01_CONTROL'!$F$13<>1,'02_COMPANY_INPUTS'!$F$30=""),"",SUMPRODUCT(G17:P17,'01_CONTROL'!$G$52:$P$52))
B20: Terminal value | C20: m | F20: =IF('01_CONTROL'!$F$13=1,IF('01_CONTROL'!$F$15=1,IFERROR(INDEX($G$16:$P$16,'01_CONTROL'!$F$11)*(1+'01_CONTROL'!$AD$67)/('06_DCF_WACC'!$F$20-'01_CONTROL'!$AD$67),""),IFERROR(INDEX($G$15:$P$15,'01_CONTROL'!$F$11)*'01_CONTROL'!$AD$68,"")),"")
B21: PV of TV | C21: m | F21: =IF($F20="","",IFERROR($F20*INDEX($G$12:$P$12,'01_CONTROL'!$F$11),""))
B22: Enterprise value (DCF) | C22: m | F22: =IF($F19="","",IFERROR($F19+$F21,""))
B23: Equity value (DCF) | C23: m | F23: =IF($F22="","",IFERROR($F22-'02_COMPANY_INPUTS'!$F$26,""))
B24: Implied price per share (DCF) | C24: CCY | F24: =IF($F23="","",IFERROR($F23/'02_COMPANY_INPUTS'!$F$11,""))
B25: TV as % of EV | C25: % | F25: =IF($F22="","",IFERROR($F21/$F22,""))
B28: DCF BASE
B29: EBITDA | C29: m | F29: ='04_DRIVERS_AND_FORECAST'!F14 | G29: ='04_DRIVERS_AND_FORECAST'!G14 | H29: ='04_DRIVERS_AND_FORECAST'!H14 | I29: ='04_DRIVERS_AND_FORECAST'!I14 | J29: ='04_DRIVERS_AND_FORECAST'!J14 | K29: ='04_DRIVERS_AND_FORECAST'!K14 | L29: ='04_DRIVERS_AND_FORECAST'!L14 | M29: ='04_DRIVERS_AND_FORECAST'!M14 | ... P29: ='04_DRIVERS_AND_FORECAST'!P14
B30: Unlevered FCF | C30: m | F30: ='04_DRIVERS_AND_FORECAST'!F22 | G30: ='04_DRIVERS_AND_FORECAST'!G22 | H30: ='04_DRIVERS_AND_FORECAST'!H22 | I30: ='04_DRIVERS_AND_FORECAST'!I22 | J30: ='04_DRIVERS_AND_FORECAST'!J22 | K30: ='04_DRIVERS_AND_FORECAST'!K22 | L30: ='04_DRIVERS_AND_FORECAST'!L22 | M30: ='04_DRIVERS_AND_FORECAST'!M22 | ... P30: ='04_DRIVERS_AND_FORECAST'!P22
B31: PV of FCF | C31: m | G31: =IF('01_CONTROL'!G52=1,IF(G30="","",G30*G12),"") | H31: =IF('01_CONTROL'!H52=1,IF(H30="","",H30*H12),"") | I31: =IF('01_CONTROL'!I52=1,IF(I30="","",I30*I12),"") | J31: =IF('01_CONTROL'!J52=1,IF(J30="","",J30*J12),"") | K31: =IF('01_CONTROL'!K52=1,IF(K30="","",K30*K12),"") | L31: =IF('01_CONTROL'!L52=1,IF(L30="","",L30*L12),"") | M31: =IF('01_CONTROL'!M52=1,IF(M30="","",M30*M12),"") | N31: =IF('01_CONTROL'!N52=1,IF(N30="","",N30*N12),"") | ... P31: =IF('01_CONTROL'!P52=1,IF(P30="","",P30*P12),"")
B33: PV of FCFs (sum) | C33: m | F33: =IF(OR('01_CONTROL'!$F$13<>1,'02_COMPANY_INPUTS'!$F$30=""),"",SUMPRODUCT(G31:P31,'01_CONTROL'!$G$52:$P$52))
B34: Terminal value | C34: m | F34: =IF('01_CONTROL'!$F$13=1,IF('01_CONTROL'!$F$15=1,IFERROR(INDEX($G$30:$P$30,'01_CONTROL'!$F$11)*(1+'01_CONTROL'!$F$67)/('06_DCF_WACC'!$F$20-'01_CONTROL'!$F$67),""),IFERROR(INDEX($G$29:$P$29,'01_CONTROL'!$F$11)*'01_CONTROL'!$F$68,"")),"")
B35: PV of TV | C35: m | F35: =IF($F34="","",IFERROR($F34*INDEX($G$12:$P$12,'01_CONTROL'!$F$11),""))
B36: Enterprise value (DCF) | C36: m | F36: =IF($F33="","",IFERROR($F33+$F35,""))
B37: Equity value (DCF) | C37: m | F37: =IF($F36="","",IFERROR($F36-'02_COMPANY_INPUTS'!$F$26,""))
B38: Implied price per share (DCF) | C38: CCY | F38: =IF($F37="","",IFERROR($F37/'02_COMPANY_INPUTS'!$F$11,""))
B39: TV as % of EV | C39: % | F39: =IF($F36="","",IFERROR($F35/$F36,""))
B42: DCF UPSIDE
B43: EBITDA | C43: m | F43: ='04_DRIVERS_AND_FORECAST'!F27 | G43: ='04_DRIVERS_AND_FORECAST'!G27 | H43: ='04_DRIVERS_AND_FORECAST'!H27 | I43: ='04_DRIVERS_AND_FORECAST'!I27 | J43: ='04_DRIVERS_AND_FORECAST'!J27 | K43: ='04_DRIVERS_AND_FORECAST'!K27 | L43: ='04_DRIVERS_AND_FORECAST'!L27 | M43: ='04_DRIVERS_AND_FORECAST'!M27 | ... P43: ='04_DRIVERS_AND_FORECAST'!P27
B44: Unlevered FCF | C44: m | F44: ='04_DRIVERS_AND_FORECAST'!F35 | G44: ='04_DRIVERS_AND_FORECAST'!G35 | H44: ='04_DRIVERS_AND_FORECAST'!H35 | I44: ='04_DRIVERS_AND_FORECAST'!I35 | J44: ='04_DRIVERS_AND_FORECAST'!J35 | K44: ='04_DRIVERS_AND_FORECAST'!K35 | L44: ='04_DRIVERS_AND_FORECAST'!L35 | M44: ='04_DRIVERS_AND_FORECAST'!M35 | ... P44: ='04_DRIVERS_AND_FORECAST'!P35
B45: PV of FCF | C45: m | G45: =IF('01_CONTROL'!G52=1,IF(G44="","",G44*G12),"") | H45: =IF('01_CONTROL'!H52=1,IF(H44="","",H44*H12),"") | I45: =IF('01_CONTROL'!I52=1,IF(I44="","",I44*I12),"") | J45: =IF('01_CONTROL'!J52=1,IF(J44="","",J44*J12),"") | K45: =IF('01_CONTROL'!K52=1,IF(K44="","",K44*K12),"") | L45: =IF('01_CONTROL'!L52=1,IF(L44="","",L44*L12),"") | M45: =IF('01_CONTROL'!M52=1,IF(M44="","",M44*M12),"") | N45: =IF('01_CONTROL'!N52=1,IF(N44="","",N44*N12),"") | ... P45: =IF('01_CONTROL'!P52=1,IF(P44="","",P44*P12),"")
B47: PV of FCFs (sum) | C47: m | F47: =IF(OR('01_CONTROL'!$F$13<>1,'02_COMPANY_INPUTS'!$F$30=""),"",SUMPRODUCT(G45:P45,'01_CONTROL'!$G$52:$P$52))
B48: Terminal value | C48: m | F48: =IF('01_CONTROL'!$F$13=1,IF('01_CONTROL'!$F$15=1,IFERROR(INDEX($G$44:$P$44,'01_CONTROL'!$F$11)*(1+'01_CONTROL'!$R$67)/('06_DCF_WACC'!$F$20-'01_CONTROL'!$R$67),""),IFERROR(INDEX($G$43:$P$43,'01_CONTROL'!$F$11)*'01_CONTROL'!$R$68,"")),"")
B49: PV of TV | C49: m | F49: =IF($F48="","",IFERROR($F48*INDEX($G$12:$P$12,'01_CONTROL'!$F$11),""))
B50: Enterprise value (DCF) | C50: m | F50: =IF($F47="","",IFERROR($F47+$F49,""))
...

Sheet 08_TRIANGULATION_RANGE
B2: 08_TRIANGULATION_RANGE
B3: Model
B4: Company
B5: Version
B6: Last updated | F6: =TODAY()
B8: SECTION
B9: COMPS OUTPUTS (FROM 05_TRADING_COMPS)
B10: Comps equity value P25 | C10: m | F10: ='05_TRADING_COMPS'!$F$43
B11: Comps equity value Median | C11: m | F11: ='05_TRADING_COMPS'!$F$44
B12: Comps equity value P75 | C12: m | F12: ='05_TRADING_COMPS'!$F$45
B14: Shares outstanding (mm) | C14: mm | F14: =IF('02_COMPANY_INPUTS'!$F$11="","",'02_COMPANY_INPUTS'!$F$11)
B16: Comps implied price P25 | C16: CCY | F16: =IF(OR($F$10="",$F$14="",N($F$14)=0),"",IFERROR(N($F$10)/N($F$14),""))
B17: Comps implied price Median | C17: CCY | F17: =IF(OR($F$11="",$F$14="",N($F$14)=0),"",IFERROR(N($F$11)/N($F$14),""))
B18: Comps implied price P75 | C18: CCY | F18: =IF(OR($F$12="",$F$14="",N($F$14)=0),"",IFERROR(N($F$12)/N($F$14),""))
B21: DCF OUTPUTS (FROM 07_DCF_FCF_AND_VALUATION)
B22: DCF equity value Downside | C22: m | F22: ='07_DCF_FCF_AND_VALUATION'!$F$56
B23: DCF equity value Base | C23: m | F23: ='07_DCF_FCF_AND_VALUATION'!$F$57
B24: DCF equity value Upside | C24: m | F24: ='07_DCF_FCF_AND_VALUATION'!$F$58
B26: DCF implied price Downside | C26: CCY | F26: ='07_DCF_FCF_AND_VALUATION'!$F$60
B27: DCF implied price Base | C27: CCY | F27: ='07_DCF_FCF_AND_VALUATION'!$F$61
B28: DCF implied price Upside | C28: CCY | F28: ='07_DCF_FCF_AND_VALUATION'!$F$62
B31: TRIANGULATION (OPTIONAL WEIGHTING)
B32: Weight DCF (0-1) | F32: 0.5
B34: Combined implied price Downside | C34: CCY | F34: =IF('01_CONTROL'!$F$13=1,IF(OR($F$26="",$F$16=""),"",IFERROR($F$32*N($F$26)+(1-$F$32)*N($F$16),"")),IF($F$16="","",N($F$16)))
B35: Combined implied price Base | C35: CCY | F35: =IF('01_CONTROL'!$F$13=1,IF(OR($F$27="",$F$17=""),"",IFERROR($F$32*N($F$27)+(1-$F$32)*N($F$17),"")),IF($F$17="","",N($F$17)))
B36: Combined implied price Upside | C36: CCY | F36: =IF('01_CONTROL'!$F$13=1,IF(OR($F$28="",$F$18=""),"",IFERROR($F$32*N($F$28)+(1-$F$32)*N($F$18),"")),IF($F$18="","",N($F$18)))
B39: REFERENCE POINT AND UPSIDE/DOWNSIDE
B40: Current share price | C40: CCY | F40: =IF('02_COMPANY_INPUTS'!$F$10="","",'02_COMPANY_INPUTS'!$F$10)
B41: Selected reference price (Base) | C41: CCY | F41: =$F$35
B42: Upside vs current | C42: % | F42: =IF(OR($F$41="",$F$40=""),"",IFERROR($F$41/$F$40-1,""))
B43: Downside vs current (Downside) | C43: % | F43: =IF(OR($F$34="",$F$40=""),"",IFERROR($F$34/$F$40-1,""))
B46: DASHBOARD SOURCE CELLS (SINGLE OUTPUTS)
B47: SRC_CurrentPrice | F47: =$F$40
B48: SRC_SharesMM | F48: =$F$14
B49: SRC_MarketCap | F49: =IF('02_COMPANY_INPUTS'!$F$12="","",'02_COMPANY_INPUTS'!$F$12)
B50: SRC_NetDebt | F50: =IF('02_COMPANY_INPUTS'!$F$26="","",'02_COMPANY_INPUTS'!$F$26)
B51: SRC_EnterpriseValue | F51: =IF(OR($F$49="",$F$50=""),"",$F$49+$F$50)
B52: SRC_ImpliedPrice_Base | F52: =$F$41
B53: SRC_UpsidePct | F53: =$F$42
B54: SRC_DownsidePct | F54: =$F$43
...

Sheet 09_SENSITIVITIES
B2: 09_SENSITIVITIES
B3: Model
B4: Company
B5: Version
B6: Last updated | F6: =TODAY()
B8: SECTION
B9: SENSITIVITY SETUP
B10: Terminal method (from 01_CONTROL) | F10: ='01_CONTROL'!$F$14
B11: Mid-year convention (from 01_CONTROL) | F11: ='01_CONTROL'!$F$16
B14: DCF SENSITIVITY: WACC VS TERMINAL GROWTH (PERPETUITY)
F15: g \ WACC | G15: ='06_DCF_WACC'!$F$20+(-0.02) | H15: ='06_DCF_WACC'!$F$20+(-0.01) | I15: ='06_DCF_WACC'!$F$20+(0.0) | J15: ='06_DCF_WACC'!$F$20+(0.01) | K15: ='06_DCF_WACC'!$F$20+(0.02) | L15: ='06_DCF_WACC'!$F$20+(0.03)
F16: 0.01 | G16: =IF(AND('01_CONTROL'!$F$13=1,'01_CONTROL'!$F$15=1),IFERROR(IFERROR(IFERROR(SUMPRODUCT('04_DRIVERS_AND_FORECAST'!$G$22:$P$22,1/(1+G15)^('01_CONTROL'!$G$53:$P$53-IF('01_CONTROL'!$F$17=1,0.5,0)),'01_CONTROL'!$G$52:$P$52)+IFERROR(IFERROR(INDEX('04_DRIVERS_AND_FORECAST'!$G$22:$P$22,'01_CONTROL'!$F$11)*(1+F16)/(G15-F16),"")*1/(1+G15)^('01_CONTROL'!$F$11-IF('01_CONTROL'!$F$17=1,0.5,0)),""),"")-'02_COMPANY_INPUTS'!$F$26,"")/'02_COMPANY_INPUTS'!$F$11,""),"") | H16: =IF(AND('01_CONTROL'!$F$13=1,'01_CONTROL'!$F$15=1),IFERROR(IFERROR(IFERROR(SUMPRODUCT('04_DRIVERS_AND_FORECAST'!$G$22:$P$22,1/(1+H15)^('01_CONTROL'!$G$53:$P$53-IF('01_CONTROL'!$F$17=1,0.5,0)),'01_CONTROL'!$G$52:$P$52)+IFERROR(IFERROR(INDEX('04_DRIVERS_AND_FORECAST'!$G$22:$P$22,'01_CONTROL'!$F$11)*(1+F16)/(H15-F16),"")*1/(1+H15)^('01_CONTROL'!$F$11-IF('01_CONTROL'!$F$17=1,0.5,0)),""),"")-'02_COMPANY_INPUTS'!$F$26,"")/'02_COMPANY_INPUTS'!$F$11,""),"") | I16: =IF(AND('01_CONTROL'!$F$13=1,'01_CONTROL'!$F$15=1),IFERROR(IFERROR(IFERROR(SUMPRODUCT('04_DRIVERS_AND_FORECAST'!$G$22:$P$22,1/(1+I15)^('01_CONTROL'!$G$53:$P$53-IF('01_CONTROL'!$F$17=1,0.5,0)),'01_CONTROL'!$G$52:$P$52)+IFERROR(IFERROR(INDEX('04_DRIVERS_AND_FORECAST'!$G$22:$P$22,'01_CONTROL'!$F$11)*(1+F16)/(I15-F16),"")*1/(1+I15)^('01_CONTROL'!$F$11-IF('01_CONTROL'!$F$17=1,0.5,0)),""),"")-'02_COMPANY_INPUTS'!$F$26,"")/'02_COMPANY_INPUTS'!$F$11,""),"") | J16: =IF(AND('01_CONTROL'!$F$13=1,'01_CONTROL'!$F$15=1),IFERROR(IFERROR(IFERROR(SUMPRODUCT('04_DRIVERS_AND_FORECAST'!$G$22:$P$22,1/(1+J15)^('01_CONTROL'!$G$53:$P$53-IF('01_CONTROL'!$F$17=1,0.5,0)),'01_CONTROL'!$G$52:$P$52)+IFERROR(IFERROR(INDEX('04_DRIVERS_AND_FORECAST'!$G$22:$P$22,'01_CONTROL'!$F$11)*(1+F16)/(J15-F16),"")*1/(1+J15)^('01_CONTROL'!$F$11-IF('01_CONTROL'!$F$17=1,0.5,0)),""),"")-'02_COMPANY_INPUTS'!$F$26,"")/'02_COMPANY_INPUTS'!$F$11,""),"") | K16: =IF(AND('01_CONTROL'!$F$13=1,'01_CONTROL'!$F$15=1),IFERROR(IFERROR(IFERROR(SUMPRODUCT('04_DRIVERS_AND_FORECAST'!$G$22:$P$22,1/(1+K15)^('01_CONTROL'!$G$53:$P$53-IF('01_CONTROL'!$F$17=1,0.5,0)),'01_CONTROL'!$G$52:$P$52)+IFERROR(IFERROR(INDEX('04_DRIVERS_AND_FORECAST'!$G$22:$P$22,'01_CONTROL'!$F$11)*(1+F16)/(K15-F16),"")*1/(1+K15)^('01_CONTROL'!$F$11-IF('01_CONTROL'!$F$17=1,0.5,0)),""),"")-'02_COMPANY_INPUTS'!$F$26,"")/'02_COMPANY_INPUTS'!$F$11,""),"") | L16: =IF(AND('01_CONTROL'!$F$13=1,'01_CONTROL'!$F$15=1),IFERROR(IFERROR(IFERROR(SUMPRODUCT('04_DRIVERS_AND_FORECAST'!$G$22:$P$22,1/(1+L15)^('01_CONTROL'!$G$53:$P$53-IF('01_CONTROL'!$F$17=1,0.5,0)),'01_CONTROL'!$G$52:$P$52)+IFERROR(IFERROR(INDEX('04_DRIVERS_AND_FORECAST'!$G$22:$P$22,'01_CONTROL'!$F$11)*(1+F16)/(L15-F16),"")*1/(1+L15)^('01_CONTROL'!$F$11-IF('01_CONTROL'!$F$17=1,0.5,0)),""),"")-'02_COMPANY_INPUTS'!$F$26,"")/'02_COMPANY_INPUTS'!$F$11,""),"")
F17: 0.015 | G17: =IF(AND('01_CONTROL'!$F$13=1,'01_CONTROL'!$F$15=1),IFERROR(IFERROR(IFERROR(SUMPRODUCT('04_DRIVERS_AND_FORECAST'!$G$22:$P$22,1/(1+G15)^('01_CONTROL'!$G$53:$P$53-IF('01_CONTROL'!$F$17=1,0.5,0)),'01_CONTROL'!$G$52:$P$52)+IFERROR(IFERROR(INDEX('04_DRIVERS_AND_FORECAST'!$G$22:$P$22,'01_CONTROL'!$F$11)*(1+F17)/(G15-F17),"")*1/(1+G15)^('01_CONTROL'!$F$11-IF('01_CONTROL'!$F$17=1,0.5,0)),""),"")-'02_COMPANY_INPUTS'!$F$26,"")/'02_COMPANY_INPUTS'!$F$11,""),"") | H17: =IF(AND('01_CONTROL'!$F$13=1,'01_CONTROL'!$F$15=1),IFERROR(IFERROR(IFERROR(SUMPRODUCT('04_DRIVERS_AND_FORECAST'!$G$22:$P$22,1/(1+H15)^('01_CONTROL'!$G$53:$P$53-IF('01_CONTROL'!$F$17=1,0.5,0)),'01_CONTROL'!$G$52:$P$52)+IFERROR(IFERROR(INDEX('04_DRIVERS_AND_FORECAST'!$G$22:$P$22,'01_CONTROL'!$F$11)*(1+F17)/(H15-F17),"")*1/(1+H15)^('01_CONTROL'!$F$11-IF('01_CONTROL'!$F$17=1,0.5,0)),""),"")-'02_COMPANY_INPUTS'!$F$26,"")/'02_COMPANY_INPUTS'!$F$11,""),"") | I17: =IF(AND('01_CONTROL'!$F$13=1,'01_CONTROL'!$F$15=1),IFERROR(IFERROR(IFERROR(SUMPRODUCT('04_DRIVERS_AND_FORECAST'!$G$22:$P$22,1/(1+I15)^('01_CONTROL'!$G$53:$P$53-IF('01_CONTROL'!$F$17=1,0.5,0)),'01_CONTROL'!$G$52:$P$52)+IFERROR(IFERROR(INDEX('04_DRIVERS_AND_FORECAST'!$G$22:$P$22,'01_CONTROL'!$F$11)*(1+F17)/(I15-F17),"")*1/(1+I15)^('01_CONTROL'!$F$11-IF('01_CONTROL'!$F$17=1,0.5,0)),""),"")-'02_COMPANY_INPUTS'!$F$26,"")/'02_COMPANY_INPUTS'!$F$11,""),"") | J17: =IF(AND('01_CONTROL'!$F$13=1,'01_CONTROL'!$F$15=1),IFERROR(IFERROR(IFERROR(SUMPRODUCT('04_DRIVERS_AND_FORECAST'!$G$22:$P$22,1/(1+J15)^('01_CONTROL'!$G$53:$P$53-IF('01_CONTROL'!$F$17=1,0.5,0)),'01_CONTROL'!$G$52:$P$52)+IFERROR(IFERROR(INDEX('04_DRIVERS_AND_FORECAST'!$G$22:$P$22,'01_CONTROL'!$F$11)*(1+F17)/(J15-F17),"")*1/(1+J15)^('01_CONTROL'!$F$11-IF('01_CONTROL'!$F$17=1,0.5,0)),""),"")-'02_COMPANY_INPUTS'!$F$26,"")/'02_COMPANY_INPUTS'!$F$11,""),"") | K17: =IF(AND('01_CONTROL'!$F$13=1,'01_CONTROL'!$F$15=1),IFERROR(IFERROR(IFERROR(SUMPRODUCT('04_DRIVERS_AND_FORECAST'!$G$22:$P$22,1/(1+K15)^('01_CONTROL'!$G$53:$P$53-IF('01_CONTROL'!$F$17=1,0.5,0)),'01_CONTROL'!$G$52:$P$52)+IFERROR(IFERROR(INDEX('04_DRIVERS_AND_FORECAST'!$G$22:$P$22,'01_CONTROL'!$F$11)*(1+F17)/(K15-F17),"")*1/(1+K15)^('01_CONTROL'!$F$11-IF('01_CONTROL'!$F$17=1,0.5,0)),""),"")-'02_COMPANY_INPUTS'!$F$26,"")/'02_COMPANY_INPUTS'!$F$11,""),"") | L17: =IF(AND('01_CONTROL'!$F$13=1,'01_CONTROL'!$F$15=1),IFERROR(IFERROR(IFERROR(SUMPRODUCT('04_DRIVERS_AND_FORECAST'!$G$22:$P$22,1/(1+L15)^('01_CONTROL'!$G$53:$P$53-IF('01_CONTROL'!$F$17=1,0.5,0)),'01_CONTROL'!$G$52:$P$52)+IFERROR(IFERROR(INDEX('04_DRIVERS_AND_FORECAST'!$G$22:$P$22,'01_CONTROL'!$F$11)*(1+F17)/(L15-F17),"")*1/(1+L15)^('01_CONTROL'!$F$11-IF('01_CONTROL'!$F$17=1,0.5,0)),""),"")-'02_COMPANY_INPUTS'!$F$26,"")/'02_COMPANY_INPUTS'!$F$11,""),"")
F18: 0.02 | G18: =IF(AND('01_CONTROL'!$F$13=1,'01_CONTROL'!$F$15=1),IFERROR(IFERROR(IFERROR(SUMPRODUCT('04_DRIVERS_AND_FORECAST'!$G$22:$P$22,1/(1+G15)^('01_CONTROL'!$G$53:$P$53-IF('01_CONTROL'!$F$17=1,0.5,0)),'01_CONTROL'!$G$52:$P$52)+IFERROR(IFERROR(INDEX('04_DRIVERS_AND_FORECAST'!$G$22:$P$22,'01_CONTROL'!$F$11)*(1+F18)/(G15-F18),"")*1/(1+G15)^('01_CONTROL'!$F$11-IF('01_CONTROL'!$F$17=1,0.5,0)),""),"")-'02_COMPANY_INPUTS'!$F$26,"")/'02_COMPANY_INPUTS'!$F$11,""),"") | H18: =IF(AND('01_CONTROL'!$F$13=1,'01_CONTROL'!$F$15=1),IFERROR(IFERROR(IFERROR(SUMPRODUCT('04_DRIVERS_AND_FORECAST'!$G$22:$P$22,1/(1+H15)^('01_CONTROL'!$G$53:$P$53-IF('01_CONTROL'!$F$17=1,0.5,0)),'01_CONTROL'!$G$52:$P$52)+IFERROR(IFERROR(INDEX('04_DRIVERS_AND_FORECAST'!$G$22:$P$22,'01_CONTROL'!$F$11)*(1+F18)/(H15-F18),"")*1/(1+H15)^('01_CONTROL'!$F$11-IF('01_CONTROL'!$F$17=1,0.5,0)),""),"")-'02_COMPANY_INPUTS'!$F$26,"")/'02_COMPANY_INPUTS'!$F$11,""),"") | I18: =IF(AND('01_CONTROL'!$F$13=1,'01_CONTROL'!$F$15=1),IFERROR(IFERROR(IFERROR(SUMPRODUCT('04_DRIVERS_AND_FORECAST'!$G$22:$P$22,1/(1+I15)^('01_CONTROL'!$G$53:$P$53-IF('01_CONTROL'!$F$17=1,0.5,0)),'01_CONTROL'!$G$52:$P$52)+IFERROR(IFERROR(INDEX('04_DRIVERS_AND_FORECAST'!$G$22:$P$22,'01_CONTROL'!$F$11)*(1+F18)/(I15-F18),"")*1/(1+I15)^('01_CONTROL'!$F$11-IF('01_CONTROL'!$F$17=1,0.5,0)),""),"")-'02_COMPANY_INPUTS'!$F$26,"")/'02_COMPANY_INPUTS'!$F$11,""),"") | J18: =IF(AND('01_CONTROL'!$F$13=1,'01_CONTROL'!$F$15=1),IFERROR(IFERROR(IFERROR(SUMPRODUCT('04_DRIVERS_AND_FORECAST'!$G$22:$P$22,1/(1+J15)^('01_CONTROL'!$G$53:$P$53-IF('01_CONTROL'!$F$17=1,0.5,0)),'01_CONTROL'!$G$52:$P$52)+IFERROR(IFERROR(INDEX('04_DRIVERS_AND_FORECAST'!$G$22:$P$22,'01_CONTROL'!$F$11)*(1+F18)/(J15-F18),"")*1/(1+J15)^('01_CONTROL'!$F$11-IF('01_CONTROL'!$F$17=1,0.5,0)),""),"")-'02_COMPANY_INPUTS'!$F$26,"")/'02_COMPANY_INPUTS'!$F$11,""),"") | K18: =IF(AND('01_CONTROL'!$F$13=1,'01_CONTROL'!$F$15=1),IFERROR(IFERROR(IFERROR(SUMPRODUCT('04_DRIVERS_AND_FORECAST'!$G$22:$P$22,1/(1+K15)^('01_CONTROL'!$G$53:$P$53-IF('01_CONTROL'!$F$17=1,0.5,0)),'01_CONTROL'!$G$52:$P$52)+IFERROR(IFERROR(INDEX('04_DRIVERS_AND_FORECAST'!$G$22:$P$22,'01_CONTROL'!$F$11)*(1+F18)/(K15-F18),"")*1/(1+K15)^('01_CONTROL'!$F$11-IF('01_CONTROL'!$F$17=1,0.5,0)),""),"")-'02_COMPANY_INPUTS'!$F$26,"")/'02_COMPANY_INPUTS'!$F$11,""),"") | L18: =IF(AND('01_CONTROL'!$F$13=1,'01_CONTROL'!$F$15=1),IFERROR(IFERROR(IFERROR(SUMPRODUCT('04_DRIVERS_AND_FORECAST'!$G$22:$P$22,1/(1+L15)^('01_CONTROL'!$G$53:$P$53-IF('01_CONTROL'!$F$17=1,0.5,0)),'01_CONTROL'!$G$52:$P$52)+IFERROR(IFERROR(INDEX('04_DRIVERS_AND_FORECAST'!$G$22:$P$22,'01_CONTROL'!$F$11)*(1+F18)/(L15-F18),"")*1/(1+L15)^('01_CONTROL'!$F$11-IF('01_CONTROL'!$F$17=1,0.5,0)),""),"")-'02_COMPANY_INPUTS'!$F$26,"")/'02_COMPANY_INPUTS'!$F$11,""),"")
F19: 0.025 | G19: =IF(AND('01_CONTROL'!$F$13=1,'01_CONTROL'!$F$15=1),IFERROR(IFERROR(IFERROR(SUMPRODUCT('04_DRIVERS_AND_FORECAST'!$G$22:$P$22,1/(1+G15)^('01_CONTROL'!$G$53:$P$53-IF('01_CONTROL'!$F$17=1,0.5,0)),'01_CONTROL'!$G$52:$P$52)+IFERROR(IFERROR(INDEX('04_DRIVERS_AND_FORECAST'!$G$22:$P$22,'01_CONTROL'!$F$11)*(1+F19)/(G15-F19),"")*1/(1+G15)^('01_CONTROL'!$F$11-IF('01_CONTROL'!$F$17=1,0.5,0)),""),"")-'02_COMPANY_INPUTS'!$F$26,"")/'02_COMPANY_INPUTS'!$F$11,""),"") | H19: =IF(AND('01_CONTROL'!$F$13=1,'01_CONTROL'!$F$15=1),IFERROR(IFERROR(IFERROR(SUMPRODUCT('04_DRIVERS_AND_FORECAST'!$G$22:$P$22,1/(1+H15)^('01_CONTROL'!$G$53:$P$53-IF('01_CONTROL'!$F$17=1,0.5,0)),'01_CONTROL'!$G$52:$P$52)+IFERROR(IFERROR(INDEX('04_DRIVERS_AND_FORECAST'!$G$22:$P$22,'01_CONTROL'!$F$11)*(1+F19)/(H15-F19),"")*1/(1+H15)^('01_CONTROL'!$F$11-IF('01_CONTROL'!$F$17=1,0.5,0)),""),"")-'02_COMPANY_INPUTS'!$F$26,"")/'02_COMPANY_INPUTS'!$F$11,""),"") | I19: =IF(AND('01_CONTROL'!$F$13=1,'01_CONTROL'!$F$15=1),IFERROR(IFERROR(IFERROR(SUMPRODUCT('04_DRIVERS_AND_FORECAST'!$G$22:$P$22,1/(1+I15)^('01_CONTROL'!$G$53:$P$53-IF('01_CONTROL'!$F$17=1,0.5,0)),'01_CONTROL'!$G$52:$P$52)+IFERROR(IFERROR(INDEX('04_DRIVERS_AND_FORECAST'!$G$22:$P$22,'01_CONTROL'!$F$11)*(1+F19)/(I15-F19),"")*1/(1+I15)^('01_CONTROL'!$F$11-IF('01_CONTROL'!$F$17=1,0.5,0)),""),"")-'02_COMPANY_INPUTS'!$F$26,"")/'02_COMPANY_INPUTS'!$F$11,""),"") | J19: =IF(AND('01_CONTROL'!$F$13=1,'01_CONTROL'!$F$15=1),IFERROR(IFERROR(IFERROR(SUMPRODUCT('04_DRIVERS_AND_FORECAST'!$G$22:$P$22,1/(1+J15)^('01_CONTROL'!$G$53:$P$53-IF('01_CONTROL'!$F$17=1,0.5,0)),'01_CONTROL'!$G$52:$P$52)+IFERROR(IFERROR(INDEX('04_DRIVERS_AND_FORECAST'!$G$22:$P$22,'01_CONTROL'!$F$11)*(1+F19)/(J15-F19),"")*1/(1+J15)^('01_CONTROL'!$F$11-IF('01_CONTROL'!$F$17=1,0.5,0)),""),"")-'02_COMPANY_INPUTS'!$F$26,"")/'02_COMPANY_INPUTS'!$F$11,""),"") | K19: =IF(AND('01_CONTROL'!$F$13=1,'01_CONTROL'!$F$15=1),IFERROR(IFERROR(IFERROR(SUMPRODUCT('04_DRIVERS_AND_FORECAST'!$G$22:$P$22,1/(1+K15)^('01_CONTROL'!$G$53:$P$53-IF('01_CONTROL'!$F$17=1,0.5,0)),'01_CONTROL'!$G$52:$P$52)+IFERROR(IFERROR(INDEX('04_DRIVERS_AND_FORECAST'!$G$22:$P$22,'01_CONTROL'!$F$11)*(1+F19)/(K15-F19),"")*1/(1+K15)^('01_CONTROL'!$F$11-IF('01_CONTROL'!$F$17=1,0.5,0)),""),"")-'02_COMPANY_INPUTS'!$F$26,"")/'02_COMPANY_INPUTS'!$F$11,""),"") | L19: =IF(AND('01_CONTROL'!$F$13=1,'01_CONTROL'!$F$15=1),IFERROR(IFERROR(IFERROR(SUMPRODUCT('04_DRIVERS_AND_FORECAST'!$G$22:$P$22,1/(1+L15)^('01_CONTROL'!$G$53:$P$53-IF('01_CONTROL'!$F$17=1,0.5,0)),'01_CONTROL'!$G$52:$P$52)+IFERROR(IFERROR(INDEX('04_DRIVERS_AND_FORECAST'!$G$22:$P$22,'01_CONTROL'!$F$11)*(1+F19)/(L15-F19),"")*1/(1+L15)^('01_CONTROL'!$F$11-IF('01_CONTROL'!$F$17=1,0.5,0)),""),"")-'02_COMPANY_INPUTS'!$F$26,"")/'02_COMPANY_INPUTS'!$F$11,""),"")
F20: 0.03 | G20: =IF(AND('01_CONTROL'!$F$13=1,'01_CONTROL'!$F$15=1),IFERROR(IFERROR(IFERROR(SUMPRODUCT('04_DRIVERS_AND_FORECAST'!$G$22:$P$22,1/(1+G15)^('01_CONTROL'!$G$53:$P$53-IF('01_CONTROL'!$F$17=1,0.5,0)),'01_CONTROL'!$G$52:$P$52)+IFERROR(IFERROR(INDEX('04_DRIVERS_AND_FORECAST'!$G$22:$P$22,'01_CONTROL'!$F$11)*(1+F20)/(G15-F20),"")*1/(1+G15)^('01_CONTROL'!$F$11-IF('01_CONTROL'!$F$17=1,0.5,0)),""),"")-'02_COMPANY_INPUTS'!$F$26,"")/'02_COMPANY_INPUTS'!$F$11,""),"") | H20: =IF(AND('01_CONTROL'!$F$13=1,'01_CONTROL'!$F$15=1),IFERROR(IFERROR(IFERROR(SUMPRODUCT('04_DRIVERS_AND_FORECAST'!$G$22:$P$22,1/(1+H15)^('01_CONTROL'!$G$53:$P$53-IF('01_CONTROL'!$F$17=1,0.5,0)),'01_CONTROL'!$G$52:$P$52)+IFERROR(IFERROR(INDEX('04_DRIVERS_AND_FORECAST'!$G$22:$P$22,'01_CONTROL'!$F$11)*(1+F20)/(H15-F20),"")*1/(1+H15)^('01_CONTROL'!$F$11-IF('01_CONTROL'!$F$17=1,0.5,0)),""),"")-'02_COMPANY_INPUTS'!$F$26,"")/'02_COMPANY_INPUTS'!$F$11,""),"") | I20: =IF(AND('01_CONTROL'!$F$13=1,'01_CONTROL'!$F$15=1),IFERROR(IFERROR(IFERROR(SUMPRODUCT('04_DRIVERS_AND_FORECAST'!$G$22:$P$22,1/(1+I15)^('01_CONTROL'!$G$53:$P$53-IF('01_CONTROL'!$F$17=1,0.5,0)),'01_CONTROL'!$G$52:$P$52)+IFERROR(IFERROR(INDEX('04_DRIVERS_AND_FORECAST'!$G$22:$P$22,'01_CONTROL'!$F$11)*(1+F20)/(I15-F20),"")*1/(1+I15)^('01_CONTROL'!$F$11-IF('01_CONTROL'!$F$17=1,0.5,0)),""),"")-'02_COMPANY_INPUTS'!$F$26,"")/'02_COMPANY_INPUTS'!$F$11,""),"") | J20: =IF(AND('01_CONTROL'!$F$13=1,'01_CONTROL'!$F$15=1),IFERROR(IFERROR(IFERROR(SUMPRODUCT('04_DRIVERS_AND_FORECAST'!$G$22:$P$22,1/(1+J15)^('01_CONTROL'!$G$53:$P$53-IF('01_CONTROL'!$F$17=1,0.5,0)),'01_CONTROL'!$G$52:$P$52)+IFERROR(IFERROR(INDEX('04_DRIVERS_AND_FORECAST'!$G$22:$P$22,'01_CONTROL'!$F$11)*(1+F20)/(J15-F20),"")*1/(1+J15)^('01_CONTROL'!$F$11-IF('01_CONTROL'!$F$17=1,0.5,0)),""),"")-'02_COMPANY_INPUTS'!$F$26,"")/'02_COMPANY_INPUTS'!$F$11,""),"") | K20: =IF(AND('01_CONTROL'!$F$13=1,'01_CONTROL'!$F$15=1),IFERROR(IFERROR(IFERROR(SUMPRODUCT('04_DRIVERS_AND_FORECAST'!$G$22:$P$22,1/(1+K15)^('01_CONTROL'!$G$53:$P$53-IF('01_CONTROL'!$F$17=1,0.5,0)),'01_CONTROL'!$G$52:$P$52)+IFERROR(IFERROR(INDEX('04_DRIVERS_AND_FORECAST'!$G$22:$P$22,'01_CONTROL'!$F$11)*(1+F20)/(K15-F20),"")*1/(1+K15)^('01_CONTROL'!$F$11-IF('01_CONTROL'!$F$17=1,0.5,0)),""),"")-'02_COMPANY_INPUTS'!$F$26,"")/'02_COMPANY_INPUTS'!$F$11,""),"") | L20: =IF(AND('01_CONTROL'!$F$13=1,'01_CONTROL'!$F$15=1),IFERROR(IFERROR(IFERROR(SUMPRODUCT('04_DRIVERS_AND_FORECAST'!$G$22:$P$22,1/(1+L15)^('01_CONTROL'!$G$53:$P$53-IF('01_CONTROL'!$F$17=1,0.5,0)),'01_CONTROL'!$G$52:$P$52)+IFERROR(IFERROR(INDEX('04_DRIVERS_AND_FORECAST'!$G$22:$P$22,'01_CONTROL'!$F$11)*(1+F20)/(L15-F20),"")*1/(1+L15)^('01_CONTROL'!$F$11-IF('01_CONTROL'!$F$17=1,0.5,0)),""),"")-'02_COMPANY_INPUTS'!$F$26,"")/'02_COMPANY_INPUTS'!$F$11,""),"")
F21: 0.035 | G21: =IF(AND('01_CONTROL'!$F$13=1,'01_CONTROL'!$F$15=1),IFERROR(IFERROR(IFERROR(SUMPRODUCT('04_DRIVERS_AND_FORECAST'!$G$22:$P$22,1/(1+G15)^('01_CONTROL'!$G$53:$P$53-IF('01_CONTROL'!$F$17=1,0.5,0)),'01_CONTROL'!$G$52:$P$52)+IFERROR(IFERROR(INDEX('04_DRIVERS_AND_FORECAST'!$G$22:$P$22,'01_CONTROL'!$F$11)*(1+F21)/(G15-F21),"")*1/(1+G15)^('01_CONTROL'!$F$11-IF('01_CONTROL'!$F$17=1,0.5,0)),""),"")-'02_COMPANY_INPUTS'!$F$26,"")/'02_COMPANY_INPUTS'!$F$11,""),"") | H21: =IF(AND('01_CONTROL'!$F$13=1,'01_CONTROL'!$F$15=1),IFERROR(IFERROR(IFERROR(SUMPRODUCT('04_DRIVERS_AND_FORECAST'!$G$22:$P$22,1/(1+H15)^('01_CONTROL'!$G$53:$P$53-IF('01_CONTROL'!$F$17=1,0.5,0)),'01_CONTROL'!$G$52:$P$52)+IFERROR(IFERROR(INDEX('04_DRIVERS_AND_FORECAST'!$G$22:$P$22,'01_CONTROL'!$F$11)*(1+F21)/(H15-F21),"")*1/(1+H15)^('01_CONTROL'!$F$11-IF('01_CONTROL'!$F$17=1,0.5,0)),""),"")-'02_COMPANY_INPUTS'!$F$26,"")/'02_COMPANY_INPUTS'!$F$11,""),"") | I21: =IF(AND('01_CONTROL'!$F$13=1,'01_CONTROL'!$F$15=1),IFERROR(IFERROR(IFERROR(SUMPRODUCT('04_DRIVERS_AND_FORECAST'!$G$22:$P$22,1/(1+I15)^('01_CONTROL'!$G$53:$P$53-IF('01_CONTROL'!$F$17=1,0.5,0)),'01_CONTROL'!$G$52:$P$52)+IFERROR(IFERROR(INDEX('04_DRIVERS_AND_FORECAST'!$G$22:$P$22,'01_CONTROL'!$F$11)*(1+F21)/(I15-F21),"")*1/(1+I15)^('01_CONTROL'!$F$11-IF('01_CONTROL'!$F$17=1,0.5,0)),""),"")-'02_COMPANY_INPUTS'!$F$26,"")/'02_COMPANY_INPUTS'!$F$11,""),"") | J21: =IF(AND('01_CONTROL'!$F$13=1,'01_CONTROL'!$F$15=1),IFERROR(IFERROR(IFERROR(SUMPRODUCT('04_DRIVERS_AND_FORECAST'!$G$22:$P$22,1/(1+J15)^('01_CONTROL'!$G$53:$P$53-IF('01_CONTROL'!$F$17=1,0.5,0)),'01_CONTROL'!$G$52:$P$52)+IFERROR(IFERROR(INDEX('04_DRIVERS_AND_FORECAST'!$G$22:$P$22,'01_CONTROL'!$F$11)*(1+F21)/(J15-F21),"")*1/(1+J15)^('01_CONTROL'!$F$11-IF('01_CONTROL'!$F$17=1,0.5,0)),""),"")-'02_COMPANY_INPUTS'!$F$26,"")/'02_COMPANY_INPUTS'!$F$11,""),"") | K21: =IF(AND('01_CONTROL'!$F$13=1,'01_CONTROL'!$F$15=1),IFERROR(IFERROR(IFERROR(SUMPRODUCT('04_DRIVERS_AND_FORECAST'!$G$22:$P$22,1/(1+K15)^('01_CONTROL'!$G$53:$P$53-IF('01_CONTROL'!$F$17=1,0.5,0)),'01_CONTROL'!$G$52:$P$52)+IFERROR(IFERROR(INDEX('04_DRIVERS_AND_FORECAST'!$G$22:$P$22,'01_CONTROL'!$F$11)*(1+F21)/(K15-F21),"")*1/(1+K15)^('01_CONTROL'!$F$11-IF('01_CONTROL'!$F$17=1,0.5,0)),""),"")-'02_COMPANY_INPUTS'!$F$26,"")/'02_COMPANY_INPUTS'!$F$11,""),"") | L21: =IF(AND('01_CONTROL'!$F$13=1,'01_CONTROL'!$F$15=1),IFERROR(IFERROR(IFERROR(SUMPRODUCT('04_DRIVERS_AND_FORECAST'!$G$22:$P$22,1/(1+L15)^('01_CONTROL'!$G$53:$P$53-IF('01_CONTROL'!$F$17=1,0.5,0)),'01_CONTROL'!$G$52:$P$52)+IFERROR(IFERROR(INDEX('04_DRIVERS_AND_FORECAST'!$G$22:$P$22,'01_CONTROL'!$F$11)*(1+F21)/(L15-F21),"")*1/(1+L15)^('01_CONTROL'!$F$11-IF('01_CONTROL'!$F$17=1,0.5,0)),""),"")-'02_COMPANY_INPUTS'!$F$26,"")/'02_COMPANY_INPUTS'!$F$11,""),"")
B24: DCF SENSITIVITY: WACC VS EXIT MULTIPLE (EXIT MULTIPLE)
F25: Exit \ WACC | G25: ='06_DCF_WACC'!$F$20+(-0.02) | H25: ='06_DCF_WACC'!$F$20+(-0.01) | I25: ='06_DCF_WACC'!$F$20+(0.0) | J25: ='06_DCF_WACC'!$F$20+(0.01) | K25: ='06_DCF_WACC'!$F$20+(0.02) | L25: ='06_DCF_WACC'!$F$20+(0.03)
